Workbook

Sheet orgNodes
A1: entityID | B1: entity | C1: tier1and2entity | D1: tier1and2entityID | E1: entityIDAbove | F1: mission | G1: website | H1: operational | I1: decision | J1: regulatory | K1: research | L1: level
A2: n01 | B2: California | C2: California | D2: 1 | E2: NA | F2: The California Dream. The idea that every person can achieve a better life, regardless of where they start out, is central to who we are as Californians. | G2: https://www.ca.gov/ | H2: Yes | I2: Yes | J2: Yes | K2: Yes | L2: 1
A3: n02 | B3: Environmental Protection Agency | C3: Environmental Protection Agency | D3: 2 | E3: n01 | F3: Restore, protect and enhance the_environment, to ensure public health, environmental quality and economic vitality. | G3: https://calepa.ca.gov/ | H3: No | I3: Yes | J3: Yes | K3: No | L3: 2
A4: n03 | B4: Department of Pesticide Regulation | C4: Environmental Protection Agency | D4: 2 | E4: n02 | F4: Protect human health and the environment by regulating pesticide sales and use, and by fostering reduced-risk pest management. | G4: https://www.cdpr.ca.gov/ | H4: No | I4: Yes | J4: Yes | K4: No | L4: 3
A5: n04 | B5: Environmental Monitoring Branch | C5: Environmental Protection Agency | D5: 2 | E5: n03 | F5: Monitors the environment to determine the fate of pesticides, protecting the public and the environment from pesticide contamination through analyzing hazards and developing pollution prevention strategies. | G5: https://www.cdpr.ca.gov/docs/emon/ehap.htm | H5: No | I5: Yes | J5: Yes | K5: No | L5: 4
A6: n05 | B6: Surface Water Protection Program | C6: Environmental Protection Agency | D6: 2 | E6: n04 | F6: Protects human health and the environment by preventing pesticides from adversely affecting our surface waters, by addressing both agricultural and nonagricultural sources of pesticide residues in surface waters. | G6: https://www.cdpr.ca.gov/docs/emon/surfwtr/index.htm | H6: No | I6: Yes | J6: Yes | K6: No | L6: 5
A7: n06 | B7: Ground Water Protection Program | C7: Environmental Protection Agency | D7: 2 | E7: n04 | F7: Evaluate and samples for pesticides to determine if they may contaminate ground water, identifies areas sensitive to pesticide contamination and develops mitigation measures to prevent that movement. | G7: https://www.cdpr.ca.gov/docs/emon/grndwtr/index.htm | H7: No | I7: Yes | J7: Yes | K7: No | L7: 5
A8: n07 | B8: Department of Toxic Substances Control | C8: Environmental Protection Agency | D8: 2 | E8: n02 | F8: Protect Californias people and environment from harmful effects of toxic substances by restoring contaminated resources, enforcing hazardous waste laws, reducing hazardous waste generation, and encouraging the manufacture of chemically safer products. | G8: https://www.dtsc.ca.gov/ | H8: No | I8: Yes | J8: Yes | K8: No | L8: 3
A9: n08 | B9: State Water Resources Control Board | C9: Environmental Protection Agency | D9: 2 | E9: n02 | F9: To preserve, enhance, and restore the quality of California's water resources and drinking water for the protection of the environment, public health, and all beneficial uses, and to ensure proper water resource allocation and efficient use, for the benefit of present and future generations. | G9: https://www.waterboards.ca.gov/ | H9: No | I9: Yes | J9: Yes | K9: No | L9: 3
A10: n09 | B10: 401 Water Quality Certification and Wetlands Program | C10: Environmental Protection Agency | D10: 2 | E10: n08 | F10: Regulates discharges of fill and dredged material under Clean Water Act Section 401 and the Porter-Cologne Water Quality Control Act. | G10: https://www.waterboards.ca.gov/water_issues/programs/cwa401/ | H10: No | I10: Yes | J10: Yes | K10: Yes | L10: 4
A11: n10 | B11: Agriculture | C11: Environmental Protection Agency | D11: 2 | E11: n08 | F11: Regulates discharges from irrigated agricultural lands to prevent agricultural discharges from impairing water quality. | G11: https://www.waterboards.ca.gov/water_issues/programs/agriculture/ | H11: No | I11: No | J11: Yes | K11: No | L11: 4
A12: n12 | B12: Cannabis Cultivation Regulatory Programs | C12: Environmental Protection Agency | D12: 2 | E12: n08 | F12: The Water Boards Cannabis Cultivation Program has four main components to address potential water quality and quantity issues related to cannabis cultivation. | G12: https://www.waterboards.ca.gov/water_issues/programs/cannabis/ | H12: No | I12: No | J12: Yes | K12: No | L12: 4
A13: n13 | B13: Nonpoint Source Program | C13: Environmental Protection Agency | D13: 2 | E13: n08 | F13: Minimize NPS pollution from land use activities in agriculture, urban development, forestry, recreational boating and marinas, hydromodification and wetlands. | G13: https://www.waterboards.ca.gov/water_issues/programs/nps/ | H13: No | I13: No | J13: Yes | K13: No | L13: 4
... A68: n68 | B68: State Lands Commission | C68: Natural Resources Agency | D68: 3 | E68: n25 | F68: Provides the people of California with effective stewardship of the lands, waterways, and resources entrusted to its care through preservation, restoration, enhancement, responsible economic development, and the promotion of public access. | G68: http://www.slc.ca.gov/ | H68: No | I68: Yes | J68: Yes | K68: No | L68: 3
A69: n69 | B69: Environmental Planning and Management Division | C69: Natural Resources Agency | D69: 3 | E69: n68 | F69: Provides policy and technical analysis to the Commission and its Executive Officer, and ensures compliance with the California Environmental Quality Act (CEQA). | H69: No | I69: Yes | J69: Yes | K69: No | L69: 4
A70: n70 | B70: Land Management Division | C70: Natural Resources Agency | D70: 3 | E70: n68 | F70: Primary responsibility for the surface management of all sovereign and school lands in California. | H70: No | I70: Yes | J70: No | K70: No | L70: 4
A71: n71 | B71: Mineral Resources Management Division | C71: Natural Resources Agency | D71: 3 | E71: n67 | F71: Responsible for the safe and environmentally sound development, regulation, and management of all energy and mineral resources on sovereign and school lands under the jurisdiction of the Commission. | H71: No | I71: Yes | J71: No | K71: No | L71: 4
A72: n72 | B72: Conservation Program | C72: Environmental Protection Agency | D72: 2 | E72: n08 | F72: Improving conservation and efficiency of water resources | G72: https://www.waterboards.ca.gov/water_issues/programs/conservation_portal/ | H72: No | I72: Yes | J72: Yes | K72: No | L72: 4
A73: n73 | B73: Government Operations Agency | C73: Government Operations Agency | D73: 4 | E73: n01 | F73: responsible for administering state operations including procurement, information technology, and human resources. The mission of GovOps is to improve management and accountability of government programs, increase efficiency, and promote better and more coordinated operational decisions. | G73: https://www.govops.ca.gov/ | H73: No | I73: Yes | J73: No | K73: Yes | L73: 2

Sheet orgEdges
A1: from | B1: to
A2: n01 | B2: n02
A3: n02 | B3: n03
A4: n03 | B4: n04
A5: n04 | B5: n05
A6: n04 | B6: n06
A7: n02 | B7: n07
A8: n02 | B8: n08
A9: n08 | B9: n09
A10: n08 | B10: n10
A11: n08 | B11: n12
A12: n08 | B12: n13
... A72: n01 | B72: n73

Sheet platformNodes
A1: platformID | B1: platform | C1: entityID | D1: entity | E1: webLabel | F1: heatmapLabel | G1: tier1and2entity | H1: tier1and2entityID | I1: website | J1: easeDiscover | K1: methodDiscover | L1: easeAccess | M1: methodAccess | N1: fileFormat | O1: metadata | P1: metadataFormat | Q1: dataDefinitions | R1: metaAttributes | S1: metadataStandards | T1: timeliness | U1: lengthAvailable | V1: Notes
A2: p01 | B2: CA Open Data Portal | C2: n73 | D2: Government Operations Agency | E2: GOA | F2: =CONCATENATE(E2,": ",B2) -> GOA: CA Open Data Portal | G2: Government Operations Agency | H2: 4 | I2: https://data.ca.gov/ | J2: High | K2: Catalog | L2: Yes | M2: Individual Export; Batch Export; Web Services | N2: csv; excel; kml; json; pdf; shapefile; txt; zip | O2: Yes | P2: html | Q2: No | R2: Descriptive | S2: Yes | T2: Irregular | U2: Period of Record
A3: p02 | B3: Surface Water Database (SURF) | C3: n04 | D3: Environmental Monitoring Branch | E3: CalEPA-Env Monitoring Branch | F3: =CONCATENATE(E3,": ",B3) -> CalEPA-Env Monitoring Branch: Surface Water Database (SURF) | G3: Environmental Protection Agency | H3: 2 | I3: https://www.cdpr.ca.gov/docs/emon/surfwtr/surfcont.htm | J3: Low | K3: Website | L3: Yes | M3: Individual Export | N3: csv; kmz; zip | O3: Yes | P3: No | Q3: No | R3: No | S3: No | T3: Yearly or Higher | U3: Period of Record
A4: p03 | B4: Well Inventory Database | C4: n04 | D4: Environmental Monitoring Branch | E4: CalEPA-Env Monitoring Branch | F4: =CONCATENATE(E4,": ",B4) -> CalEPA-Env Monitoring Branch: Well Inventory Database | G4: Environmental Protection Agency | H4: 2 | I4: https://www.cdpr.ca.gov/docs/emon/grndwtr/well_inventory_database/index.htm | J4: Low | K4: Website | L4: Yes | M4: Batch Export | N4: excel | O4: No | P4: No | Q4: Yes | R4: No | S4: No | T4: Irregular | U4: Period of Record
A5: p04 | B5: Integrated Water Quality System Project | C5: n08 | D5: State Water Resources Control Board | E5: CalEPA-SWRCB | F5: =CONCATENATE(E5,": ",B5) -> CalEPA-SWRCB: Integrated Water Quality System Project | G5: Environmental Protection Agency | H5: 2 | I5: https://www.waterboards.ca.gov/ciwqs/publicreports.html | J5: Low | K5: Website | L5: Yes | M5: Individual Export; Batch Export | N5: csv | O5: Yes | P5: html | Q5: Yes | R5: Administrative | S5: No | T5: Daily or Higher | U5: Period of Record
A6: p05 | B6: Regulated Site Portal | C6: n02 | D6: Environmental Protection Agency | E6: CalEPA | F6: =CONCATENATE(E6,": ",B6) -> CalEPA: Regulated Site Portal | G6: Environmental Protection Agency | H6: 2 | I6: https://siteportal.calepa.ca.gov/nsite/ | J6: Medium | K6: Map | L6: Yes | M6: Individual Export; Batch Export | N6: csv | O6: No | P6: No | Q6: No | R6: No | S6: No | T6: Irregular | U6: Period of Record
A7: p06 | B7: EnvirStor | C7: n07 | D7: Department of Toxic Substances Control | E7: CalEPA-Toxic Substances | F7: =CONCATENATE(E7,": ",B7) -> CalEPA-Toxic Substances: EnvirStor | G7: Environmental Protection Agency | H7: 2 | I7: https://www.envirostor.dtsc.ca.gov/public/ | J7: Medium | K7: Catalog | L7: Yes | M7: Batch Export | N7: excel; html; txt | O7: No | P7: No | Q7: No | R7: No | S7: No | T7: Daily or Higher | U7: Period of Record
A8: p07 | B8: CalEnviroScreen | C8: n24 | D8: Office of Environmental Health Hazard Assessment | E8: CalEPA-Env Health Hazards | F8: =CONCATENATE(E8,": ",B8) -> CalEPA-Env Health Hazards: CalEnviroScreen | G8: Environmental Protection Agency | H8: 2 | I8: https://oehha.ca.gov/calenviroscreen/maps-data/download-data | J8: Low | K8: Website | L8: Yes | M8: Individual Export; Web Services | N8: excel; shapefile | O8: Yes | P8: xml | Q8: Yes | R8: Administrative; Descriptive | S8: Some | T8: Irregular | U8: Current Only
A9: p08 | B9: Electronic Water Rights Information Management System (EWRIMS) | C9: n20 | D9: Water Rights Programs | E9: CalEPA-Water Rights | F9: =CONCATENATE(E9,": ",B9) -> CalEPA-Water Rights: Electronic Water Rights Information Management System (EWRIMS) | G9: Environmental Protection Agency | H9: 2 | I9: https://www.waterboards.ca.gov/waterrights/water_issues/programs/ewrims/index.html#db | J9: Low | K9: Website | L9: Yes | M9: Individual Export; Batch Export | N9: csv; shapefile | O9: Yes | P9: xml | Q9: Yes | R9: Administrative; Descriptive | S9: No | T9: Irregular | U9: Limited Record
A10: p09 | B10: Stormwater Multiple Application and Report Tracking System | C10: n14 | D10: Stormwater Program | E10: CalEPA-Stormwater | F10: =CONCATENATE(E10,": ",B10) -> CalEPA-Stormwater: Stormwater Multiple Application and Report Tracking System | G10: Environmental Protection Agency | H10: 2 | I10: https://smarts.waterboards.ca.gov/smarts/faces/SwSmartsLogin.xhtml | J10: Low | K10: Website | L10: Yes | M10: Individual Export; Batch Export | N10: excel; html; txt | O10: No | P10: No | Q10: No | R10: No | S10: No | T10: Daily or Higher | U10: Limited Record
A11: p10 | B11: Drinking Water Watch | C11: n19 | D11: Drinking Water Program | E11: CalEPA-Drinking Water | F11: =CONCATENATE(E11,": ",B11) -> CalEPA-Drinking Water: Drinking Water Watch | G11: Environmental Protection Agency | H11: 2 | I11: https://sdwis.waterboards.ca.gov/PDWW/ | J11: Low | K11: Website | L11: Yes | M11: Copy and Paste | N11: html | O11: Yes | P11: in data | Q11: Yes | R11: Administrative; Descriptive | S11: No | T11: Yearly or Higher | U11: Limited Record
A12: p11 | B12: Drinking Water Information Clearinghouse | C12: n19 | D12: Drinking Water Program | E12: CalEPA-Drinking Water | F12: =CONCATENATE(E12,": ",B12) -> CalEPA-Drinking Water: Drinking Water Information Clearinghouse | G12: Environmental Protection Agency | H12: 2 | I12: https://drinc.ca.gov/drinc/DWPRepository.aspx | J12: Low | K12: Website | L12: Yes | M12: Individual Export | N12: excel; csv; pdf | O12: Yes | P12: pdf | Q12: Yes | R12: Administrative | S12: No | T12: Unknown | U12: Limited Record
A13: p12 | B13: Impaired Water Bodies | C13: n16 | D13: Water Quality Assessment | E13: CalEPA-Water Quality Assessments | F13: =CONCATENATE(E13,": ",B13) -> CalEPA-Water Quality Assessments: Impaired Water Bodies | G13: Environmental Protection Agency | H13: 2 | I13: https://www.waterboards.ca.gov/water_issues/programs/tmdl/integrated2012.shtml | J13: Low | K13: Website | L13: Yes | M13: Individual Export; Web Services | N13: excel; shapefile | O13: No | P13: No | Q13: Yes | R13: No | S13: No | T13: Irregular | U13: Limited Record
... A18: p17 | B18: CA Environmental Data Exchange Network | C18: n08 | D18: State Water Resources Control Board | E18: CalEPA-SWRCB | F18: =CONCATENATE(E18,": ",B18) -> CalEPA-SWRCB: CA Environmental Data Exchange Network | G18: Environmental Protection Agency | H18: 2 | I18: https://ceden.waterboards.ca.gov/AdvancedQueryTool | J18: Low | K18: Catalog | L18: Yes | M18: Individual Export; Web Services | N18: excel; html; txt | O18: No | P18: No | Q18: No | R18: No | S18: No | T18: Unknown | U18: Period of Record
A19: p18 | B19: My Water Quality | C19: nMix | D19: California Water Quality Monitoring Council | E19: CalEPA,NRA | F19: =CONCATENATE(E19,": ",B19) -> CalEPA,NRA: My Water Quality | G19: NA | H19: NA | I19: https://mywaterquality.ca.gov/index.html | J19: Low | K19: Website; Map | L19: Yes | M19: Individual Export; Batch Export; Link to Source | N19: csv; png; pdf; txt; excel | O19: Yes | P19: html | Q19: No | R19: Descriptive | S19: Yes | T19: Unknown | U19: Period of Record
A20: p19 | B20: GAMA OnLine Tools | C20: n21 | D20: GAMA | E20: CalEPA-GAMA | F20: =CONCATENATE(E20,": ",B20) -> CalEPA-GAMA: GAMA OnLine Tools | G20: Environmental Protection Agency | H20: 2 | I20: https://www.waterboards.ca.gov/water_issues/programs/gama/online_tools.html | J20: High | K20: Website; Catalog; Map | L20: Yes | M20: Individual Export; Batch Export | N20: excel; kml | O20: Yes; No | P20: html | Q20: No | R20: Descriptive | S20: Yes | T20: Irregular | U20: Period of Record
A21: p20 | B21: Water Conservation and Production Reports | C21: n72 | D21: Conservation Program | E21: CalEPA-Conservation | F21: =CONCATENATE(E21,": ",B21) -> CalEPA-Conservation: Water Conservation and Production Reports | G21: Environmental Protection Agency | H21: 2 | I21: https://www.waterboards.ca.gov/water_issues/programs/conservation_portal/conservation_reporting.html#monthly_archive | J21: Low | K21: Website | L21: Yes | M21: Batch Export | N21: excel; pdf | O21: No | P21: No | Q21: No | R21: No | S21: No | T21: Yearly or Higher | U21: Limited Record
A22: p21 | B22: Natural Resources Agency Open Data | C22: n25 | D22: Natural Resources Agency | E22: NRA | F22: =CONCATENATE(E22,": ",B22) -> NRA: Natural Resources Agency Open Data | G22: Natural Resources Agency | H22: 3 | I22: https://data.cnra.ca.gov/ | J22: High | K22: Catalog | L22: Yes | M22: Individual Export; Web Services | N22: csv; excel; kml; json; html; pdf; zip | O22: Yes | P22: html | Q22: Yes | R22: Administrative; Descriptive; Structural | S22: Yes | T22: Irregular | U22: Period of Record
A23: p22 | B23: CA Water Library | C23: n26 | D23: Department of Water Resources | E23: NRA-DWR | F23: =CONCATENATE(E23,": ",B23) -> NRA-DWR: CA Water Library | G23: Natural Resources Agency | H23: 3 | I23: https://cawaterlibrary.net/ | J23: High | K23: Catalog | L23: Yes | M23: Individual Export | N23: pdf | O23: Yes | P23: html | Q23: No | R23: Descriptive | S23: No | T23: Irregular | U23: Not Applicable
A24: p23 | B24: Groundwater Exchange | C24: nMix | D24: Groundwater Management | E24: Hub | F24: =CONCATENATE(E24,": ",B24) -> Hub: Groundwater Exchange | G24: NA | H24: NA | I24: https://groundwaterexchange.org/ | J24: Medium | K24: Catalog | L24: No | M24: Link to Source | N24: None | O24: No | P24: No | Q24: No | R24: No | S24: No | T24: Irregular | U24: Not Applicable
A25: p24 | B25: Best Available Maps | C25: n26 | D25: Department of Water Resources | E25: NRA-DWR | F25: =CONCATENATE(E25,": ",B25) -> NRA-DWR: Best Available Maps | G25: Natural Resources Agency | H25: 3 | I25: http://gis.bam.water.ca.gov/bam/ | J25: Medium | K25: Map | L25: No | M25: Link to Source | N25: None | O25: No | P25: No | Q25: No | R25: No | S25: No | T25: Irregular | U25: Current Only
A26: p25 | B26: CA Data Exchange Center | C26: n26 | D26: Department of Water Resources | E26: NRA-DWR | F26: =CONCATENATE(E26,": ",B26) -> NRA-DWR: CA Data Exchange Center | G26: Natural Resources Agency | H26: 3 | I26: https://cdec.water.ca.gov/ | J26: Low | K26: Website | L26: Yes | M26: Individual Export; Web Services | N26: html; png | O26: No | P26: No | Q26: No | R26: No | S26: No | T26: Daily or Higher | U26: Limited Record
A27: p26 | B27: CA Irrigation Management Information System | C27: n26 | D27: Department of Water Resources | E27: NRA-DWR | F27: =CONCATENATE(E27,": ",B27) -> NRA-DWR: CA Irrigation Management Information System | G27: Natural Resources Agency | H27: 3 | I27: https://cimis.water.ca.gov/ | J27: Low | K27: Website | L27: Yes | M27: Individual Export | N27: csv; html; json | O27: Yes | P27: html | Q27: No | R27: Administrative | S27: No | T27: Daily or Higher | U27: Limited Record
A28: p27 | B28: Water Management Planning Tool | C28: n26 | D28: Department of Water Resources | E28: NRA-DWR | F28: =CONCATENATE(E28,": ",B28) -> NRA-DWR: Water Management Planning Tool | G28: Natural Resources Agency | H28: 3 | I28: https://gis.water.ca.gov/app/boundaries/ | J28: Medium | K28: Map | L28: Yes | M28: Web Services | N28: json | O28: Yes | P28: html | Q28: No | R28: Descriptive | S28: Yes | T28: Irregular | U28: Current Only
A29: p28 | B29: Groundwater Information Center Interactive Map Application | C29: n26 | D29: Department of Water Resources | E29: NRA-DWR | F29: =CONCATENATE(E29,": ",B29) -> NRA-DWR: Groundwater Information Center Interactive Map Application | G29: Natural Resources Agency | H29: 3 | I29: https://gis.water.ca.gov/app/gicima/ | J29: Low | K29: Website | L29: Yes | M29: Individual Export | N29: csv; html; json | O29: Yes | P29: html | Q29: No | R29: Administrative; Descriptive | S29: No | T29: Yearly or Higher | U29: Limited Record
A30: p29 | B30: Flood Emergency Response Information Exchange | C30: n29 | D30: Flood Management Program | E30: NRA-Flood Management | F30: =CONCATENATE(E30,": ",B30) -> NRA-Flood Management: Flood Emergency Response Information Exchange | G30: Natural Resources Agency | H30: 3 | I30: http://ferix.water.ca.gov/webapp/home.jsp | J30: Low | K30: Website | L30: Yes | M30: Individual Export; Link to Source | N30: html; pdf | O30: No | P30: No | Q30: No | R30: No | S30: No | T30: Irregular | U30: Period of Record
A31: p30 | B31: CA Statewide Groundwater Elevation Monitoring (CASGEM) | C31: n30 | D31: Groundwater Management Program | E31: NRA-Groundwater Management | F31: =CONCATENATE(E31,": ",B31) -> NRA-Groundwater Management: CA Statewide Groundwater Elevation Monitoring (CASGEM) | G31: Natural Resources Agency | H31: 3 | I31: https://water.ca.gov/Programs/Groundwater-Management/Groundwater-Elevation-Monitoring--CASGEM | J31: Low | K31: Unknown | L31: Registration Required | M31: Individual Export; Copy and Paste | N31: png; html | O31: Yes | P31: html | Q31: No | R31: Descriptive | S31: No | T31: Unknown | U31: Unknown
A32: p31 | B32: SGMA Groundwater Management Portal | C32: n30 | D32: Groundwater Management Program | E32: NRA-Groundwater Management | F32: =CONCATENATE(E32,": ",B32) -> NRA-Groundwater Management: SGMA Groundwater Management Portal | G32: Natural Resources Agency | H32: 3 | I32: https://sgma.water.ca.gov/portal/#intro | J32: Low | K32: Website; Map | L32: Yes | M32: Individual Export | N32: pdf; shapefile | O32: No | P32: No | Q32: No | R32: No | S32: No | T32: Unknown | U32: Period of Record
A33: p32 | B33: DOC Maps: California Geological Survey | C33: n36 | D33: CA Geological Survey | E33: NRA-CGS | F33: =CONCATENATE(E33,": ",B33) -> NRA-CGS: DOC Maps: California Geological Survey | G33: Natural Resources Agency | H33: 3 | I33: https://maps.conservation.ca.gov/cgs/#datalist | J33: Low | K33: Website | L33: Yes | M33: Web Services | N33: shapefile; zip | O33: Yes | P33: html | Q33: Yes | R33: Administrative; Descriptive; Structural | S33: Yes | T33: Irregular | U33: Period of Record
A34: p33 | B34: Water Use SB 1281 Data and Reports | C34: n38 | D34: Division of Oil, Gas, and Geothermal Resources | E34: NRA-DOGGR | F34: =CONCATENATE(E34,": ",B34) -> NRA-DOGGR: Water Use SB 1281 Data and Reports | G34: Natural Resources Agency | H34: 3 | I34: http://www.conservation.ca.gov/dog/SB%201281/Pages/SB_1281DataAndReports.aspx | J34: Low | K34: Website | L34: Yes | M34: Individual Export | N34: csv; pdf; txt | O34: No | P34: No | Q34: Yes | R34: No | S34: No | T34: Yearly or Higher | U34: Limited Record
A35: p34 | B35: Biogeographic Information and Observation System | C35: n43 | D35: Ecosystem Conservation Division | E35: NRA-Ecosystems Conservation | F35: =CONCATENATE(E35,": ",B35) -> NRA-Ecosystems Conservation: Biogeographic Information and Observation System | G35: Natural Resources Agency | H35: 3 | I35: https://map.dfg.ca.gov/bios/ | J35: Medium | K35: Map | L35: Yes | M35: Individual Export; Link to Source | N35: shapefile; html | O35: Yes | P35: html | Q35: No | R35: Administrative; Descriptive; Structural | S35: Yes | T35: Unknown | U35: Period of Record
A36: p35 | B36: Geographic Information Systems (GIS) Services | C36: n43 | D36: Ecosystem Conservation Division | E36: NRA-Ecosystems Conservation | F36: =CONCATENATE(E36,": ",B36) -> NRA-Ecosystems Conservation: Geographic Information Systems (GIS) Services | G36: Natural Resources Agency | H36: 3 | I36: https://www.wildlife.ca.gov/Data/GIS | J36: Low | K36: Website | L36: Yes | M36: Individual Export; Web Services | N36: shapefile; zip | O36: No | P36: No | Q36: No | R36: No | S36: No | T36: Unknown | U36: Period of Record
... A38: p37 | B38: CA Renewable Energy Statistics and Data | C38: n47 | D38: Renewable Energy Division | E38: NRA-Renewable Energy | F38: =CONCATENATE(E38,": ",B38) -> NRA-Renewable Energy: CA Renewable Energy Statistics and Data | G38: Natural Resources Agency | H38: 3 | I38: http://www.energy.ca.gov/almanac/renewables_data/ | J38: Low | K38: Website | L38: Yes | M38: Copy and Paste; Individual Export | N38: csv; excel; html | O38: No | P38: No | Q38: No | R38: No | S38: No | T38: Yearly or Higher | U38: Limited Record

Sheet dataNodes
A1: dataID | B1: dataGroup | C1: dataCategory
A2: d01 | B2: Built | C2: Infrastructure
A3: d02 | B3: Natural | C3: Infrastructure
A4: d03 | B4: Quality | C4: Quality
A5: d04 | B5: Regulatory | C5: Quality
A6: d05 | B6: Evapotranspiration | C6: Quantity
A7: d06 | B7: Extreme Events | C7: Quantity
A8: d07 | B8: Glacial and Snow | C8: Quantity
A9: d08 | B9: Groundwater | C9: Quantity
A10: d09 | B10: Meteorology | C10: Quantity
A11: d10 | B11: Precipitation | C11: Quantity
A12: d11 | B12: Reservoir | C12: Quantity
... A19: d18 | B19: Management Plans | C19: Use

Sheet dataNodeTypes
A1: platformID | B1: platform | C1: entity | D1: tier1and2entity | E1: website | F1: data | G1: dataGroup | H1: dataCategory | I1: dataID | J1: notes | M1: dataGroup - linked to dataNodes tab | N1: dataID - linked to dataNodes tab
A2: p01 | B2: CA Open Data Portal | C2: Government Operations Agency | D2: Government Operations Agency | E2: https://data.ca.gov/ | F2: DWR offices, legal boundaries, dams, aqueducts, water planning areas, levee centerlines etc | G2: Built | H2: Infrastructure | I2: =VLOOKUP($G2,$M$2:$N$19,2,FALSE) -> d01 | M2: =dataNodes!B2 -> Built | N2: =dataNodes!A2 -> d01
A3: p01 | B3: CA Open Data Portal | C3: Government Operations Agency | D3: Government Operations Agency | E3: https://data.ca.gov/ | F3: Hydrologic network, sediment basins, groundwater basins | G3: Natural | H3: Infrastructure | I3: =VLOOKUP(G3,$M$2:$N$19,2,FALSE) -> d02 | M3: =dataNodes!B3 -> Natural | N3: =dataNodes!A3 -> d02
A4: p01 | B4: CA Open Data Portal | C4: Government Operations Agency | D4: Government Operations Agency | E4: https://data.ca.gov/ | F4: Benthos, aquatic organism tissue, toxicity, chemistry, water quality data, groundwater quality | G4: Quality | H4: Quality | I4: =VLOOKUP(G4,$M$2:$N$19,2,FALSE) -> d03 | M4: =dataNodes!B4 -> Quality | N4: =dataNodes!A4 -> d03
A5: p01 | B5: CA Open Data Portal | C5: Government Operations Agency | D5: Government Operations Agency | E5: https://data.ca.gov/ | F5: Drinking water quality data; pesticides database | G5: Regulatory | H5: Quality | I5: =VLOOKUP(G5,$M$2:$N$19,2,FALSE) -> d04 | M5: =dataNodes!B5 -> Regulatory | N5: =dataNodes!A5 -> d04
A6: p01 | B6: CA Open Data Portal | C6: Government Operations Agency | D6: Government Operations Agency | E6: https://data.ca.gov/ | F6: Drinking water quality data | G6: Utilities | H6: Use | I6: =VLOOKUP(G6,$M$2:$N$19,2,FALSE) -> d17 | M6: =dataNodes!B6 -> Evapotranspiration | N6: =dataNodes!A6 -> d05
A7: p01 | B7: CA Open Data Portal | C7: Government Operations Agency | D7: Government Operations Agency | E7: https://data.ca.gov/ | F7: Groundwater elevation | G7: Groundwater | H7: Quantity | I7: =VLOOKUP(G7,$M$2:$N$19,2,FALSE) -> d08 | M7: =dataNodes!B7 -> Extreme Events | N7: =dataNodes!A7 -> d06
A8: p01 | B8: CA Open Data Portal | C8: Government Operations Agency | D8: Government Operations Agency | E8: https://data.ca.gov/ | F8: Flow targets | G8: Management Plans | H8: Use | I8: =VLOOKUP(G8,$M$2:$N$19,2,FALSE) -> d18 | M8: =dataNodes!B8 -> Glacial and Snow | N8: =dataNodes!A8 -> d07
A9: p01 | B9: CA Open Data Portal | C9: Government Operations Agency | D9: Government Operations Agency | E9: https://data.ca.gov/ | F9: CIMIS Weather Station Data | G9: Evapotranspiration | H9: Quantity | I9: =VLOOKUP(G9,$M$2:$N$19,2,FALSE) -> d05 | M9: =dataNodes!B9 -> Groundwater | N9: =dataNodes!A9 -> d08
A10: p01 | B10: CA Open Data Portal | C10: Government Operations Agency | D10: Government Operations Agency | E10: https://data.ca.gov/ | F10: CIMIS Weather Station Data | G10: Precipitation | H10: Quantity | I10: =VLOOKUP(G10,$M$2:$N$19,2,FALSE) -> d10 | M10: =dataNodes!B10 -> Meteorology | N10: =dataNodes!A10 -> d09
A11: p01 | B11: CA Open Data Portal | C11: Government Operations Agency | D11: Government Operations Agency | E11: https://data.ca.gov/ | F11: CIMIS Weather Station Data | G11: Meteorology | H11: Quantity | I11: =VLOOKUP(G11,$M$2:$N$19,2,FALSE) -> d09 | M11: =dataNodes!B11 -> Precipitation | N11: =dataNodes!A11 -> d10
A12: p01 | B12: CA Open Data Portal | C12: Government Operations Agency | D12: Government Operations Agency | E12: https://data.ca.gov/ | F12: Drought Monitor Statistics | G12: Extreme Events | H12: Quantity | I12: =VLOOKUP(G12,$M$2:$N$19,2,FALSE) -> d06 | M12: =dataNodes!B12 -> Reservoir | N12: =dataNodes!A12 -> d11
A13: p01 | B13: CA Open Data Portal | C13: Government Operations Agency | D13: Government Operations Agency | E13: https://data.ca.gov/ | F13: CIMIS Weather Station Data | G13: Soil | H13: Quantity | I13: =VLOOKUP(G13,$M$2:$N$19,2,FALSE) -> d12 | M13: =dataNodes!B13 -> Soil | N13: =dataNodes!A13 -> d12
A14: p01 | B14: CA Open Data Portal | C14: Government Operations Agency | D14: Government Operations Agency | E14: https://data.ca.gov/ | F14: CIMIS Weather Station Data | G14: Irrigation | H14: Use | I14: =VLOOKUP(G14,$M$2:$N$19,2,FALSE) -> d15 | M14: =dataNodes!B14 -> Surface Water | N14: =dataNodes!A14 -> d13
... A19: p05 | B19: Regulated Site Portal | C19: Environmental Protection Agency | D19: Environmental Protection Agency | E19: https://siteportal.calepa.ca.gov/nsite/ | F19: Violations and compliance | G19: Regulatory | H19: Quality | I19: =VLOOKUP(G19,$M$2:$N$19,2,FALSE) -> d04 | M19: =dataNodes!B19 -> Management Plans | N19: =dataNodes!A19 -> d18
A20: p06 | B20: EnvirStor | C20: Department of Toxic Substances Control | D20: Environmental Protection Agency | E20: https://www.envirostor.dtsc.ca.gov/public/ | F20: toxic site clean up location, status, description | G20: Regulatory | H20: Quality | I20: =VLOOKUP(G20,$M$2:$N$19,2,FALSE) -> d04
A21: p07 | B21: CalEnviroScreen | C21: Office of Environmental Health Hazard Assessment | D21: Environmental Protection Agency | E21: https://oehha.ca.gov/calenviroscreen/maps-data/download-data | F21: Contaminant and percent of violations for drinking water | G21: Regulatory | H21: Quality | I21: =VLOOKUP(G21,$M$2:$N$19,2,FALSE) -> d04
A22: p07 | B22: CalEnviroScreen | C22: Office of Environmental Health Hazard Assessment | D22: Environmental Protection Agency | E22: https://oehha.ca.gov/calenviroscreen/maps-data/download-data | F22: Contaminant and percent of violations for drinking water | G22: Utilities | H22: Use | I22: =VLOOKUP(G22,$M$2:$N$19,2,FALSE) -> d17
A23: p07 | B23: CalEnviroScreen | C23: Office of Environmental Health Hazard Assessment | D23: Environmental Protection Agency | E23: https://oehha.ca.gov/calenviroscreen/maps-data/download-data | F23: Imparied water bodies - TMDL 303 List | G23: Quality | H23: Quality | I23: =VLOOKUP(G23,$M$2:$N$19,2,FALSE) -> d03
A24: p07 | B24: CalEnviroScreen | C24: Office of Environmental Health Hazard Assessment | D24: Environmental Protection Agency | E24: https://oehha.ca.gov/calenviroscreen/maps-data/download-data | F24: groundwater cleanup sites | G24: Groundwater | H24: Quality | I24: =VLOOKUP(G24,$M$2:$N$19,2,FALSE) -> d08
A25: p08 | B25: Electronic Water Rights Information Management System (EWRIMS) | C25: Water Rights Programs | D25: Environmental Protection Agency | E25: https://www.waterboards.ca.gov/waterrights/water_issues/programs/ewrims/index.html#db | F25: public water rights database | G25: Use | H25: Water rights | I25: =VLOOKUP(G25,$M$2:$N$19,2,FALSE) -> d16
A26: p08 | B26: Electronic Water Rights Information Management System (EWRIMS) | C26: Water Rights Programs | D26: Environmental Protection Agency | E26: https://www.waterboards.ca.gov/waterrights/water_issues/programs/ewrims/index.html#db | F26: location of diversions; fully appropriated streams | G26: Built | H26: Infrastructure | I26: =VLOOKUP(G26,$M$2:$N$19,2,FALSE) -> d01
A27: p08 | B27: Electronic Water Rights Information Management System (EWRIMS) | C27: Water Rights Programs | D27: Environmental Protection Agency | E27: https://www.waterboards.ca.gov/waterrights/water_issues/programs/ewrims/index.html#db | F27: hydrologic units; watersheds; hydrography | G27: Natural | H27: Infrastructure | I27: =VLOOKUP(G27,$M$2:$N$19,2,FALSE) -> d02
A28: p09 | B28: Stormwater Multiple Application and Report Tracking System | C28: Stormwater Program | D28: Environmental Protection Agency | E28: https://smarts.waterboards.ca.gov/smarts/faces/SwSmartsLogin.xhtml | F28: facilities and sites | G28: Built | H28: Infrastructure | I28: =VLOOKUP(G28,$M$2:$N$19,2,FALSE) -> d01
A29: p09 | B29: Stormwater Multiple Application and Report Tracking System | C29: Stormwater Program | D29: Environmental Protection Agency | E29: https://smarts.waterboards.ca.gov/smarts/faces/SwSmartsLogin.xhtml | F29: Stormwater reports by use group | G29: Use | H29: Use | I29: =VLOOKUP(G29,$M$2:$N$19,2,FALSE) -> d16
A30: p09 | B30: Stormwater Multiple Application and Report Tracking System | C30: Stormwater Program | D30: Environmental Protection Agency | E30: https://smarts.waterboards.ca.gov/smarts/faces/SwSmartsLogin.xhtml | F30: Stormwater compliance | G30: Regulatory | H30: Quality | I30: =VLOOKUP(G30,$M$2:$N$19,2,FALSE) -> d04
A31: p10 | B31: Drinking Water Watch | C31: Drinking Water Program | E31: https://sdwis.waterboards.ca.gov/PDWW/ | F31: consumer confidence reports and violations/enforcement | G31: Regulatory | H31: Quality | I31: =VLOOKUP(G31,$M$2:$N$19,2,FALSE) -> d04
A32: p10 | B32: Drinking Water Watch | C32: Drinking Water Program | E32: https://sdwis.waterboards.ca.gov/PDWW/ | F32: utility informatin | G32: Utilities | H32: Use | I32: =VLOOKUP(G32,$M$2:$N$19,2,FALSE) -> d17
A33: p10 | B33: Drinking Water Watch | C33: Drinking Water Program | E33: https://sdwis.waterboards.ca.gov/PDWW/ | F33: Monitoring results | G33: Quality | H33: Quality | I33: =VLOOKUP(G33,$M$2:$N$19,2,FALSE) -> d03
A34: p11 | B34: Drinking Water Information Clearinghouse | C34: Drinking Water Program | D34: Environmental Protection Agency | E34: https://drinc.ca.gov/drinc/DWPRepository.aspx | F34: location of public water systems | G34: Built | H34: Infrastructure | I34: =VLOOKUP(G34,$M$2:$N$19,2,FALSE) -> d01
A35: p11 | B35: Drinking Water Information Clearinghouse | C35: Drinking Water Program | D35: Environmental Protection Agency | E35: https://drinc.ca.gov/drinc/DWPRepository.aspx | F35: conservation reports of small suppliers; monthly water use | G35: Utilities | H35: Use | I35: =VLOOKUP(G35,$M$2:$N$19,2,FALSE) -> d17
A36: p11 | B36: Drinking Water Information Clearinghouse | C36: Drinking Water Program | D36: Environmental Protection Agency | E36: https://drinc.ca.gov/drinc/DWPRepository.aspx | F36: water quality | G36: Quality | H36: Quality | I36: =VLOOKUP(G36,$M$2:$N$19,2,FALSE) -> d03
A37: p12 | B37: Impaired Water Bodies | C37: Water Quality Assessment | D37: Environmental Protection Agency | E37: https://www.waterboards.ca.gov/water_issues/programs/tmdl/integrated2012.shtml | F37: 303d listed water | G37: Regulatory | H37: Quality | I37: =VLOOKUP(G37,$M$2:$N$19,2,FALSE) -> d04
A38: p12 | B38: Impaired Water Bodies | C38: Water Quality Assessment | D38: Environmental Protection Agency | E38: https://www.waterboards.ca.gov/water_issues/programs/tmdl/integrated2012.shtml | F38: 303d listed waters; stream lines | G38: Natural | H38: Infrastructure | I38: =VLOOKUP(G38,$M$2:$N$19,2,FALSE) -> d02
A39: p13 | B39: Public Water System Service Area Boundary Tool | C39: Drinking Water Program | D39: Environmental Protection Agency | E39: http://cehtp.org/water/ | F39: drinking water boundaries | G39: Built | H39: Infrastructure | I39: =VLOOKUP(G39,$M$2:$N$19,2,FALSE) -> d01
A40: p13 | B40: Public Water System Service Area Boundary Tool | C40: Drinking Water Program | D40: Environmental Protection Agency | E40: http://cehtp.org/water/ | F40: drinking water quality | G40: Utilities | H40: Use | I40: =VLOOKUP(G40,$M$2:$N$19,2,FALSE) -> d17
A41: p13 | B41: Public Water System Service Area Boundary Tool | C41: Drinking Water Program | D41: Environmental Protection Agency | E41: http://cehtp.org/water/ | F41: drinking water quality | G41: Regulatory | H41: Quality | I41: =VLOOKUP(G41,$M$2:$N$19,2,FALSE) -> d04
A42: p14 | B42: Data Map Services | C42: State Water Resources Control Board | D42: Environmental Protection Agency | E42: http://gispublic.waterboards.ca.gov/arcgis/rest/services | F42: Drought data | G42: Extreme Events | H42: Quantity | I42: =VLOOKUP(G42,$M$2:$N$19,2,FALSE) -> d06
A43: p14 | B43: Data Map Services | C43: State Water Resources Control Board | D43: Environmental Protection Agency | E43: http://gispublic.waterboards.ca.gov/arcgis/rest/services | F43: groundwater GSA, facilities, utilities, drinking water service areasetc. | G43: Built | H43: Infrastructure | I43: =VLOOKUP(G43,$M$2:$N$19,2,FALSE) -> d01
A44: p14 | B44: Data Map Services | C44: State Water Resources Control Board | D44: Environmental Protection Agency | E44: http://gispublic.waterboards.ca.gov/arcgis/rest/services | F44: hydrography | G44: Natural | H44: Infrastructure | I44: =VLOOKUP(G44,$M$2:$N$19,2,FALSE) -> d02
...

Sheet dataEdges
A1: from | B1: to
A2: p01 | B2: d01
A3: p01 | B3: d02
A4: p01 | B4: d03
A5: p01 | B5: d04
A6: p01 | B6: d17
A7: p01 | B7: d08
A8: p01 | B8: d18
A9: p01 | B9: d05
A10: p01 | B10: d10
A11: p01 | B11: d09
A12: p01 | B12: d06
... A124: p37 | B124: d01
