Workbook
Name Infrastructure: #REF!
Name Quality: #REF!
Name Quantity: #REF!
Name Use: #REF!

Sheet readme 
B2: entry differed in value
B3: only one of us included this
B4: question, not sure if should include

Sheet metricsKey
A1: columnName | B1: categories | C1: definition | D1: proposedScore
B2: None | C2: Data are collected but not found.
B3: Unknown | C3: Data are collected and available but not to the public
A4: easeDiscover | B4: Low | C4: Data are not found in the same location and are not searchable. | D4: 1
A5: easeDiscover | B5: Medium | C5: Data found at the same location; however, the search index is poor or inconsistent. | D5: 2
A6: easeDiscover | B6: High | C6: Data found at the same location that can be queried via spatial or text filters with well-defined key words. | D6: 3
A7: methodDiscover | B7: Unknown | C7: Data could not be discovered without seeking permission, registration, or an additional step. | D7: 0
A8: methodDiscover | B8: Website | C8: Data were found by navigating through URL links. | D8: 1
A9: methodDiscover | B9: Catalog | C9: Connects data sources to a searchable, descriptive directory so the user can find and explore the data they need no matter where it's located. | D9: 2
A10: methodDiscover | B10: Map | C10: Data found based on a location (such as watershed, aquifer, or county). | D10: 2
A11: easeAccess | B11: Unknown | C11: Platform shows the data exist, but does not provide any information or means to access the data. | D11: 0
A12: easeAccess | B12: Permission Required | C12: User must request permission to access data. Permission is not guaranteed. | D12: 1
A13: easeAccess | B13: Software Required | C13: User must download or obtain special software to access data. | D13: 1
A14: easeAccess | B14: Training Required | C14: User must undergo training prior to accessing the data. It was not clear whether access is then granted or if it is discretionary. | D14: 1
A15: easeAccess | B15: Registration Required | C15: User must register to access data and permission is automatically granted. Registration can be a useful tool for state agencies to understand how their data are being used. | D15: 2
... A29: fileFormat | B29: Machine readable with open software | C29: Data are machine-readable and include csv, txt, xml, json, geojson, netCDF, etc. | D29: 5
A30: metadata | B30: Unknown | C30: Don't know if they have metadata… usually can't access data
A31: metadata | B31: yes | C31: All the data have metadata
A32: metadata | B32: no | C32: None of the data have metadata
A33: metadata | B33: some | C33: Some data have metadata
A34: metadataFormat | B34: No | C34: No metadata were provided. | D34: 0
A35: metadataFormat | B35: Unknown | C35: Data could not be accessed. It is unknown if metadata are provided. | D35: 1
A36: metadataFormat | B36: Not machine readable | C36: Metadata is not in a machine readable format. It may be located within the text of a pdf. | D36: 1
A37: metadataFormat | B37: Machine readable with proprietary software | C37: Metadata are in a machine readable format that requires proprietary software to access. File formats include excel and word. | D37: 2
A38: metadataFormat | B38: Machine readable with open software | C38: Metadata are in a machine-readable format (typically xml). Sometimes the metadata are part of the data file (for instance, USGS stream gauge data provides metadata within the data download). | D38: 3
A39: dataDefinitions | B39: No | C39: No data glossaries found. | D39: 0
A40: dataDefinitions | B40: Unknown | C40: Data were not publicly accessible and so it is unknown if a data glossary is available. | D40: 0
A41: dataDefinitions | B41: Some | C41: Some data had glossaries. | D41: 1
A42: dataDefinitions | B42: Yes | C42: Data glossaries were available for all data. | D42: 2
A43: metadataAttributes | B43: No | C43: No metadata were provided. | D43: 0
A44: metadataAttributes | B44: Unknown | C44: Data were not publicly accessible so it is unknown if metadata were provided | D44: 0
A45: metadataAttributes | B45: Administrative | C45: Administrative metadata provides information to help manage a resource, such as when and how it was created, file type and other technical information, including quality control, and who can access it. | D45: 1
... A63: lengthAvailable | B63: Period of Record | C63: The full time series for the data are accessible. | D63: 4
A65: List of File Formats | B65: List of Metadata formats
A66: unknown | B66: unknown
A67: pdf | B67: no
A68: jpg | B68: broken link
A69: png | B69: in data
A70: tiff | B70: pdf
A71: excel | B71: word
...

Sheet orgEdges
A1: from | B1: to
A2: calculated in r

Sheet orgNodes
A1: entityID | B1: entity | C1: tier1and2entity | D1: tier1and2entityID | E1: entityIDAbove | F1: mission | G1: website | H1: operational | I1: decision | J1: regulatory | K1: research | L1: level
A2: n01 | B2: Colorado | C2: Colorado | D2: 1 | E2: NA | G2: https://www.colorado.com/ | H2: Yes | I2: Yes | J2: Yes | K2: Yes | L2: 1
A3: n02 | B3: Department of Natural Resources | C3: Department of Natural Resources | D3: 2 | E3: n01 | F3: manage and conserve Colorado’s natural resources for the benefit of people today – and tomorrow | G3: https://cdnr.us/#/start | H3: Yes | I3: Yes | J3: Yes | K3: Yes | L3: 2
A4: n03 | B4: Colorado Avalance Information Center | C4: Department of Natural Resources | D4: 2 | E4: n02 | F4: to provide avalanche information, education and promote research for the protection of life, property and the enhancement of the state’s economy. | G4: https://avalanche.state.co.us/ | H4: No | I4: No | J4: No | K4: Yes | L4: 3
A5: n04 | B5: Division of Forestry | C5: Department of Natural Resources | D5: 2 | E5: n02 | F5: achieve stewardship of Colorado’s diverse forest environments for the benefit of present and future generations. | G5: https://csfs.colostate.edu/ | H5: No | I5: Yes | J5: No | K5: No | L5: 3
A6: n05 | B6: Division of Reclamation, Mining & Safety | C6: Department of Natural Resources | D6: 2 | E6: n02 | F6: protect the public, miners and the environment during current mining operations, restore abandoned mines, and to ensure that all mined land is reclaimed to beneficial use. | G6: https://www.colorado.gov/drms | H6: Yes | I6: No | J6: Yes | K6: No | L6: 3
A7: n06 | B7: Colorado Oil & Gas Conservation Commision | C7: Department of Natural Resources | D7: 2 | E7: n02 | F7: regulate the development and production of the natural resources of oil and gas in the state of Colorado in a manner that protects public health, safety, welfare, the environment and wildlife resources. | G7: http://cogcc.state.co.us/ | H7: No | I7: No | J7: Yes | K7: No | L7: 3
A8: n07 | B8: Division of Parks & Wildlife | C8: Department of Natural Resources | D8: 2 | E8: n02 | F8: perpetuate the wildlife resources of the state, to provide a quality state parks system, and to provide enjoyable and sustainable outdoor recreation opportunities that educate and inspire current and future generations to serve as active stewards of Colorado's natural resources. | G8: http://cpw.state.co.us/ | H8: No | I8: Yes | J8: No | K8: No | L8: 3
A9: n08 | B9: Division of Water Resources | C9: Department of Natural Resources | D9: 2 | E9: n02 | F9: administer the waters of the State to maximize lawful beneficial use, ensure that dams and water wells are properly constructed and safe, and provide information about water resources to the public. | G9: http://water.state.co.us | H9: Yes | I9: Yes | J9: Yes | K9: Yes | L9: 3
A10: n09 | B10: Dam Safety Program | C10: Departmentof Natural Resources | D10: 2 | E10: n08 | F10: carries out two principal statutorily defined duties; determining the safe storage level of the reservoir dams, and reviewing and approving plans and specifications for the construction and repair of Jurisdictional dams, modern dam safety best-practice includes an assortment of engineering and risk management tools | G10: https://dwr.colorado.gov/services/dam-safety | H10: Yes | I10: No | J10: Yes | K10: No | L10: 4
A11: n10 | B11: Data and Information Program | C11: Departmentof Natural Resources | D11: 2 | E11: n08 | F11: supports and maintains DWR's database of streamflows, diversion records, lake storage levels, water rights and more in order to support water administration and inform the public | G11: https://dwr.colorado.gov/services/data-information | H11: Yes | I11: Yes | J11: No | K11: No | L11: 4
A12: n11 | B12: Water Administration | C12: Departmentof Natural Resources | D12: 2 | E12: n08 | F12: administers water rights calls | G12: https://dwr.colorado.gov/services/water-administration | H12: Yes | I12: No | J12: Yes | K12: No | L12: 4
A13: n12 | B13: Well Construction and Inspection Program | C13: Departmentof Natural Resources | D13: 2 | E13: n08 | F13: protects the groundwater resources and public health through enforcement of minimum well construction and pump installation standards | G13: https://dwr.colorado.gov/services/well-construction-inspection | H13: No | I13: No | J13: Yes | K13: No | L13: 4
A14: n13 | B14: Well Metering Program | C14: Departmentof Natural Resources | D14: 2 | E14: n08 | F14: oversees State Engineer rules on measuring groundwater with interstate compacts and intrabasin concerns | G14: https://dwr.colorado.gov/services/well-metering | H14: Yes | I14: Yes | J14: Yes | K14: No | L14: 4
... A33: n32 | B33: Colorado Public Utilities Commission | C33: Department of Regulatory Agencies | D33: 5 | E33: n31 | F33: effectively regulating utilities and facilities so that the people of Colorado receive safe, reliable, and reasonably-priced services consistent with the economic, environmental and social values of our state. | G33: https://puc.colorado.gov/ | H33: No | I33: No | J33: Yes | K33: Yes | L33: 3
A34: n33 | B34: Energy Section | C34: =C32 -> Department of Regulatory Agencies | D34: =D32 -> 5 | E34: n32 | F34: responsible for supporting the mission of the Commission to assure the availability of safe, reliable, adequate, and efficient electric, gas, steam and water services to utility customers at rates that are just, reasonable, and not discriminatory. | G34: https://puc.colorado.gov/energyandwater | H34: No | I34: No | J34: Yes | K34: Yes | L34: 4
A35: n34 | B35: Colorado State University | C35: Colorado State University | D35: 6 | E35: n01 | G35: https://www.colostate.edu/ | H35: No | I35: Yes | J35: No | K35: Yes | L35: 2
A36: n35 | B36: Colorado Climate Center | C36: Colorado State University | D36: 6 | E36: n34 | F36: providing information and expertise on Colorado's complex climate | G36: https://climate.colostate.edu/ | H36: No | I36: Yes | J36: No | K36: Yes | L36: 3
A37: n36 | B37: Colorado School of Mines | C37: Colorado School of Mines | D37: 7 | E37: n01 | F37: focused on science and engineering, where students and faculty together address the great challenges society faces today—particularly those related to the Earth, energy and the environment. | G37: https://www.mines.edu/ | H37: No | I37: Yes | J37: No | K37: Yes | L37: 2
A38: n37 | B38: Colorado Geologic Survey | C38: =B37 -> Colorado School of Mines | D38: 7 | E38: n36 | F38: To help reduce the impact of geologic hazards on the citizens of Colorado; to promote responsible economic development of mineral and energy resources; to provide geologic insight into water resources; and to proffer sound geologic advice and information to a variety of constituencies. | G38: https://coloradogeologicalsurvey.org/ | H38: No | I38: Yes | J38: No | K38: Yes | L38: 3
A39: n38 | B39: Water Program | C39: =B38 -> Colorado Geologic Survey | D39: 7 | E39: n37 | F39: studying how geology and human activities impact Colorado’s important groundwater resources. | G39: https://coloradogeologicalsurvey.org/water/ | H39: No | I39: No | J39: No | K39: Yes | L39: 4
A40: n39 | B40: Department of Transportation | C40: Department of Transportation | D40: 8 | E40: n01 | F40: To provide the best multi-modal transportation system for Colorado that most effectively and safely moves people, goods, and information. | G40: https://www.codot.gov/ | H40: Yes | I40: Yes | J40: Yes | K40: No | L40: 2
A41: n40 | B41: Environmental Programs Branch | C41: Department of Transportation | D41: 8 | E41: n39 | F41: manages environmental policy, environmental procedure, programmatic agreements and environmental data to inform the planning and project development process | G41: https://www.codot.gov/programs/environmental | H41: Yes | I41: No | J41: No | K41: No | L41: 3
A42: n41 | B42: Water Quality Section | C42: Department of Transportation | D42: 8 | E42: n40 | F42: Ensure the quality of stormwater runoff is protected while Colorado's roadways are constructed, operated, and maintained;Promote innovative control measures (i.e. best management practices);Provide effective water quality education to CDOT staff; and facilitate cooperation between CDOT, watershed groups, and other water quality program managers, businesses and the public | G42: https://www.codot.gov/programs/environmental/water-quality | H42: Yes | I42: No | J42: No | K42: No | L42: 4
A43: n42 | B43: Environmental Policy and Biological Resources Section | C43: Department of Transportation | D43: 8 | E43: n40 | F43: provide technical assistance for transportation project developmentand construction with the goal of an overall benefit to the aquatic ecosystems in Colorado | G43: https://www.codot.gov/programs/environmental/wetlands/overview.html | H43: Yes | I43: No | J43: No | K43: No | L43: 4
A44: n43 | B44: Colorado Information Marketplace | C44: Office of Information | D44: 9 | E44: n01 | F44: Colorado's open data at your fingertips | G44: https://data.colorado.gov/ | H44: No | I44: Yes | J44: No | K44: Yes | L44: 2

Sheet platformNodes
A1: platformID | B1: platform | C1: entity | D1: entityID | E1: webLabel | F1: heatmapLabel | G1: tier1and2entity | H1: tier1and2entityID | I1: website | J1: easeDiscover | K1: methodDiscover | L1: easeAccess | M1: methodAccess | N1: LinktoSource | O1: fileFormat | P1: metadata | Q1: metadataFormat | R1: dataDefinitions | S1: metaAttributes | T1: metadataStandards | U1: timeliness | V1: lengthAvailable | W1: Notes
A2: p01 | B2: Observations Data | C2: Colorado Avalance Information Center | D2: n03 | E2: CDNR | F2: =CONCATENATE(E2,": ",B2) -> CDNR: Observations Data | G2: Department of Natural Resources | H2: n02 | I2: https://avalanche.state.co.us/observations/weather-stations/ | J2: Medium | K2: Website; Catalog | L2: Yes | M2: Copy and Paste; Batch Export | N2: Not Applicable | O2: html; csv | P2: yes | Q2: in data | R2: No | S2: Descriptive | T2: No | U2: Daily or Higher | V2: Limited Record
A3: p02 | B3: Colorado Oil and Gas Information System | C3: Colorado Oil and Gas Conservation Commision | D3: n06 | E3: COGCC | F3: =CONCATENATE(E3,": ",B3) -> COGCC: Colorado Oil and Gas Information System | G3: Department of Natural Resources | H3: n02 | I3: https://cogcc.state.co.us/COGIS/LiveQuery.html | J3: High | K3: Catalog | L3: Yes | M3: Individual Export; Copy and Paste | N3: Not Applicable | O3: excel; pdf; html | P3: yes | Q3: in data | R3: No | S3: Descriptive; Structural | T3: No | U3: Monthly or Higher | V3: Period of Record
A4: p22 | B4: Data Downloads | C4: Colorado Oil and Gas Conservation Commision | D4: n06 | E4: COGCC | F4: =CONCATENATE(E4,": ",B4) -> COGCC: Data Downloads | G4: Department of Natural Resources | H4: n02 | I4: https://cogcc.state.co.us/data2.html#/downloads | J4: High | K4: Website | L4: Yes | M4: Full Export | N4: Not Applicable | O4: excel; access; shapefile; pdf; zip | P4: some | Q4: pdf | R4: Yes | S4: Administrative; Descriptive | T4: Yes | U4: Monthly or Higher | V4: Period of Record | W4: Definitions as formation codes
A5: p23 | B5: Reports Portal | C5: Colorado Oil and Gas Conservation Commision | D5: n06 | E5: COGCC | F5: =CONCATENATE(E5,": ",B5) -> COGCC: Reports Portal | G5: Department of Natural Resources | H5: n02 | I5: https://cogcc.state.co.us/COGCCReports/production.aspx?id=MonthlyWaterProdByCounty | J5: High | K5: Catalog | L5: Yes | M5: Individual Export | N5: Not Applicable | O5: excel; pdf; csv; xml | P5: some | Q5: pdf; html | R5: Yes | S5: Administrative | T5: No | U5: Monthly or Higher | V5: Period of Record
A6: p03 | B6: CDSS Data and Tools | C6: Division of Water Resources | D6: n08 | E6: CDWR | F6: =CONCATENATE(E6,": ",B6) -> CDWR: CDSS Data and Tools | G6: Department of Natural Resources | H6: n02 | I6: https://dwr.state.co.us/tools | J6: Medium | K6: Catalog; Map | L6: Yes | M6: Full Export; Batch Export | N6: Not Applicable | O6: pdf; html; csv; shapefile; geodatabase; raster; excel | P6: yes | Q6: unknown | R6: No | S6: Descriptive; Administrative; Structural | T6: Unknown | U6: Varies | V6: Varies | W6: some datasets had metadata-ish attributes,
A7: p04 | B7: Imaged Documents | C7: Division of Water Resources | D7: n08 | E7: CDWR | F7: =CONCATENATE(E7,": ",B7) -> CDWR: Imaged Documents | G7: Department of Natural Resources | H7: n02 | I7: https://dnrweblink.state.co.us/dwr/ | J7: Medium | K7: Catalog | L7: Yes | M7: Individual Export | N7: Not Applicable | O7: pdf | P7: some | Q7: in data | R7: Some | S7: Descriptive | T7: No | U7: Varies | V7: Period of Record
A8: p50 | B8: GIS Data | C8: Division of Water Resources | D8: n08 | E8: CDWR | F8: =CONCATENATE(E8,": ",B8) -> CDWR: GIS Data | G8: Department of Natural Resources | H8: n02 | I8: https://www.colorado.gov/pacific/cdss/gis-data | J8: Medium | K8: Website | L8: Yes | M8: Full Export | N8: Not Applicable | O8: zip; shapefile; geodatabase | P8: yes | Q8: xml; html | R8: No | S8: Descriptive; Administrative | T8: Yes | U8: Varies | V8: Current Only
A9: p51 | B9: Modeling Data | C9: Division of Water Resources | D9: n08 | E9: CDWR | F9: =CONCATENATE(E9,": ",B9) -> CDWR: Modeling Data | G9: Department of Natural Resources | H9: n02 | I9: https://www.colorado.gov/pacific/cdss/modeling-data | J9: Medium | K9: Website | L9: Yes | M9: Full Export | N9: Not Applicable | O9: software specific; excel | P9: yes | Q9: pdf | R9: Some | S9: Descriptive; Administrative | T9: No | U9: Varies | V9: Period of Record
A10: p20 | B10: Surface Water Conditions | C10: Division of Water Resources | D10: n08 | E10: CDWR | F10: =CONCATENATE(E10,": ",B10) -> CDWR: Surface Water Conditions | G10: Department of Natural Resources | H10: n02 | I10: https://dwr.state.co.us/surfacewater/default.aspx | J10: Medium | K10: Catalog | L10: Yes | M10: Individual Export; Link to Source | N10: Broken Links | O10: txt | P10: yes | Q10: in data | R10: No | S10: Administrative | T10: No | U10: Daily or Higher | V10: Limited Record | W10: will be removed 11/1/2020
A11: p05 | B11: Open Data | C11: Department of Public Health and Environment | D11: n21 | E11: CDPHE | F11: =CONCATENATE(E11,": ",B11) -> CDPHE: Open Data | G11: Department of Public Health and Environment | H11: n21 | I11: https://data-cdphe.opendata.arcgis.com/ | J11: Medium | K11: Catalog | L11: Yes | M11: Full Export | N11: Not Applicable | O11: excel; shapefile; kml | P11: yes | Q11: html; xml | R11: Yes | S11: Descriptive; Administrative; Structural | T11: Yes | U11: Varies | V11: Varies
A12: p06 | B12: Clean Water - GIS Maps | C12: Clean Water Program | D12: n23 | E12: CDPHE | F12: =CONCATENATE(E12,": ",B12) -> CDPHE: Clean Water - GIS Maps | G12: Department of Public Health and Environment | H12: n21 | I12: https://www.colorado.gov/pacific/cdphe/clean-water-gis-maps | J12: Medium | K12: Website | L12: Yes | M12: Individual Export | N12: Not Applicable | O12: shapefile; geodatabase; zip | P12: yes | Q12: xml | R12: Yes | S12: Descriptive; Administrative | T12: Yes | U12: Unknown | V12: Current only
A13: p07 | B13: Watershed Rapid Assessment Program | C13: Clean Water Program | D13: n23 | E13: CDPHE | F13: =CONCATENATE(E13,": ",B13) -> CDPHE: Watershed Rapid Assessment Program | G13: Department of Public Health and Environment | H13: n21 | I13: https://erams.com/wrap | J13: Medium | K13: Map | L13: Yes | M13: Batch Export | N13: Not Applicable | O13: png; pdf; csv; excel; shapefile | P13: yes | Q13: html | R13: No | S13: Descriptive; Administrative | T13: Yes | U13: Daily or Higher | V13: Varies | W13: This tool is really cool
A14: p09 | B14: Water Quality Planning | C14: Clean Water Program | D14: n23 | E14: CDPHE | F14: =CONCATENATE(E14,": ",B14) -> CDPHE: Water Quality Planning | G14: Department of Public Health and Environment | H14: n21 | I14: https://www.colorado.gov/pacific/cdphe/wq-planning | J14: Medium | K14: Website | L14: Yes | M14: Individual Export | N14: Not Applicable | O14: pdf | P14: yes | Q14: in data | R14: No | S14: Administrative | T14: No | U14: Unknown | V14: Limited Record
A15: p10 | B15: Agricultural Water Quality Database | C15: Agricultural Water Quality Program | D15: n29 | E15: CDA | F15: =CONCATENATE(E15,": ",B15) -> CDA: Agricultural Water Quality Database | G15: Department of Agriculture | H15: n27 | I15: https://erams.com/co_agwaterquality/search_data | J15: High | K15: Website | L15: Yes | M15: Individual Export | N15: Not Applicable | O15: csv | P15: no | Q15: no | R15: No | S15: No | T15: No | U15: Unknown | V15: Period of Record
A16: p12 | B16: Drinking water compliance assurance | C16: Safe Drinking Water Program | D16: n24 | E16: CDPHE | F16: =CONCATENATE(E16,": ",B16) -> CDPHE: Drinking water compliance assurance | G16: Department of Public Health and Environment | H16: n21 | I16: https://www.colorado.gov/pacific/cdphe/drinking-water-consumer-information | J16: Medium | K16: Website; Catalog | L16: Yes | M16: Full Export; Individual Export | N16: Not Applicable | O16: csv; excel | P16: some | Q16: pdf | R16: Yes | S16: Administrative | T16: No | U16: Monthly or Higher | V16: Period of Record
A17: p13 | B17: Colorado Environmental Records | C17: Department of Public Health and Environment | D17: n21 | E17: CDPHE | F17: =CONCATENATE(E17,": ",B17) -> CDPHE: Colorado Environmental Records | G17: Department of Public Health and Environment | H17: n21 | I17: https://environmentalrecords.colorado.gov/HPRMWebDrawer/search | J17: Medium | K17: Catalog | L17: Yes | M17: Individual Export | N17: Not Applicable | O17: pdf | P17: yes | Q17: in data | R17: No | S17: Administrative | T17: Yes | U17: Unknown | V17: Period of Record
A18: p14 | B18: Water quality 10-year roadmap | C18: Clean Water Program | D18: n23 | E18: CDPHE | F18: =CONCATENATE(E18,": ",B18) -> CDPHE: Water quality 10-year roadmap | G18: Department of Public Health and Environment | H18: n21 | I18: https://www.colorado.gov/pacific/cdphe/WQ-10-Year-Roadmap | J18: Medium | K18: Website | L18: Yes | M18: Individual Export | N18: Not Applicable | O18: pdf | P18: yes | Q18: in data | R18: No | S18: Descriptive; Structural | T18: No | U18: Unknown | V18: Current only
A19: p15 | B19: Animas River reports, data and maps | C19: Clean Water Program | D19: n23 | E19: CDPHE | F19: =CONCATENATE(E19,": ",B19) -> CDPHE: Animas River reports, data and maps | G19: Department of Public Health and Environment | H19: n21 | I19: https://www.colorado.gov/pacific/cdphe/animas-river-spill | J19: Medium | K19: Website | L19: Yes | M19: Individual Export | N19: Not Applicable | O19: pdf; excel; shapefile | P19: yes | Q19: in data | R19: some | S19: Descriptive | T19: No | U19: Unknown | V19: Period of Record
A20: p16 | B20: Publications | C20: =orgNodes!B38 -> Colorado Geologic Survey | D20: n37 | E20: CGS | F20: =CONCATENATE(E20,": ",B20) -> CGS: Publications | G20: Colorado School of Mines | H20: n36 | I20: https://coloradogeologicalsurvey.org/gis-data-map-portal/ | J20: Medium | K20: Website | L20: Yes | M20: Individual Export | N20: Not Applicable | O20: shapefile | P20: some | Q20: xml | R20: No | S20: Administrative | T20: No | U20: Unknown | V20: Unknown
A21: p17 | B21: Total Maximum Daily Loads (TMDLs) | C21: Clean Water Program | D21: n23 | E21: CDPHE | F21: =CONCATENATE(E21,": ",B21) -> CDPHE: Total Maximum Daily Loads (TMDLs) | G21: Department of Public Health and Environment | H21: n21 | I21: https://www.colorado.gov/pacific/cdphe/total-maximum-daily-loads-tmdls | J21: Medium | K21: Website | L21: Yes | M21: Individual Export | N21: Not Applicable | O21: pdf | P21: yes | Q21: in data | R21: No | S21: Descriptive | T21: Unknown | U21: Unknown | V21: Period of Record
A22: p18 | B22: Colorado Information Marketplace | C22: Colorado | D22: n43 | E22: CO | F22: =CONCATENATE(E22,": ",B22) -> CO: Colorado Information Marketplace | G22: Colorado | H22: n42 | I22: https://data.colorado.gov/ | J22: Medium | K22: Catalog | L22: Yes | M22: Web Services; Full Export | N22: Not Applicable | O22: csv; tsv; rdf; xml; rss | P22: yes | Q22: html | R22: Yes | S22: Administrative; Descriptive; Structural | T22: Yes | U22: Varies | V22: Varies | W22: Z: p also included map for methodaccess and marked export method as batch - Z marked individual since you can only export one dataset at a time?
A23: p19 | B23: Colorado's Water Plan | C23: Water Conservation Board | D23: n02 | E23: CDWR | F23: =CONCATENATE(E23,": ",B23) -> CDWR: Colorado's Water Plan | G23: Department of Natural Resources | H23: n02 | I23: https://www.colorado.gov/pacific/cowaterplan | J23: Medium | K23: Website | L23: Yes | M23: Individual Export | N23: Not Applicable | O23: pdf; excel; csv | P23: yes | Q23: in data | R23: some | S23: Descriptive; Structural | T23: Yes | U23: Daily or Higher | V23: Varies
A24: p25 | B24: Colorado hazadous waste site assessments | C24: Disease Control and Environmental Epidemiology | D24: n26 | E24: CDPHE | F24: =CONCATENATE(E24,": ",B24) -> CDPHE: Colorado hazadous waste site assessments | G24: Department of Public Health and Environment | H24: n21 | I24: https://www.colorado.gov/pacific/cdphe/colorado-site-assessments | J24: Medium | K24: Website | L24: Yes | M24: Individual Export | N24: Not Applicable | O24: pdf | P24: no | Q24: no | R24: no | S24: no | T24: no | U24: Varies | V24: Period of Record
A25: p26 | B25: Clean water active permits | C25: Clean Water Program | D25: n23 | E25: CDPHE | F25: =CONCATENATE(E25,": ",B25) -> CDPHE: Clean water active permits | G25: Department of Public Health and Environment | H25: n21 | I25: https://www.colorado.gov/pacific/cdphe/clean-water-active-permits | J25: Medium | K25: Website | L25: Yes | M25: Full Export | N25: Not Applicable | O25: excel | P25: no | Q25: no | R25: no | S25: no | T25: no | U25: Unknown | V25: Current only
A26: p27 | B26: Abandoned Mines Water Quality Study | C26: Clean Water Program | D26: n23 | E26: CDPHE | F26: =CONCATENATE(E26,": ",B26) -> CDPHE: Abandoned Mines Water Quality Study | G26: Department of Public Health and Environment | H26: n21 | I26: https://www.colorado.gov/pacific/cdphe/WQ-Mine-Impacted-Streams-Task-Force | J26: Medium | K26: Website | L26: Yes | M26: Individual Export | N26: Not Applicable | O26: pdf; excel | P26: some | Q26: in data | R26: Some | S26: Descriptive | T26: Yes | U26: Varies | V26: Limited Record
A27: p28 | B27: Aquatic pesticides permit | C27: Clean Water Program | D27: n23 | E27: CDPHE | F27: =CONCATENATE(E27,": ",B27) -> CDPHE: Aquatic pesticides permit | G27: Department of Public Health and Environment | H27: n21 | I27: https://www.colorado.gov/pacific/cdphe/wq-pesticides-permits | J27: Medium | K27: Website | L27: Yes | M27: Individual Export | N27: Not Applicable | O27: pdf; excel | P27: some | Q27: in data | R27: No | S27: Descriptive | T27: Yes | U27: Varies | V27: Varies
A28: p29 | B28: Measurable Results Program | C28: Clean Water Program | D28: n23 | E28: CDPHE | F28: =CONCATENATE(E28,": ",B28) -> CDPHE: Measurable Results Program | G28: Department of Public Health and Environment | H28: n21 | I28: https://www.colorado.gov/pacific/cdphe/clean-water-measurable-results-program | J28: Medium | K28: Website | L28: Yes | M28: Individual Export | N28: Not Applicable | O28: pdf | P28: some | Q28: in data | R28: No | S28: Descriptive | T28: Yes | U28: Unknown | V28: Varies
A29: p30 | B29: On Site Wastewater treatment systems | C29: Clean Water Program | D29: n23 | E29: CDPHE | F29: =CONCATENATE(E29,": ",B29) -> CDPHE: On Site Wastewater treatment systems | G29: Department of Public Health and Environment | H29: n21 | I29: https://www.colorado.gov/pacific/cdphe/clean-water-site-wastewater-treatment-systems | J29: Medium | K29: Website | L29: Yes | M29: Individual Export | N29: Not Applicable | O29: pdf | P29: some | Q29: in data | R29: No | S29: Descriptive | T29: Yes | U29: Yearly or Higher | V29: Limited Record
A30: p31 | B30: PFAS 2020 Sampling Project | C30: Safe Drinking Water Program | D30: n24 | E30: CDPHE | F30: =CONCATENATE(E30,": ",B30) -> CDPHE: PFAS 2020 Sampling Project | G30: Department of Public Health and Environment | H30: n21 | I30: https://cohealthviz.dphe.state.co.us/t/EnvironmentalEpidemiologyPublic/views/PFAS_PWS_ParticipationDash/PFAS_Sampling_Participation?:origin=card_share_linkand:embed=yand:isGuestRedirectFromVizportal=y | J30: Medium | K30: Map | L30: Yes | M30: Individual Export; Full Export | N30: Not Applicable | O30: pdf; png; excel | P30: no | Q30: no | R30: no | S30: no | T30: no | U30: Monthly or Higher | V30: Period of Record | W30: https://cohealthviz.dphe.state.co.us/t/EnvironmentalEpidemiologyPublic/views/PFAS_results_DRAFT/Download?%3AshowAppBanner=false&%3Adisplay_count=n&%3AshowVizHome=n&%3Aorigin=viz_share_link&%3AisGuestRedirectFromVizportal=y&%3Aembed=y
A31: p32 | B31: Consumer Confidence Rule | C31: Safe Drinking Water Program | D31: n24 | E31: CDPHE | F31: =CONCATENATE(E31,": ",B31) -> CDPHE: Consumer Confidence Rule | G31: Department of Public Health and Environment | H31: n21 | I31: https://www.colorado.gov/cdphe/ccr | J31: Medium | K31: Website | L31: Yes | M31: Individual export | N31: Not Applicable | O31: word | P31: yes | Q31: in data | R31: Yes | S31: Descriptive | T31: Yes | U31: Unknown | V31: Period of Record
A32: p33 | B32: Web Public Water System and Violation | C32: Safe Drinking Water Program | D32: n24 | E32: CDPHE | F32: =CONCATENATE(E32,": ",B32) -> CDPHE: Web Public Water System and Violation | G32: Department of Public Health and Environment | H32: n21 | I32: https://datastudio.google.com/reporting/18DpQAMm-riBo5DfqEUCgDqMspPPhu-Ul/page/q5Fz | J32: Medium | K32: Catalog | L32: Yes | M32: Full Export; Batch Export | N32: Not Applicable | O32: pdf; csv; excel | P32: yes | Q32: in data | R32: Yes | S32: Administrative; Descriptive; Structural | T32: yes | U32: Monthly or Higher | V32: Period of Record
A33: p35 | B33: Environmental Data | C33: Department of Public Health and Environment | D33: n21 | E33: CDPHE | F33: =CONCATENATE(E33,": ",B33) -> CDPHE: Environmental Data | G33: Department of Public Health and Environment | H33: n21 | I33: https://coepht.colorado.gov/environmental-data | J33: Medium | K33: Website | L33: Yes | M33: Individual Export | N33: Not Applicable | O33: pdf; excel | P33: Yes | Q33: pdf; html | R33: No | S33: Descriptive; Administrative | T33: Yes | U33: Varies | V33: Limited Record
A34: p39 | B34: Utility Providers | C34: Energy Section | D34: n33 | E34: PUC | F34: =CONCATENATE(E34,": ",B34) -> PUC: Utility Providers | G34: Department of Regulatory Agencies | H34: n31 | I34: https://puc.colorado.gov/utilityproviders | J34: Medium | K34: Website | L34: Yes | M34: Full Export | N34: Not Applicable | O34: pdf | P34: no | Q34: no | R34: No | S34: No | T34: No | U34: Monthly or Higher | V34: Current only
A35: p40 | B35: Regions Single POA Reports | C35: Water Quality Section | D35: n41 | E35: DOT | F35: =CONCATENATE(E35,": ",B35) -> DOT: Regions Single POA Reports | G35: Department of Transportation | H35: n39 | I35: https://www.codot.gov/business/hydraulics/regions-single-poa-reports | J35: Low | K35: Website | L35: Yes | M35: Individual Export | N35: Not Applicable | O35: pdf | P35: some | Q35: in data | R35: No | S35: Descriptive | T35: Some | U35: Varies | V35: Limited Record
A36: p42 | B36: Wet Weather Monitoring Program | C36: Water Quality Section | D36: n41 | E36: DOT | F36: =CONCATENATE(E36,": ",B36) -> DOT: Wet Weather Monitoring Program | G36: Department of Transportation | H36: n39 | I36: https://www.codot.gov/programs/environmental/water-quality/stormwater-programs/wet-weather-monitoring-program | J36: Low | K36: Website | L36: Yes | M36: Full Export | N36: Not Applicable | O36: pdf; excel | P36: some | Q36: in data | R36: No | S36: No | T36: Some | U36: Varies | V36: Varies
A37: p48 | B37: Energy and Water Reports to the Legislature | C37: Energy and Water | D37: n33 | E37: PUC | F37: =CONCATENATE(E37,": ",B37) -> PUC: Energy and Water Reports to the Legislature | G37: Department of Regulatory Agencies | H37: n31 | I37: https://puc.colorado.gov/energyandwaterreports | J37: Medium | K37: Website | L37: Yes | M37: Individual Export | O37: pdf | P37: some | Q37: in data | R37: No | S37: Descriptive | T37: Some | U37: Yearly or Higher | V37: Limited Record

Sheet dataNodeTypes
A1: platformID | B1: platform | C1: entity | D1: tier1and2entity | E1: website | F1: data | G1: dataGroup | H1: dataCategory | I1: dataID | J1: notes | M1: dataGroup - linked to dataNodes tab | N1: dataID - linked to dataNodes tab
A2: p01 | B2: Weather Station | C2: Colorado Avalance Information Center | D2: Department of Natural Resources | E2: https://avalanche.state.co.us/observations/weather-stations/ | F2: rainfall | G2: Precipitation | H2: =VLOOKUP(G2,dataNodes!$B$2:$C$19,2,FALSE) -> Quantity | I2: =VLOOKUP(G2,$M$2:$N$20,2,FALSE) -> d10 | M2: =dataNodes!B2 -> Built | N2: =dataNodes!A2 -> d01
A3: p01 | B3: Weather Station | C3: Colorado Avalance Information Center | D3: Department of Natural Resources | E3: https://avalanche.state.co.us/observations/weather-stations/ | F3: meterology data | G3: Meteorology | H3: =VLOOKUP(G3,dataNodes!$B$2:$C$19,2,FALSE) -> Quantity | I3: =VLOOKUP(G3,$M$2:$N$20,2,FALSE) -> d09 | M3: =dataNodes!B3 -> Natural | N3: =dataNodes!A3 -> d02
A4: p01 | B4: Weather Station | C4: Colorado Avalance Information Center | D4: Department of Natural Resources | E4: https://avalanche.state.co.us/observations/weather-stations/ | F4: snowfall | G4: Glacial and Snow | H4: =VLOOKUP(G4,dataNodes!$B$2:$C$19,2,FALSE) -> Quantity | I4: =VLOOKUP(G4,$M$2:$N$20,2,FALSE) -> d07 | M4: =dataNodes!B4 -> Quality | N4: =dataNodes!A4 -> d03
A5: p02 | B5: Colorado Oil and Gas Information System | C5: Colorado Oil & Gas Conservation Commision | D5: Department of Natural Resources | E5: https://cogcc.state.co.us/COGIS/LiveQuery.html | F5: water production associated with oil & gas production | G5: Use | H5: =VLOOKUP(G5,dataNodes!$B$2:$C$19,2,FALSE) -> Use | I5: =VLOOKUP(G5,$M$2:$N$20,2,FALSE) -> d16 | M5: =dataNodes!B5 -> Regulatory | N5: =dataNodes!A5 -> d04
A6: p02 | B6: Colorado Oil and Gas Information System | C6: Colorado Oil & Gas Conservation Commision | D6: Department of Natural Resources | E6: https://cogcc.state.co.us/COGIS/LiveQuery.html | F6: water production associated with oil & gas production | G6: Groundwater | H6: =VLOOKUP(G6,dataNodes!$B$2:$C$19,2,FALSE) -> Quantity | I6: =VLOOKUP(G6,$M$2:$N$20,2,FALSE) -> d08 | M6: =dataNodes!B6 -> Evapotranspiration | N6: =dataNodes!A6 -> d05
A7: p02 | B7: Colorado Oil and Gas Information System | C7: Colorado Oil & Gas Conservation Commision | D7: Department of Natural Resources | E7: https://cogcc.state.co.us/COGIS/LiveQuery.html | F7: spill incidents | G7: Regulatory | H7: =VLOOKUP(G7,dataNodes!$B$2:$C$19,2,FALSE) -> Quality | I7: =VLOOKUP(G7,$M$2:$N$20,2,FALSE) -> d04 | M7: =dataNodes!B7 -> Extreme Events | N7: =dataNodes!A7 -> d06
A8: p22 | B8: COGCC Data Downloads | C8: Colorado Oil & Gas Conservation Commision | D8: Department of Natural Resources | E8: https://cogcc.state.co.us/data2.html#/downloads | F8: well shapefile | G8: Built | H8: =VLOOKUP(G8,dataNodes!$B$2:$C$19,2,FALSE) -> Infrastructure | I8: =VLOOKUP(G8,$M$2:$N$20,2,FALSE) -> d01 | M8: =dataNodes!B8 -> Glacial and Snow | N8: =dataNodes!A8 -> d07
A9: p22 | B9: COGCC Data Downloads | C9: Colorado Oil & Gas Conservation Commision | D9: Department of Natural Resources | E9: https://cogcc.state.co.us/data2.html#/downloads | F9: well water, water produced | G9: Groundwater | H9: =VLOOKUP(G9,dataNodes!$B$2:$C$19,2,FALSE) -> Quantity | I9: =VLOOKUP(G9,$M$2:$N$20,2,FALSE) -> d08 | M9: =dataNodes!B9 -> Groundwater | N9: =dataNodes!A9 -> d08
A10: p22 | B10: COGCC Data Downloads | C10: Colorado Oil & Gas Conservation Commision | D10: Department of Natural Resources | E10: https://cogcc.state.co.us/data2.html#/downloads | F10: spill incidents | G10: Regulatory | H10: =VLOOKUP(G10,dataNodes!$B$2:$C$19,2,FALSE) -> Quality | I10: =VLOOKUP(G10,$M$2:$N$20,2,FALSE) -> d04 | M10: =dataNodes!B10 -> Meteorology | N10: =dataNodes!A10 -> d09
A11: p22 | B11: COGCC Data Downloads | C11: Colorado Oil & Gas Conservation Commision | D11: Department of Natural Resources | E11: https://cogcc.state.co.us/data2.html#/downloads | F11: water produced | G11: Use | H11: =VLOOKUP(G11,dataNodes!$B$2:$C$19,2,FALSE) -> Use | I11: =VLOOKUP(G11,$M$2:$N$20,2,FALSE) -> d16 | M11: =dataNodes!B11 -> Precipitation | N11: =dataNodes!A11 -> d10
A12: p23 | B12: COGCC Reports Portal | C12: Colorado Oil & Gas Conservation Commision | D12: Department of Natural Resources | E12: https://cogcc.state.co.us/COGCCReports/production.aspx?id=MonthlyWaterProdByCounty | F12: Water production by county (oil and gas sites) | G12: Use | H12: =VLOOKUP(G12,dataNodes!$B$2:$C$19,2,FALSE) -> Use | I12: =VLOOKUP(G12,$M$2:$N$20,2,FALSE) -> d16 | M12: =dataNodes!B12 -> Reservoir | N12: =dataNodes!A12 -> d11
A13: p03 | B13: CDSS Data & Tools | C13: Division of Water Resources | D13: Department of Natural Resources | E13: https://dwr.state.co.us/tools/ | F13: weather data | G13: Meteorology | H13: =VLOOKUP(G13,dataNodes!$B$2:$C$19,2,FALSE) -> Quantity | I13: =VLOOKUP(G13,$M$2:$N$20,2,FALSE) -> d09 | M13: =dataNodes!B13 -> Soil | N13: =dataNodes!A13 -> d12
... A19: p03 | B19: CDSS Data & Tools | C19: Division of Water Resources | D19: Department of Natural Resources | E19: https://dwr.state.co.us/tools/ | F19: NDVI indicated irrigation data | G19: Irrigation | H19: =VLOOKUP(G19,dataNodes!$B$2:$C$19,2,FALSE) -> Use | I19: =VLOOKUP(G19,$M$2:$N$20,2,FALSE) -> d15 | M19: =dataNodes!B19 -> Management Plans | N19: =dataNodes!A19 -> d18
A20: p03 | B20: CDSS Data & Tools | C20: Division of Water Resources | D20: Department of Natural Resources | E20: https://dwr.state.co.us/tools/ | F20: evapotranspiration data | G20: Evapotranspiration | H20: =VLOOKUP(G20,dataNodes!$B$2:$C$19,2,FALSE) -> Quantity | I20: =VLOOKUP(G20,$M$2:$N$20,2,FALSE) -> d05
A21: p03 | B21: CDSS Data & Tools | C21: Division of Water Resources | D21: Department of Natural Resources | E21: https://dwr.state.co.us/tools/ | F21: river basins, aquifers | G21: Natural | H21: =VLOOKUP(G21,dataNodes!$B$2:$C$19,2,FALSE) -> Infrastructure | I21: =VLOOKUP(G21,$M$2:$N$20,2,FALSE) -> d02
A22: p03 | B22: CDSS Data & Tools | C22: Division of Water Resources | D22: Department of Natural Resources | E22: https://dwr.state.co.us/tools/ | F22: water right amounts and transactions | G22: Regulatory | H22: =VLOOKUP(G22,dataNodes!$B$2:$C$19,2,FALSE) -> Quality | I22: =VLOOKUP(G22,$M$2:$N$20,2,FALSE) -> d04
A23: p04 | B23: Laserfiche | C23: Water Conservation Board | D23: Department of Natural Resources | E23: https://dnrweblink.state.co.us/dwr/ | F23: management plans | G23: Management Plans | H23: =VLOOKUP(G23,dataNodes!$B$2:$C$19,2,FALSE) -> Use | I23: =VLOOKUP(G23,$M$2:$N$20,2,FALSE) -> d18
A24: p04 | B24: Laserfiche | C24: Water Conservation Board | D24: Department of Natural Resources | E24: https://dnrweblink.state.co.us/dwr/ | F24: ground water levels, aquifers data, etc | G24: Groundwater | H24: =VLOOKUP(G24,dataNodes!$B$2:$C$19,2,FALSE) -> Quantity | I24: =VLOOKUP(G24,$M$2:$N$20,2,FALSE) -> d08
A25: p04 | B25: Laserfiche | C25: Water Conservation Board | D25: Department of Natural Resources | E25: https://dnrweblink.state.co.us/dwr/ | F25: diversion demand reports, etc. | G25: Use | H25: =VLOOKUP(G25,dataNodes!$B$2:$C$19,2,FALSE) -> Use | I25: =VLOOKUP(G25,$M$2:$N$20,2,FALSE) -> d16
A26: p20 | B26: Surface Water Conditions | C26: Division of Water Resources | D26: Department of Natural Resources | E26: https://dwr.state.co.us/surfacewater/ | F26: streamflow, reservoir data | G26: Surface Water | H26: =VLOOKUP(G26,dataNodes!$B$2:$C$19,2,FALSE) -> Quantity | I26: =VLOOKUP(G26,$M$2:$N$20,2,FALSE) -> d13
A27: p20 | B27: Surface Water Conditions | C27: Division of Water Resources | D27: Department of Natural Resources | E27: https://dwr.state.co.us/surfacewater/ | F27: streamflow, reservoir data | G27: Reservoir | H27: =VLOOKUP(G27,dataNodes!$B$2:$C$19,2,FALSE) -> Quantity | I27: =VLOOKUP(G27,$M$2:$N$20,2,FALSE) -> d11
A28: p21 | B28: Satellite Monitoring ( USGS Colorado Water Data | C28: Division of Water Resources | D28: Department of Natural Resources | E28: https://waterdata.usgs.gov/co/nwis | F28: Water flow and levels in streams and lakes. | G28: Surface Water | H28: =VLOOKUP(G28,dataNodes!$B$2:$C$19,2,FALSE) -> Quantity | I28: =VLOOKUP(G28,$M$2:$N$20,2,FALSE) -> d13
A29: p21 | B29: Satellite Monitoring ( USGS Colorado Water Data | C29: Division of Water Resources | D29: Department of Natural Resources | E29: https://waterdata.usgs.gov/co/nwis | F29: use data | G29: Use | H29: =VLOOKUP(G29,dataNodes!$B$2:$C$19,2,FALSE) -> Use | I29: =VLOOKUP(G29,$M$2:$N$20,2,FALSE) -> d16
A30: p21 | B30: Satellite Monitoring ( USGS Colorado Water Data | C30: Division of Water Resources | D30: Department of Natural Resources | E30: https://waterdata.usgs.gov/co/nwis | F30: Water levels in wells. | G30: Groundwater | H30: =VLOOKUP(G30,dataNodes!$B$2:$C$19,2,FALSE) -> Quantity | I30: =VLOOKUP(G30,$M$2:$N$20,2,FALSE) -> d08
A31: p05 | B31: CDPHE Open Data | C31: Department of Public Health & Environment | D31: Department of Public Health & Environment | E31: https://data-cdphe.opendata.arcgis.com/ | F31: precipitation data | G31: Precipitation | H31: =VLOOKUP(G31,dataNodes!$B$2:$C$19,2,FALSE) -> Quantity | I31: =VLOOKUP(G31,$M$2:$N$20,2,FALSE) -> d10
... A34: p06 | B34: Clean Water - GIS Maps | C34: Clean Water Program | D34: Department of Public Health & Environment | E34: https://www.colorado.gov/pacific/cdphe/clean-water-gis-maps | F34: surface water quantity | G34: Surface Water | H34: =VLOOKUP(G34,dataNodes!$B$2:$C$19,2,FALSE) -> Quantity | I34: =VLOOKUP(G34,$M$2:$N$20,2,FALSE) -> d13
A35: p07 | B35: Watershed Rapid Assessment Program | C35: =platformNodes!$C$13 -> Clean Water Program | D35: =$D$31 -> Department of Public Health & Environment | E35: https://erams.com/map/ | F35: soil condition in watershed | G35: Soil | H35: =VLOOKUP(G35,dataNodes!$B$2:$C$19,2,FALSE) -> Quantity | I35: =VLOOKUP(G35,$M$2:$N$20,2,FALSE) -> d12
A36: p07 | B36: Watershed Rapid Assessment Program | C36: =platformNodes!$C$13 -> Clean Water Program | D36: =$D$31 -> Department of Public Health & Environment | E36: https://erams.com/map/ | F36: watershed data | G36: Built | H36: =VLOOKUP(G36,dataNodes!$B$2:$C$19,2,FALSE) -> Infrastructure | I36: =VLOOKUP(G36,$M$2:$N$20,2,FALSE) -> d01
A37: p07 | B37: Watershed Rapid Assessment Program | C37: =platformNodes!$C$13 -> Clean Water Program | D37: =$D$31 -> Department of Public Health & Environment | E37: https://erams.com/map/ | F37: water rights; consumptive use | G37: Use | H37: =VLOOKUP(G37,dataNodes!$B$2:$C$19,2,FALSE) -> Use | I37: =VLOOKUP(G37,$M$2:$N$20,2,FALSE) -> d16
A38: p07 | B38: Watershed Rapid Assessment Program | C38: =platformNodes!$C$13 -> Clean Water Program | D38: =$D$31 -> Department of Public Health & Environment | E38: https://erams.com/map/ | F38: wetlands | G38: Natural | H38: =VLOOKUP(G38,dataNodes!$B$2:$C$19,2,FALSE) -> Infrastructure | I38: =VLOOKUP(G38,$M$2:$N$20,2,FALSE) -> d02
A39: p07 | B39: Watershed Rapid Assessment Program | C39: =platformNodes!$C$13 -> Clean Water Program | D39: =$D$31 -> Department of Public Health & Environment | E39: https://erams.com/map/ | F39: water quality data, atmospheric deposition | G39: Quality | H39: =VLOOKUP(G39,dataNodes!$B$2:$C$19,2,FALSE) -> Quality | I39: =VLOOKUP(G39,$M$2:$N$20,2,FALSE) -> d03
A40: p07 | B40: Watershed Rapid Assessment Program | C40: =platformNodes!$C$13 -> Clean Water Program | D40: =$D$31 -> Department of Public Health & Environment | E40: https://erams.com/map/ | F40: streamflow data | G40: Surface Water | H40: =VLOOKUP(G40,dataNodes!$B$2:$C$19,2,FALSE) -> Quantity | I40: =VLOOKUP(G40,$M$2:$N$20,2,FALSE) -> d13
A41: p07 | B41: Watershed Rapid Assessment Program | C41: =platformNodes!$C$13 -> Clean Water Program | D41: =$D$31 -> Department of Public Health & Environment | E41: https://erams.com/map/ | F41: fema flood zone | G41: Extreme Events | H41: =VLOOKUP(G41,dataNodes!$B$2:$C$19,2,FALSE) -> Quantity | I41: =VLOOKUP(G41,$M$2:$N$20,2,FALSE) -> d06
A42: p07 | B42: Watershed Rapid Assessment Program | C42: =platformNodes!$C$13 -> Clean Water Program | D42: =$D$31 -> Department of Public Health & Environment | E42: https://erams.com/map/ | F42: water quality standards | G42: Regulatory | H42: =VLOOKUP(G42,dataNodes!$B$2:$C$19,2,FALSE) -> Quality | I42: =VLOOKUP(G42,$M$2:$N$20,2,FALSE) -> d04
A43: p07 | B43: Watershed Rapid Assessment Program | C43: =platformNodes!$C$13 -> Clean Water Program | D43: =$D$31 -> Department of Public Health & Environment | E43: https://erams.com/map/ | F43: Snotel data | G43: Glacial and Snow | H43: =VLOOKUP(G43,dataNodes!$B$2:$C$19,2,FALSE) -> Quantity | I43: =VLOOKUP(G43,$M$2:$N$20,2,FALSE) -> d07
A44: p07 | B44: Watershed Rapid Assessment Program | C44: =platformNodes!$C$13 -> Clean Water Program | D44: =$D$31 -> Department of Public Health & Environment | E44: https://erams.com/map/ | F44: PRISM precipitation | G44: Precipitation | H44: =VLOOKUP(G44,dataNodes!$B$2:$C$19,2,FALSE) -> Quantity | I44: =VLOOKUP(G44,$M$2:$N$20,2,FALSE) -> d10
A45: p07 | B45: Watershed Rapid Assessment Program | C45: =platformNodes!$C$13 -> Clean Water Program | D45: =$D$31 -> Department of Public Health & Environment | E45: https://erams.com/map/ | F45: PRISM Temperature | G45: Meteorology | H45: =VLOOKUP(G45,dataNodes!$B$2:$C$19,2,FALSE) -> Quantity | I45: =VLOOKUP(G45,$M$2:$N$20,2,FALSE) -> d09
A46: p09 | B46: Water Quality Planning | C46: Clean Water Program | D46: =$D$31 -> Department of Public Health & Environment | E46: https://www.colorado.gov/pacific/cdphe/wq-planning | F46: regional and statewide water management plans | G46: Management Plans | H46: =VLOOKUP(G46,dataNodes!$B$2:$C$19,2,FALSE) -> Use | I46: =VLOOKUP(G46,$M$2:$N$20,2,FALSE) -> d18
A47: p10 | B47: Agricultural Water Quality Database | C47: Agricultural Water Quality Program | D47: Department of Agriculture | E47: https://erams.com/co_agwaterquality/search_data | F47: water quality data | G47: Quality | H47: =VLOOKUP(G47,dataNodes!$B$2:$C$19,2,FALSE) -> Quality | I47: =VLOOKUP(G47,$M$2:$N$20,2,FALSE) -> d03
...

Sheet dataNodes
A1: dataID | B1: dataGroup | C1: dataCategory
A2: d01 | B2: Built | C2: Infrastructure
A3: d02 | B3: Natural | C3: Infrastructure
A4: d03 | B4: Quality | C4: Quality
A5: d04 | B5: Regulatory | C5: Quality
A6: d05 | B6: Evapotranspiration | C6: Quantity
A7: d06 | B7: Extreme Events | C7: Quantity
A8: d07 | B8: Glacial and Snow | C8: Quantity
A9: d08 | B9: Groundwater | C9: Quantity
A10: d09 | B10: Meteorology | C10: Quantity
A11: d10 | B11: Precipitation | C11: Quantity
A12: d11 | B12: Reservoir | C12: Quantity
... A19: d18 | B19: Management Plans | C19: Use

Sheet dataEdges
A1: from | B1: to
A2: create in r program
