Workbook

Sheet orgNodes
A1: entityID | B1: entity | C1: tier1and2entity | D1: tier1and2entityID | E1: entityIDAbove | F1: mission | G1: website | H1: operational | I1: decision | J1: regulatory | K1: research | L1: level
A2: n01 | B2: Executive Branch | C2: Executive Branch | D2: 1 | E2: NA | F2: Implement and enforce the laws written by Congress. | G2: https://www.whitehouse.gov/about-the-white-house/the-executive-branch/ | H2: Yes | I2: Yes | J2: Yes | K2: Yes | L2: 1
A3: n02 | B3: Department of Agriculture | C3: Department of Agriculture | D3: 2 | E3: n01 | F3: Provide leadership on food, agriculture, natural resoruces, rural development, nutrition, and related issues based on public policy, the best available science, and effective management. | G3: https://www.usda.gov/ | H3: Yes | I3: Yes | J3: No | K3: Yes | L3: 2
A4: n03 | B4: Agricultural Research Service | C4: Department of Agriculture | D4: 2 | E4: n02 | F4: Conduct research to develop and transfer solutions to agricultural problems of high national priority. | G4: https://www.ars.usda.gov/ | H4: No | I4: Yes | J4: No | K4: Yes | L4: 3
A5: n04 | B5: National Agricultural Statistics Service | C5: Department of Agriculture | D5: 2 | E5: n02 | F5: Provide timely, accurate, and useful statistics in service to U.S. agriculture. | G5: https://www.nass.usda.gov/ | H5: No | I5: Yes | J5: No | K5: No | L5: 3
A6: n05 | B6: Natural Resources Conservation Service | C6: Department of Agriculture | D6: 2 | E6: n02 | F6: Provide resources to farmers and landowners to aid them with conservation. | G6: https://www.nrcs.usda.gov/ | H6: Yes | I6: Yes | J6: No | K6: No | L6: 3
A7: n06 | B7: Economic Research Service | C7: Department of Agriculture | D7: 2 | E7: n02 | F7: Anticipate trends and emerging issues in agriculture, food, the environment, and rural America and to conduct high-quality, objective economic research to inform and enhance public and private decision making. | G7: https://www.ers.usda.gov/ | H7: No | I7: Yes | J7: No | K7: Yes | L7: 3
A8: n07 | B8: Department of Commerce | C8: Department of Commerce | D8: 3 | E8: n01 | F8: Promote job creation, economic growth, sustainable development, and improved living standards for all Americans by working in partnership with businesses, universities, communities, and workers. | G8: https://www.commerce.gov/ | H8: Yes | I8: Yes | J8: No | K8: Yes | L8: 2
A9: n08 | B9: National Oceanic and Atmospheric Administration | C9: Department of Commerce | D9: 3 | E9: n07 | F9: To understand and predict changes in climate, weather, oceans, and coasts, to share that knowledge and information with others, and to conserve and manage coastal and marine ecosystems and resources. | G9: http://www.noaa.gov/ | H9: Yes | I9: Yes | J9: No | K9: Yes | L9: 3
A10: n09 | B10: National Weather Service | C10: Department of Commerce | D10: 3 | E10: n08 | F10: Provide weather, water, and climate data, forecasts and warnings for the protection of life and property and enhancement of the national economy. | G10: https://www.weather.gov/ | H10: Yes | I10: Yes | J10: No | K10: Yes | L10: 4
A11: n10 | B11: Department of Defense | C11: Department of Defense | D11: 4 | E11: n01 | F11: Provide the military forces needed to deter war and to protect the security of our country. | G11: https://www.defense.gov/ | H11: Yes | I11: Yes | J11: Yes | K11: No | L11: 2
A12: n11 | B12: National Geospatial Intelligence Agency | C12: Department of Defense | D12: 4 | E12: n10 | F12: Provide timely, relevant, and accurate geospatial intelligence in support of national security. | G12: http://www.nga.mil/ | H12: Yes | I12: Yes | J12: No | K12: No | L12: 3
A13: n12 | B13: Army Corps of Engineers | C13: Department of Defense | D13: 4 | E13: n10 | F13: Deliver vital public and military engineering services; partnering in peace and war to strengthen our Nations security, energize the economy and reduce risks from disasters | G13: https://www.usace.army.mil/ | H13: Yes | I13: Yes | J13: Yes | K13: No | L13: 3
... A15: n14 | B15: Office of Energy Efficiency and Renewable Energy | C15: Department of Energy | D15: 5 | E15: n13 | F15: Create and sustain American leadership in the transition to a global clean energy economy. | G15: https://www.energy.gov/eere/water/ | H15: No | I15: Yes | J15: No | K15: Yes | L15: 3
A16: n15 | B16: Water Power Technologies Office | C16: Department of Energy | D16: 5 | E16: n14 | G16: https://www.energy.gov/eere/water/ | H16: No | I16: Yes | J16: No | K16: Yes | L16: 4
A17: n16 | B17: Oak Ridge National Laboratory | C17: Department of Energy | D17: 5 | E17: n15 | F17: Deliver scientific discoveries and technical breakthroughs that will accelerate the development and deployment of solutions in clean energy and global security. | G17: https://ornl.gov/ | H17: No | I17: Yes | J17: No | K17: Yes | L17: 5
A18: n17 | B18: Pacific Northwest National Laboratory | C18: Department of Energy | D18: 5 | E18: n15 | F18: Transform the world through courageous discovery and innovation. | G18: https://www.pnnl.gov/ | H18: No | I18: No | J18: No | K18: Yes | L18: 5
A19: n18 | B19: Idaho National Laboratory | C19: Department of Energy | D19: 5 | E19: n15 | F19: Discover, demonstrate, and secure innovative nuclear energy solutions, other clean energy options, and critical infrastructure. | G19: https://www.inl.gov/ | H19: No | I19: No | J19: No | K19: Yes | L19: 5
A20: n19 | B20: Sandia National Laboratory | C20: Department of Energy | D20: 5 | E20: n15 | F20: Develop advanced technologies to ensure global peace. | G20: https://www.sandia.gov/ | H20: No | I20: No | J20: No | K20: Yes | L20: 5
A21: n20 | B21: National Renewable Energy Laboratory | C21: Department of Energy | D21: 5 | E21: n15 | F21: Advance the science and engineering of energy efficiency, sustainable transportation, and renewable power technologies and provide the knowledge to integrate and optimize energy systems. | G21: https://www.nrel.gov/ | H21: No | I21: Yes | J21: No | K21: Yes | L21: 5
A22: n21 | B22: Argonne National Laboratory | C22: Department of Energy | D22: 5 | E22: n15 | F22: Serve America as a science and energy laboratory distinguished by the breadth of R&D capabilities in concert with a powerful suite of experimental and computational facilities. | G22: http://www.anl.gov/ | H22: No | I22: No | J22: No | K22: Yes | L22: 5
A23: n22 | B23: Energy Information Administration | C23: Department of Energy | D23: 5 | E23: n13 | F23: Collect, analyze, and disseminate independent and impartial energy information to promote sound policymaking, efficient markets, and public understanding of energy and its interaction with the economy and the environment. | G23: https://www.eia.gov/ | H23: No | I23: Yes | J23: No | K23: No | L23: 3
A24: n23 | B24: Department of Homeland Security | C24: Department of Homeland Security | D24: 6 | E24: n01 | F24: With honor and integrity, we will safeguard the American people, our homeland, and our values. | G24: https://www.dhs.gov/ | H24: Yes | I24: Yes | J24: Yes | K24: No | L24: 2
A25: n24 | B25: Federal Emergency Management Agency | C25: Department of Homeland Security | D25: 6 | E25: n23 | F25: Helping people before, during, and after disasters. | G25: https://www.fema.gov/ | H25: Yes | I25: Yes | J25: Yes | K25: No | L25: 3
A26: n25 | B26: National Protection and Programs Directorate | C26: Department of Homeland Security | D26: 6 | E26: n23 | F26: Lead the national effort to protect and enhance the resilience of the nations physical and cyber infrastructure. | G26: https://www.dhs.gov/national-protection-and-programs-directorate | H26: No | I26: Yes | J26: No | K26: No | L26: 3
A27: n26 | B27: Office of Infrastructure Protection | C27: Department of Homeland Security | D27: 6 | E27: n25 | F27: Lead the national effort to secure critical infrastructure from all hazards by managing risk and enhancing resilience through collaboration with the critical infrastructure community. | G27: https://www.dhs.gov/office-infrastructure-protection | H27: No | I27: Yes | J27: No | K27: No | L27: 4
A28: n27 | B28: Department of Interior | C28: Department of Interior | D28: 7 | E28: n01 | F28: Protects and manage the Nations natural resources and cultural heritage; provide scientific and other information about those resources; and honor its trust responsibilities or special commitments to American Indians, Alaska Natives, and affiliated island communities. | G28: https://www.doi.gov/ | H28: Yes | I28: Yes | J28: Yes | K28: Yes | L28: 2
... A43: n42 | B43: Tennessee Valley Authority | C43: Independent Establishments and Government Corporations | D43: 10 | E43: n35 | F43: Serve the people of the Tennessee Valley to help the region thrive and grow. | G43: https://www.tva.gov/ | H43: Yes | I43: Yes | J43: No | K43: No | L43: 3

Sheet orgEdges
A1: from | B1: to
A2: n01 | B2: n02
A3: n02 | B3: n03
A4: n02 | B4: n04
A5: n02 | B5: n05
A6: n02 | B6: n06
A7: n01 | B7: n07
A8: n07 | B8: n08
A9: n08 | B9: n09
A10: n01 | B10: n10
A11: n10 | B11: n11
A12: n10 | B12: n12
... A42: n35 | B42: n42

Sheet platformNodes
A1: platformID | B1: platform | C1: entity | D1: entityID | E1: webLabel | F1: heatmapLabel | G1: tier1and2entity | H1: tier1and2entityID | I1: website | J1: easeDiscover | K1: methodDiscover | L1: easeAccess | M1: methodAccess | N1: fileFormat | O1: metadata | P1: metadataFormat | Q1: dataDefinitions | R1: metaAttributes | S1: metadataStandards | T1: timeliness | U1: lengthAvailable
A2: p01 | B2: HSIN-CI Dams Portal | C2: Office of Infrastructure Protection | D2: n26 | E2: DHS-IP | F2: =CONCATENATE(E2,": ",B2) -> DHS-IP: HSIN-CI Dams Portal | G2: Department of Homeland Security | H2: =VLOOKUP(D2,orgNodes!$A$2:$D$43,4,FALSE) -> 6 | I2: https://www.dhs.gov/hsin-dams-portal | J2: No | K2: Unknown | L2: Permission Required | M2: Unknown | N2: Unknown | O2: Unknown | P2: Unknown | Q2: Unknown | R2: Unknown | S2: Unknown | T2: Unknown | U2: Current Only
A3: p02 | B3: Flood Map Service Center | C3: Federal Emergency Management Agency | D3: n24 | E3: DHS-FEMA | F3: DHS-FEMA: Flood Map Service Center | G3: Department of Homeland Security | H3: =VLOOKUP(D3,orgNodes!$A$2:$D$43,4,FALSE) -> 6 | I3: https://msc.fema.gov/portal/home | J3: Low | K3: Website | L3: Software Required | M3: Individual Export; Web Services | N3: pdf; software specific; shapefile | O3: No | P3: xml | Q3: Yes | R3: Administrative; Descriptive; Structural | S3: No | T3: Irregular | U3: Unknown
A4: p03 | B4: IP Gateway | C4: Office of Infrastructure Protection | D4: n26 | E4: DHS-IP | F4: DHS-IP: IP Gateway | G4: Department of Homeland Security | H4: =VLOOKUP(D4,orgNodes!$A$2:$D$43,4,FALSE) -> 6 | I4: https://www.dhs.gov/ipgateway | J4: No | K4: Unknown | L4: Training Required | M4: Unknown | N4: Unknown | O4: No | P4: Unknown | Q4: Unknown | R4: Unknown | S4: Unknown | T4: Unknown | U4: Unknown
A5: p04 | B5: No Public Portal | C5: National Geospatial Intelligence Agency | D5: n11 | E5: DOD-NGIA | F5: DOD-NGIA: No Public Portal | G5: Department of Defense | H5: =VLOOKUP(D5,orgNodes!$A$2:$D$43,4,FALSE) -> 4 | I5: https://www.nga.mil/Pages/Default.aspx | J5: No | K5: Unknown | L5: No | M5: Unknown | N5: Unknown | O5: No | P5: Unknown | Q5: Unknown | R5: Unknown | S5: Unknown | T5: Unknown | U5: Unknown
A6: p05 | B6: Corps CWMS | C6: Army Corps of Engineers | D6: n12 | E6: DOD-USACE | F6: DOD-USACE: Corps CWMS | G6: Department of Defense | H6: =VLOOKUP(D6,orgNodes!$A$2:$D$43,4,FALSE) -> 4 | I6: http://water.usace.army.mil | J6: Medium | K6: Map | L6: Yes | M6: Individual Export; Web Services | N6: csv; png; image | O6: Yes | P6: html | Q6: No | R6: Hybrid | S6: No | T6: Daily or Higher | U6: Limited Record
A7: p06 | B7: Atmospheric Radiation Measurement | C7: Department of Energy | D7: n13 | E7: DOE | F7: DOE: Atmospheric Radiation Measurement | G7: Department of Energy | H7: =VLOOKUP(D7,orgNodes!$A$2:$D$43,4,FALSE) -> 5 | I7: https://www.arm.gov/data | J7: High | K7: Catalog | L7: Registration Required | M7: Individual Export; Web Services | N7: netCDF | O7: No | P7: Unknown | Q7: Unknown | R7: Unknown | S7: Unknown | T7: Irregular | U7: Period of Record
A8: p07 | B8: Renewable and Alternative Fuels | C8: Energy Information Administration | D8: n22 | E8: DOE-EIA | F8: DOE-EIA: Renewable and Alternative Fuels | G8: Department of Energy | H8: =VLOOKUP(D8,orgNodes!$A$2:$D$43,4,FALSE) -> 5 | I8: https://www.eia.gov/renewable/data.php#hydro | J8: Low | K8: Website | L8: Yes | M8: Batch Export | N8: excel | O8: No | P8: No | Q8: No | R8: No | S8: No | T8: Yearly or Higher | U8: Limited Record
A9: p08 | B9: NREL Data Catalog | C9: National Renewable Energy Laboratory | D9: n20 | E9: DOE-NREL | F9: DOE-NREL: NREL Data Catalog | G9: Department of Energy | H9: =VLOOKUP(D9,orgNodes!$A$2:$D$43,4,FALSE) -> 5 | I9: https://data.nrel.gov/ | J9: High | K9: Catalog | L9: Yes | M9: Individual Export; Web Services | N9: excel; ascii; zip | O9: Yes | P9: in data | Q9: No | R9: Administrative | S9: No | T9: Irregular | U9: Varies
A10: p09 | B10: HydroGIS Viewer | C10: Oak Ridge National Laboratory | D10: n16 | E10: DOE-ORNL | F10: DOE-ORNL: HydroGIS Viewer | G10: Department of Energy | H10: =VLOOKUP(D10,orgNodes!$A$2:$D$43,4,FALSE) -> 5 | I10: https://nhaap.ornl.gov/content/hydrogis-0 | J10: Medium | K10: Map; Website | L10: Yes | M10: Unknown | N10: access; excel; shapefile | O10: Yes | P10: html | Q10: No | R10: Descriptive; Structural | S10: No | T10: Irregular | U10: Limited Record
A11: p10 | B11: National Groundwater Monitoring Network | C11: Advisory Committee on Water Information | D11: n27 | E11: DOI-ACWI | F11: DOI-ACWI: National Groundwater Monitoring Network | G11: Department of Interior | H11: =VLOOKUP(D11,orgNodes!$A$2:$D$43,4,FALSE) -> 7 | I11: https://cida.usgs.gov/ngwmn/index.jsp | J11: High | K11: Map | L11: Yes | M11: Batch Export | N11: csv; tsv; zip | O11: Yes | P11: pdf | Q11: Yes | R11: Administrative; Descriptive; Structural | S11: No | T11: Daily or Higher | U11: Period of Record
A12: p11 | B12: Hydromet | C12: Bureau of Reclamation | D12: n28 | E12: DOI-BoR | F12: DOI-BoR: Hydromet | G12: Department of Interior | H12: =VLOOKUP(D12,orgNodes!$A$2:$D$43,4,FALSE) -> 7 | I12: https://www.usbr.gov/pn/hydromet/ | J12: Low | K12: Website | L12: Yes | M12: Copy and Paste | N12: html | O12: Yes | P12: html | Q12: Yes | R12: Descriptive | S12: No | T12: Daily or Higher | U12: Period of Record
A13: p12 | B13: Agrimet | C13: Bureau of Reclamation | D13: n28 | E13: DOI-BoR | F13: DOI-BoR: Agrimet | G13: Department of Interior | H13: =VLOOKUP(D13,orgNodes!$A$2:$D$43,4,FALSE) -> 7 | I13: https://www.usbr.gov/pn/agrimet/ | J13: Low | K13: Website | L13: Yes | M13: Individual Export | N13: txt; excel; json | O13: Yes | P13: html | Q13: Yes | R13: Administrative; Descriptive | S13: No | T13: Daily or Higher | U13: Period of Record
A14: p13 | B14: Reclamation Water Information System | C14: Bureau of Reclamation | D14: n28 | E14: DOI-BoR | F14: DOI-BoR: Reclamation Water Information System | G14: Department of Interior | H14: =VLOOKUP(D14,orgNodes!$A$2:$D$43,4,FALSE) -> 7 | I14: https://water.usbr.gov/ | J14: High | K14: Map; Catalog | L14: Yes | M14: Web Services; Individual Export; Full Export | N14: json; csv; WML2; zip | O14: Yes | P14: in data | Q14: Yes | R14: Administrative; Descriptive | S14: No | T14: Daily or Higher | U14: Limited Record
... A28: p27 | B28: National Contaminant Occurrence Database | C28: Environmental Protection Agency | D28: n36 | E28: EPA | F28: EPA: National Contaminant Occurrence Database | G28: Environmental Protection Agency | H28: =VLOOKUP(D28,orgNodes!$A$2:$D$43,4,FALSE) -> 10 | I28: https://www.epa.gov/dwstandardsregulations/national-contaminant-occurrence-database-ncod | J28: Low | K28: Website | L28: Yes | M28: Individual Export | N28: zip; txt | O28: Yes | P28: pdf | Q28: Yes | R28: Administrative | S28: No | T28: Irregular | U28: Limited Record
A29: p28 | B29: Water Quality Portal | C29: EPA, USGS, NWQMC | D29: nMix | E29: EPA, USGS, NWQMC | F29: Joint: Water Quality Portal | G29: EPA, USGS, NWQMC | H29: NA | I29: https://www.waterqualitydata.us/ | J29: High | K29: Map; Catalog | L29: Yes | M29: Web Services; Batch Export | N29: csv; shapefile; tsv; excel; kml | O29: Yes | P29: html | Q29: Yes | R29: Administrative; Descriptive; Structural | S29: No | T29: Daily or Higher | U29: Period of Record
A30: p29 | B30: GeoPlatform.Gov | C30: Federal Geospatial Data Committee | D30: n37 | E30: FGDC | F30: FGDC: GeoPlatform.Gov | G30: Federal Geospatial Data Committee | H30: =VLOOKUP(D30,orgNodes!$A$2:$D$43,4,FALSE) -> 10 | I30: https://www.geoplatform.gov/ | J30: Medium | K30: Catalog | L30: Yes | M30: Link to Source | N30: Not Applicable | O30: Yes | P30: html | Q30: No | R30: Descriptive | S30: No | T30: Irregular | U30: Current Only
A31: p30 | B31: Data.Gov | C31: General Services Administration | D31: n38 | E31: GSA | F31: GSA: Data.Gov | G31: General Services Administration | H31: =VLOOKUP(D31,orgNodes!$A$2:$D$43,4,FALSE) -> 10 | I31: https://www.data.gov/ | J31: Medium | K31: Catalog | L31: Yes | M31: Web Services; Link to Source | N31: Not Applicable | O31: Yes | P31: json | Q31: No | R31: Descriptive | S31: No | T31: Irregular | U31: Varies
A32: p31 | B32: HealthData.Gov | C32: Department of Health and Human Services | D32: n33 | E32: HHS | F32: HHS: HealthData.Gov | G32: Department of Health and Human Services | H32: =VLOOKUP(D32,orgNodes!$A$2:$D$43,4,FALSE) -> 9 | I32: https://www.healthdata.gov/ | J32: Medium | K32: Catalog | L32: Yes | M32: Individual Export; Web Services | N32: csv; json; xml; rdf | O32: Yes | P32: json | Q32: No | R32: Descriptive | S32: No | T32: Irregular | U32: Period of Record
A33: p32 | B33: Data.CDC.Gov | C33: Department of Health and Human Services | D33: n33 | E33: HHS-CDC | F33: HHS-CDC: Data.CDC.Gov | G33: Department of Health and Human Services | H33: =VLOOKUP(D33,orgNodes!$A$2:$D$43,4,FALSE) -> 9 | I33: https://data.cdc.gov/ | J33: Medium | K33: Catalog | L33: Yes | M33: Individual Export; Web Services; Link to Source | N33: csv; rdf; xml | O33: Yes | P33: pdf | Q33: Yes | R33: Administrative; Descriptive; Structural | S33: No | T33: Irregular | U33: Limited Record
A34: p33 | B34: EGIS OpenData | C34: Department of Housing and Urban Development | D34: n32 | E34: HUD | F34: HUD: EGIS OpenData | G34: Department of Housing and Urban Development | H34: =VLOOKUP(D34,orgNodes!$A$2:$D$43,4,FALSE) -> 8 | I34: https://egis-hud.opendata.arcgis.com/ | J34: High | K34: Catalog | L34: Yes | M34: Web Services; Individual Export | N34: shapefile; excel | O34: Yes | P34: html | Q34: Some | R34: Descriptive | S34: Some | T34: Irregular | U34: Current Only
A35: p34 | B35: Alaska Satellite Facility DAAC | C35: Earth Science Division | D35: n41 | E35: NASA-ESD | F35: NASA-ESD: Alaska Satellite Facility DAAC | G35: National Aeronautics and Space Administration | H35: =VLOOKUP(D35,orgNodes!$A$2:$D$43,4,FALSE) -> 10 | I35: https://www.asf.alaska.edu/get-data/get-started/ | J35: Low | K35: Map; Catalog; Website | L35: Registration Required | M35: Web Services; Individual Export | N35: image; pdf; shapefile; raster; hdf5; csv | O35: Yes | P35: xml | Q35: Yes | R35: Administrative; Descriptive; Structural | S35: Some | T35: Irregular | U35: Period of Record
A36: p35 | B36: Earthdata Search | C36: Earth Science Division | D36: n41 | E36: NASA-ESD | F36: NASA-ESD: Earthdata Search | G36: National Aeronautics and Space Administration | H36: =VLOOKUP(D36,orgNodes!$A$2:$D$43,4,FALSE) -> 10 | I36: https://search.earthdata.nasa.gov/ | J36: High | K36: Map; Catalog | L36: Registration Required | M36: Web Services; Individual Export | N36: Unknown | O36: Yes | P36: html | Q36: No | R36: Descriptive | S36: Yes | T36: Irregular | U36: Period of Record
A37: p36 | B37: Goddard Earth Sciences Data and Information Services Center | C37: Earth Science Division | D37: n41 | E37: NASA-ESD | F37: NASA-ESD: Goddard Earth Sciences Data and Information Services Center | G37: National Aeronautics and Space Administration | H37: =VLOOKUP(D37,orgNodes!$A$2:$D$43,4,FALSE) -> 10 | I37: https://daac.gsfc.nasa.gov/ | J37: Medium | K37: Catalog | L37: Yes | M37: Web Services; Individual Export | N37: netcdf; hdf5 | O37: Yes | P37: pdf | Q37: Yes | R37: Administrative; Descriptive; Structural | S37: No | T37: Irregular | U37: Period of Record
A38: p37 | B38: Global Hydrology Resource Center DAAC | C38: Earth Science Division | D38: n41 | E38: NASA-ESD | F38: NASA-ESD: Global Hydrology Resource Center DAAC | G38: National Aeronautics and Space Administration | H38: =VLOOKUP(D38,orgNodes!$A$2:$D$43,4,FALSE) -> 10 | I38: https://ghrc.nsstc.nasa.gov/home/ | J38: Medium | K38: Map; Catalog | L38: Yes | M38: Web Services; Individual Export; Batch Export | N38: netcdf; hdf5 | O38: Yes | P38: pdf | Q38: Yes | R38: Administrative; Descriptive; Structural | S38: No | T38: Irregular | U38: Period of Record
A39: p38 | B39: Land Processes DAAC | C39: Earth Science Division | D39: n41 | E39: NASA-ESD | F39: NASA-ESD: Land Processes DAAC | G39: National Aeronautics and Space Administration | H39: =VLOOKUP(D39,orgNodes!$A$2:$D$43,4,FALSE) -> 10 | I39: https://lpdaac.usgs.gov/ | J39: High | K39: Catalog | L39: Registration Required | M39: Link to Source | N39: Not Applicable | O39: Yes | P39: xml | Q39: Yes | R39: Administrative; Descriptive | S39: Yes | T39: Irregular | U39: Period of Record
A40: p39 | B40: National Snow and Ice Data Center DAAC | C40: Earth Science Division | D40: n41 | E40: NASA-ESD | F40: NASA-ESD: National Snow and Ice Data Center DAAC | G40: National Aeronautics and Space Administration | H40: =VLOOKUP(D40,orgNodes!$A$2:$D$43,4,FALSE) -> 10 | I40: https://nsidc.org/daac | J40: High | K40: Catalog | L40: Yes | M40: Web Services; Batch Export; Individual Export | N40: ascii; xml; hdf5 | O40: Yes | P40: xml | Q40: Yes | R40: Administrative; Descriptive; Structural | S40: Yes | T40: Irregular | U40: Period of Record
A41: p40 | B41: Oak Ridge National Laboratory DAAC | C41: Earth Science Division | D41: n41 | E41: NASA-ESD | F41: NASA-ESD: Oak Ridge National Laboratory DAAC | G41: National Aeronautics and Space Administration | H41: =VLOOKUP(D41,orgNodes!$A$2:$D$43,4,FALSE) -> 10 | I41: https://daac.ornl.gov/ | J41: Low | K41: Website | L41: Registration Required | M41: Web Services; Individual Export | N41: Unknown | O41: Yes | P41: html | Q41: Yes | R41: Administrative; Descriptive; Structural | S41: No | T41: Irregular | U41: Period of Record
... A44: p43 | B44: Socioeconomic Data and Applications Data Center | C44: Earth Science Division | D44: n41 | E44: NASA-ESD | F44: NASA-ESD: Socioeconomic Data and Applications Data Center | G44: National Aeronautics and Space Administration | H44: =VLOOKUP(D44,orgNodes!$A$2:$D$43,4,FALSE) -> 10 | I44: http://sedac.ciesin.columbia.edu/ | J44: High | K44: Catalog | L44: Registration Required | M44: Web Services; Individual Export | N44: shapefile | O44: Yes | P44: xml | Q44: Yes | R44: Administrative; Descriptive; Structural | S44: Yes | T44: Irregular | U44: Period of Record
A45: p44 | B45: Joint Agricultural Weather Facility | C45: NOAA, USDA | D45: nMix | E45: NOAA, USDA | F45: Joint: Agricultural Weather Facility | G45: NOAA, USDA | H45: NA | I45: https://www.usda.gov/oce/weather/ | J45: Low | K45: Website | L45: Yes | M45: Individual Export | N45: pdf | O45: No | P45: No | Q45: No | R45: No | S45: No | T45: Irregular | U45: Limited Record
A46: p45 | B46: River Forecast Center | C46: Tennessee Valley Authority | D46: n42 | E46: TVA | F46: TVA: River Forecast Center | G46: Tennessee Valley Authority | H46: =VLOOKUP(D46,orgNodes!$A$2:$D$43,4,FALSE) -> 10 | I46: https://www.tva.gov/ | J46: Low | K46: Website | L46: Yes | M46: Copy and Paste; Individual Export | N46: html; csv; excel | O46: No | P46: No | Q46: Yes | R46: No | S46: No | T46: Daily or Higher | U46: Current Only
A47: p46 | B47: Agricultural Research Database System | C47: Agricultural Research Service | D47: n03 | E47: USDA-ARS | F47: USDA-ARS: Agricultural Research Database System | G47: Department of Agriculture | H47: =VLOOKUP(D47,orgNodes!$A$2:$D$43,4,FALSE) -> 2 | I47: https://www.nrrig.mwa.ars.usda.gov/stewards/stewards.html | J47: Medium | K47: Map | L47: Registration Required | M47: Unknown | N47: Unknown | O47: Yes | P47: Unknown | Q47: Unknown | R47: Descriptive | S47: Unknown | T47: Irregular | U47: Unknown
A48: p47 | B48: QuickStats | C48: National Agricultural Statistics Service | D48: n04 | E48: USDA-NASS | F48: USDA-NASS: QuickStats | G48: Department of Agriculture | H48: =VLOOKUP(D48,orgNodes!$A$2:$D$43,4,FALSE) -> 2 | I48: https://quickstats.nass.usda.gov/ | J48: Medium | K48: Catalog | L48: Yes | M48: Web Services; Individual Export | N48: csv; html | O48: No | P48: No | Q48: Yes | R48: No | S48: No | T48: Irregular | U48: Period of Record
A49: p48 | B49: National Water and Climate Center | C49: Natural Resources Conservation Service | D49: n05 | E49: USDA-NRCS | F49: USDA-NRCS: National Water and Climate Center | G49: Department of Agriculture | H49: =VLOOKUP(D49,orgNodes!$A$2:$D$43,4,FALSE) -> 2 | I49: https://www.wcc.nrcs.usda.gov/webmap/ | J49: High | K49: Map; Catalog | L49: Yes | M49: Individual Export; Batch Export | N49: csv; html | O49: Yes | P49: in data | Q49: Yes | R49: Administrative; Descriptive | S49: No | T49: Daily or Higher | U49: Period of Record
A50: p49 | B50: Climate Data Online | C50: National Oceanic and Atmospheric Administration | D50: n08 | E50: DOC-NOAA | F50: DOC-NOAA: Climate Data Online | G50: Department of Commerce | H50: =VLOOKUP(D50,orgNodes!$A$2:$D$43,4,FALSE) -> 3 | I50: https://www.ncdc.noaa.gov/cdo-web/ | J50: High | K50: Map; Catalog | L50: Yes | M50: Web Services; FTP; Individual Export; Batch Export | N50: csv; txt; zip; pdf | O50: Yes | P50: pdf | Q50: Yes | R50: Administrative; Descriptive | S50: No | T50: Daily or Higher | U50: Period of Record
A51: p50 | B51: OneStop | C51: National Oceanic and Atmospheric Administration | D51: n08 | E51: DOC-NOAA | F51: DOC-NOAA: OneStop | G51: Department of Commerce | H51: =VLOOKUP(D51,orgNodes!$A$2:$D$43,4,FALSE) -> 3 | I51: https://data.noaa.gov/onestop | J51: High | K51: Catalog | L51: Yes | M51: Web Services; FTP; Link to Source; Individual Export | N51: shapefile; csv; xml; txt; kmz | O51: Yes | P51: html | Q51: Some | R51: Administrative | S51: No | T51: Irregular | U51: Period of Record
A52: p51 | B52: Advanced Hydrologic Prediction Service | C52: National Weather Service | D52: n09 | E52: DOC-NWS | F52: DOC-NWS: Advanced Hydrologic Prediction Service | G52: Department of Commerce | H52: =VLOOKUP(D52,orgNodes!$A$2:$D$43,4,FALSE) -> 3 | I52: https://water.weather.gov/ahps/ | J52: Low | K52: Website | L52: Yes | M52: Web Services; Individual Export | N52: netCDF; shapefile; raster; kmz | O52: Yes | P52: html | Q52: No | R52: Administrative | S52: No | T52: Daily or Higher | U52: Limited Record
A53: p52 | B53: Climate Prediction Center | C53: National Weather Service | D53: n09 | E53: DOC-NWS | F53: DOC-NWS: Climate Prediction Center | G53: Department of Commerce | H53: =VLOOKUP(D53,orgNodes!$A$2:$D$43,4,FALSE) -> 3 | I53: http://www.cpc.ncep.noaa.gov/products/monitoring_and_data/us.shtml | J53: Low | K53: Website | L53: Yes | M53: Individual Export; Copy and Paste | N53: raster; shapefile; html; png | O53: No | P53: No | Q53: No | R53: No | S53: No | T53: Irregular | U53: Limited Record
A54: p53 | B54: National Operational Hydrologic Remote Sensing Center | C54: National Weather Service | D54: n09 | E54: DOC-NWS | F54: DOC-NWS: National Operational Hydrologic Remote Sensing Center | G54: Department of Commerce | H54: =VLOOKUP(D54,orgNodes!$A$2:$D$43,4,FALSE) -> 3 | I54: https://www.nohrsc.noaa.gov/ | J54: Low | K54: Website | L54: Yes | M54: Individual Export; FTP | N54: netCDF; raster; shapefile; zip | O54: Yes | P54: html | Q54: Yes | R54: Administrative; Descriptive; Structural | S54: No | T54: Daily or Higher | U54: Period of Record
A55: p54 | B55: Precipitation Frequency Data Server | C55: National Weather Service | D55: n09 | E55: DOC-NWS | F55: DOC-NWS: Precipitation Frequency Data Server | G55: Department of Commerce | H55: =VLOOKUP(D55,orgNodes!$A$2:$D$43,4,FALSE) -> 3 | I55: https://hdsc.nws.noaa.gov/hdsc/pfds/ | J55: High | K55: Map; Catalog | L55: Yes | M55: Individual Export; FTP | N55: html; csv; xml; ascii; shapefile | O55: No | P55: pdf | Q55: Yes | R55: Administrative; Descriptive | S55: No | T55: Daily or Higher | U55: Limited Record
...

Sheet dataNodes
A1: dataID | B1: dataGroup | C1: dataCategory
A2: d01 | B2: Built | C2: Infrastructure
A3: d02 | B3: Natural | C3: Infrastructure
A4: d03 | B4: Quality | C4: Quality
A5: d04 | B5: Regulatory | C5: Quality
A6: d05 | B6: Evapotranspiration | C6: Quantity
A7: d06 | B7: Extreme Events | C7: Quantity
A8: d07 | B8: Glacial and Snow | C8: Quantity
A9: d08 | B9: Groundwater | C9: Quantity
A10: d09 | B10: Meteorology | C10: Quantity
A11: d10 | B11: Precipitation | C11: Quantity
A12: d11 | B12: Reservoir | C12: Quantity
... A19: d18 | B19: Management Plans | C19: Use

Sheet dataNodeTypes
A1: platformID | B1: entity | C1: tier1and2entity | D1: platform | E1: website | F1: data | G1: dataCategory | H1: dataGroup | I1: dataID | J1: notes | M1: dataGroup - linked to dataNodes tab | N1: dataID - linked to dataNodes tab
A2: p51 | B2: National Weather Service | C2: Department of Commerce | D2: Advanced Hydrologic Prediction Service | E2: https://water.weather.gov/ahps/ | F2: Precipitation as Rain | G2: Water Quantity | H2: Precipitation | I2: =VLOOKUP(H2,$M$2:$N$19,2,FALSE) -> d10 | J2: Federal is the first type and a little out-dated. Need to remove duplicates for edges | M2: =dataNodes!B2 -> Built | N2: =dataNodes!A2 -> d01
A3: p51 | B3: National Weather Service | C3: Department of Commerce | D3: Advanced Hydrologic Prediction Service | E3: https://water.weather.gov/ahps/ | F3: River Stage | G3: Water Quantity | H3: Surface Water | I3: =VLOOKUP(H3,$M$2:$N$19,2,FALSE) -> d13 | M3: =dataNodes!B3 -> Natural | N3: =dataNodes!A3 -> d02
A4: p34 | B4: Earth Science Division | C4: National Aeronautics and Space Administration | D4: Alaska Satellite Facility DAAC | E4: https://www.asf.alaska.edu/get-data/get-started/ | F4: Wetland Extent | G4: Infrastructure | H4: Natural | I4: =VLOOKUP(H4,$M$2:$N$19,2,FALSE) -> d02 | M4: =dataNodes!B4 -> Quality | N4: =dataNodes!A4 -> d03
A5: p34 | B5: Earth Science Division | C5: National Aeronautics and Space Administration | D5: Alaska Satellite Facility DAAC | E5: https://www.asf.alaska.edu/get-data/get-started/ | F5: Soil Moisture | G5: Water Quantity | H5: Soil | I5: =VLOOKUP(H5,$M$2:$N$19,2,FALSE) -> d12 | M5: =dataNodes!B5 -> Regulatory | N5: =dataNodes!A5 -> d04
A6: p24 | B6: Environmental Protection Agency | C6: Environmental Protection Agency | D6: ATTAINS | E6: https://www.epa.gov/waterdata/attains | F6: 303d Assessment | G6: Water Quality | H6: Regulatory | I6: =VLOOKUP(H6,$M$2:$N$19,2,FALSE) -> d04 | M6: =dataNodes!B6 -> Evapotranspiration | N6: =dataNodes!A6 -> d05
A7: p24 | B7: Environmental Protection Agency | C7: Environmental Protection Agency | D7: ATTAINS | E7: https://www.epa.gov/waterdata/attains | F7: Source of Impairment | G7: Water Quality | H7: Regulatory | I7: =VLOOKUP(H7,$M$2:$N$19,2,FALSE) -> d04 | M7: =dataNodes!B7 -> Extreme Events | N7: =dataNodes!A7 -> d06
A8: p24 | B8: Environmental Protection Agency | C8: Environmental Protection Agency | D8: ATTAINS | E8: https://www.epa.gov/waterdata/attains | F8: TMDLs | G8: Water Quality | H8: Regulatory | I8: =VLOOKUP(H8,$M$2:$N$19,2,FALSE) -> d04 | M8: =dataNodes!B8 -> Glacial and Snow | N8: =dataNodes!A8 -> d07
A9: p24 | B9: Environmental Protection Agency | C9: Environmental Protection Agency | D9: ATTAINS | E9: https://www.epa.gov/waterdata/attains | F9: Designated Use | G9: Water Use | H9: Use | I9: =VLOOKUP(H9,$M$2:$N$19,2,FALSE) -> d16 | M9: =dataNodes!B9 -> Groundwater | N9: =dataNodes!A9 -> d08
A10: p06 | B10: Department of Energy | C10: Department of Energy | D10: Atmospheric Radiation Measurement | E10: https://www.arm.gov/data | F10: Glacier and Snow Depth | G10: Water Quantity | H10: Glacial and Snow | I10: =VLOOKUP(H10,$M$2:$N$19,2,FALSE) -> d07 | M10: =dataNodes!B10 -> Meteorology | N10: =dataNodes!A10 -> d09
A11: p06 | B11: Department of Energy | C11: Department of Energy | D11: Atmospheric Radiation Measurement | E11: https://www.arm.gov/data | F11: Precipitation as Rain | G11: Water Quantity | H11: Precipitation | I11: =VLOOKUP(H11,$M$2:$N$19,2,FALSE) -> d10 | M11: =dataNodes!B11 -> Precipitation | N11: =dataNodes!A11 -> d10
A12: p06 | B12: Department of Energy | C12: Department of Energy | D12: Atmospheric Radiation Measurement | E12: https://www.arm.gov/data | F12: Soil Moisture | G12: Water Quantity | H12: Soil | I12: =VLOOKUP(H12,$M$2:$N$19,2,FALSE) -> d12 | M12: =dataNodes!B12 -> Reservoir | N12: =dataNodes!A12 -> d11
A13: p06 | B13: Department of Energy | C13: Department of Energy | D13: Atmospheric Radiation Measurement | E13: https://www.arm.gov/data | F13: Soil Temperature | G13: Water Quantity | H13: Soil | I13: =VLOOKUP(H13,$M$2:$N$19,2,FALSE) -> d12 | M13: =dataNodes!B13 -> Soil | N13: =dataNodes!A13 -> d12
A14: p49 | B14: National Oceanic and Atmospheric Administration | C14: Department of Commerce | D14: Climate Data Online | E14: https://www.ncdc.noaa.gov/cdo-web/ | F14: Evaporation | G14: Water Quantity | H14: Evapotranspiration | I14: =VLOOKUP(H14,$M$2:$N$19,2,FALSE) -> d05 | M14: =dataNodes!B14 -> Surface Water | N14: =dataNodes!A14 -> d13
... A19: p49 | B19: National Oceanic and Atmospheric Administration | C19: Department of Commerce | D19: Climate Data Online | E19: https://www.ncdc.noaa.gov/cdo-web/ | F19: Relative Humidity | G19: Water Quantity | H19: Meteorology | I19: =VLOOKUP(H19,$M$2:$N$19,2,FALSE) -> d09 | M19: =dataNodes!B19 -> Management Plans | N19: =dataNodes!A19 -> d18
A20: p49 | B20: National Oceanic and Atmospheric Administration | C20: Department of Commerce | D20: Climate Data Online | E20: https://www.ncdc.noaa.gov/cdo-web/ | F20: Precipitation as Rain | G20: Water Quantity | H20: Precipitation | I20: =VLOOKUP(H20,$M$2:$N$19,2,FALSE) -> d10
A21: p49 | B21: National Oceanic and Atmospheric Administration | C21: Department of Commerce | D21: Climate Data Online | E21: https://www.ncdc.noaa.gov/cdo-web/ | F21: Soil Temperature | G21: Water Quantity | H21: Soil | I21: =VLOOKUP(H21,$M$2:$N$19,2,FALSE) -> d12
A22: p52 | B22: National Weather Service | C22: Department of Commerce | D22: Climate Prediction Center | E22: http://www.cpc.ncep.noaa.gov/products/monitoring_and_data/us.shtml | F22: Air Temperature | G22: Water Quantity | H22: Meteorology | I22: =VLOOKUP(H22,$M$2:$N$19,2,FALSE) -> d09
A23: p52 | B23: National Weather Service | C23: Department of Commerce | D23: Climate Prediction Center | E23: http://www.cpc.ncep.noaa.gov/products/monitoring_and_data/us.shtml | F23: Precipitation as Rain | G23: Water Quantity | H23: Precipitation | I23: =VLOOKUP(H23,$M$2:$N$19,2,FALSE) -> d10
A24: p52 | B24: National Weather Service | C24: Department of Commerce | D24: Climate Prediction Center | E24: http://www.cpc.ncep.noaa.gov/products/monitoring_and_data/us.shtml | F24: Soil Moisture | G24: Water Quantity | H24: Soil | I24: =VLOOKUP(H24,$M$2:$N$19,2,FALSE) -> d12
A25: p05 | B25: United States Army Corps of Engineers | C25: Department of Defense | D25: Corps CWMS | E25: http://water.usace.army.mil | F25: NID Information | G25: Infrastructure | H25: Built | I25: =VLOOKUP(H25,$M$2:$N$19,2,FALSE) -> d01
A26: p05 | B26: United States Army Corps of Engineers | C26: Department of Defense | D26: Corps CWMS | E26: http://water.usace.army.mil | F26: Streambed Elevation | G26: Infrastructure | H26: Natural | I26: =VLOOKUP(H26,$M$2:$N$19,2,FALSE) -> d02
A27: p05 | B27: United States Army Corps of Engineers | C27: Department of Defense | D27: Corps CWMS | E27: http://water.usace.army.mil | F27: Precipitation | G27: Water Quantity | H27: Precipitation | I27: =VLOOKUP(H27,$M$2:$N$19,2,FALSE) -> d10
A28: p05 | B28: United States Army Corps of Engineers | C28: Department of Defense | D28: Corps CWMS | E28: http://water.usace.army.mil | F28: Reservoir Inflow | G28: Water Quantity | H28: Reservoir | I28: =VLOOKUP(H28,$M$2:$N$19,2,FALSE) -> d11
A29: p05 | B29: United States Army Corps of Engineers | C29: Department of Defense | D29: Corps CWMS | E29: http://water.usace.army.mil | F29: Reservoir Stage | G29: Water Quantity | H29: Reservoir | I29: =VLOOKUP(H29,$M$2:$N$19,2,FALSE) -> d11
A30: p05 | B30: United States Army Corps of Engineers | C30: Department of Defense | D30: Corps CWMS | E30: http://water.usace.army.mil | F30: Stream Discharge | G30: Water Quantity | H30: Surface Water | I30: =VLOOKUP(H30,$M$2:$N$19,2,FALSE) -> d13
A31: p05 | B31: United States Army Corps of Engineers | C31: Department of Defense | D31: Corps CWMS | E31: http://water.usace.army.mil | F31: Stream Stage | G31: Water Quantity | H31: Surface Water | I31: =VLOOKUP(H31,$M$2:$N$19,2,FALSE) -> d13
... A40: p33 | B40: Department of Housing and Urban Development | C40: Department of Housing and Urban Development | D40: EGIS OpenData | E40: https://egis-hud.opendata.arcgis.com/ | F40: Flood Extent | G40: Water Quantity | H40: Extreme Events | I40: =VLOOKUP(H40,$M$2:$N$19,2,FALSE) -> d06
A41: p32 | B41: Department of Health and Human Services | C41: Department of Health and Human Services | D41: Data.CDC.Gov | F41: Water quality | G41: Water Quality | H41: Quality | I41: =VLOOKUP(H41,$M$2:$N$19,2,FALSE) -> d03
A42: p25 | B42: Environmental Protection Agency | C42: Environmental Protection Agency | D42: ECHO | E42: https://echo.epa.gov/ | F42: Facility Compliance | G42: Water Quality | H42: Regulatory | I42: =VLOOKUP(H42,$M$2:$N$19,2,FALSE) -> d04
A43: p25 | B43: Environmental Protection Agency | C43: Environmental Protection Agency | D43: ECHO | E43: https://echo.epa.gov/ | F43: Facility Enforcement Actions | G43: Water Quality | H43: Regulatory | I43: =VLOOKUP(H43,$M$2:$N$19,2,FALSE) -> d04
A44: p25 | B44: Environmental Protection Agency | C44: Environmental Protection Agency | D44: ECHO | E44: https://echo.epa.gov/ | F44: Facility Inspections | G44: Water Quality | H44: Regulatory | I44: =VLOOKUP(H44,$M$2:$N$19,2,FALSE) -> d04
A45: p25 | B45: Environmental Protection Agency | C45: Environmental Protection Agency | D45: ECHO | E45: https://echo.epa.gov/ | F45: Facility Penalties Assessed | G45: Water Quality | H45: Regulatory | I45: =VLOOKUP(H45,$M$2:$N$19,2,FALSE) -> d04
A46: p25 | B46: Environmental Protection Agency | C46: Environmental Protection Agency | D46: ECHO | E46: https://echo.epa.gov/ | F46: Facility Permits | G46: Water Quality | H46: Regulatory | I46: =VLOOKUP(H46,$M$2:$N$19,2,FALSE) -> d04
A47: p25 | B47: Environmental Protection Agency | C47: Environmental Protection Agency | D47: ECHO | E47: https://echo.epa.gov/ | F47: Facility Violations | G47: Water Quality | H47: Regulatory | I47: =VLOOKUP(H47,$M$2:$N$19,2,FALSE) -> d04
A48: p25 | B48: Environmental Protection Agency | C48: Environmental Protection Agency | D48: ECHO | E48: https://echo.epa.gov/ | F48: TMDLs | G48: Water Quality | H48: Regulatory | I48: =VLOOKUP(H48,$M$2:$N$19,2,FALSE) -> d04
A49: p26 | B49: Environmental Protection Agency | C49: Environmental Protection Agency | D49: EnviroAtlas | E49: https://www.epa.gov/enviroatlas | F49: Wetland Extent | G49: Infrastructure | H49: Natural | I49: =VLOOKUP(H49,$M$2:$N$19,2,FALSE) -> d02
A50: p26 | B50: Environmental Protection Agency | C50: Environmental Protection Agency | D50: EnviroAtlas | E50: https://www.epa.gov/enviroatlas | F50: Number of High Hazard Potential Dams | G50: Infrastructure | H50: Regulatory | I50: =VLOOKUP(H50,$M$2:$N$19,2,FALSE) -> d04
A51: p26 | B51: Environmental Protection Agency | C51: Environmental Protection Agency | D51: EnviroAtlas | E51: https://www.epa.gov/enviroatlas | F51: 303d Assessment | G51: Water Quality | H51: Regulatory | I51: =VLOOKUP(H51,$M$2:$N$19,2,FALSE) -> d04
A52: p26 | B52: Environmental Protection Agency | C52: Environmental Protection Agency | D52: EnviroAtlas | E52: https://www.epa.gov/enviroatlas | F52: Length of Impairment | G52: Water Quality | H52: Regulatory | I52: =VLOOKUP(H52,$M$2:$N$19,2,FALSE) -> d04
...

Sheet dataEdges
A1: from | B1: to
A2: p51 | B2: d10
A3: p51 | B3: d13
A4: p34 | B4: d02
A5: p34 | B5: d12
A6: p24 | B6: d04
A7: p24 | B7: d16
A8: p06 | B8: d07
A9: p06 | B9: d10
A10: p06 | B10: d12
A11: p49 | B11: d05
A12: p49 | B12: d07
... A177: p56 | B177: d04
