Workbook

Sheet orgNodes
A1: entityID | B1: entity | C1: tier1and2entity | D1: tier1and2entityID | E1: entityIDAbove | F1: mission | G1: website | H1: operational | I1: decision | J1: regulatory | K1: research | L1: level
A2: n01 | B2: North Carolina | C2: North Carolina | D2: 1 | E2: NA | G2: https://www.nc.gov/ | H2: Yes | I2: Yes | J2: Yes | K2: Yes | L2: 1
A3: n02 | B3: Department of Environmental Quality | C3: Department of Environmental Quality | D3: 2 | E3: n01 | F3: Providing science based environmental stewardship for the health and prosperity of ALL North Carolinians. | G3: https://deq.nc.gov/ | H3: Yes | I3: Yes | J3: Yes | K3: Yes | L3: 2
A4: n03 | B4: Water Infrastructure | C4: Department of Environmental Quality | D4: 2 | E4: n02 | F4: Provide financial assistance for projects that improve water quality. | G4: https://deq.nc.gov/about/divisions/water-infrastructure | H4: No | I4: Yes | J4: Yes | K4: No | L4: 3
A5: n04 | B5: Water Resources | C5: Department of Environmental Quality | D5: 2 | E5: n02 | F5: Efficiently and effectively protect the states surface water and groundwater resources through quality monitoring programs, efficient permitting, responsible management, fair and effective enforcement and excellence in public service. | G5: https://deq.nc.gov/about/divisions/water-resources | H5: Yes | I5: Yes | J5: Yes | K5: Yes | L5: 3
A6: n05 | B6: Water Resources Enforcement | C6: Department of Environmental Quality | D6: 2 | E6: n04 | G6: https://deq.nc.gov/about/divisions/water-resources/water-resources-enforcement | H6: No | I6: Yes | J6: Yes | K6: No | L6: 4
A7: n06 | B7: Public Water Supply | C7: Department of Environmental Quality | D7: 2 | E7: n04 | F7: Regulate public water systems within the state under the statutory authority of G.S. 130A Article 10 | G7: https://deq.nc.gov/about/divisions/water-resources/drinking-water | H7: Yes | I7: Yes | J7: Yes | K7: No | L7: 4
A8: n07 | B8: Water Planning | C8: Department of Environmental Quality | D8: 2 | E8: n04 | F8: Develop standards, rules and management strategies to protect water quality, carries out water supply planning, provides guidance to local water systems and monitors drought conditions. | G8: https://deq.nc.gov/about/divisions/water-resources/planning | H8: Yes | I8: Yes | J8: Yes | K8: Yes | L8: 4
A9: n08 | B9: Basin Planning | C9: Department of Environmental Quality | D9: 2 | E9: n07 | F9: Develop and maintain the most detailed and comprehensive, online, living statewide basin plan, practicable, for the StateÕs seventeen river basins. | G9: https://deq.nc.gov/about/divisions/water-resources/planning/basin-planning | H9: No | I9: Yes | J9: No | K9: No | L9: 5
A10: n09 | B10: Classifications, Standards, and Rules Review | C10: Department of Environmental Quality | D10: 2 | E10: n07 | F10: Responsible for developing and assisting with theÊinterpretation and implementation of the state's surface water and groundwater quality standards and surface water body classifications such as Water Supply (WS), High Quality Waters (HQW), and others. | G10: https://deq.nc.gov/about/divisions/water-resources/planning/classification-standards | H10: No | I10: Yes | J10: Yes | K10: No | L10: 5
A11: n10 | B11: Groundwater Management | C11: Department of Environmental Quality | D11: 2 | E11: n07 | F11: Provides technical and management support for the development and use of ground water resources in the State of North Carolina. | G11: https://deq.nc.gov/about/divisions/water-resources/water-planning/ground-water-management-branch | H11: Yes | I11: Yes | J11: No | K11: No | L11: 5
A12: n11 | B12: Modeling and Assessment | C12: Department of Environmental Quality | D12: 2 | E12: n07 | F12: Uses computer models and data analyses to simulate and assess surface water resources.Ê | G12: https://deq.nc.gov/about/divisions/water-resources/planning/modeling-assessment | H12: Yes | I12: No | J12: No | K12: Yes | L12: 5
A13: n12 | B13: Water Quality Regional Operations | C13: Department of Environmental Quality | D13: 2 | E13: n04 | F13: Focuses on service to the regional surface water and groundwater concerns of citizens, local governments and business communities. | G13: https://deq.nc.gov/about/divisions/water-resources/water-quality-regional-operations | H13: Yes | I13: Yes | J13: Yes | K13: No | L13: 4
A14: n13 | B14: Water Science | C14: Department of Environmental Quality | D14: 2 | E14: n04 | F14: Provides the Division of Water Resources with scientific and technical support required to monitor, regulate, and manage water quality throughout North Carolina. | G14: https://deq.nc.gov/about/divisions/water-resources/water-resources-data/water-sciences-home-page | H14: Yes | I14: Yes | J14: Yes | K14: No | L14: 4
A15: n14 | B15: Aquatic Toxicology Branch | C15: Department of Environmental Quality | D15: 2 | E15: n13 | F15: Serves the state of North Carolina through its support of the EPA mandatedÊNPDESÊprogram as it pertains to theÊClean Water Act (CWA)Êestablished in 1972. | G15: https://deq.nc.gov/about/divisions/water-resources/water-resources-data/water-sciences-home-page/aquatic-toxicology-branch | H15: No | I15: Yes | J15: Yes | K15: No | L15: 5
A16: n15 | B16: Biological Assessment Branch | C16: Department of Environmental Quality | D16: 2 | E16: n13 | F16: Evaluate the water quality of streams and rivers using the biological communities that live there. | G16: https://deq.nc.gov/about/divisions/water-resources/water-resources-data/water-sciences-home-page/biological-assessment-branch | H16: No | I16: Yes | J16: Yes | K16: No | L16: 5
A17: n16 | B17: Ecosystems Branch | C17: Department of Environmental Quality | D17: 2 | E17: n13 | G17: https://deq.nc.gov/about/divisions/water-resources/water-resources-data/water-sciences-home-page/ecosystems-branch | H17: No | I17: Yes | J17: No | K17: No | L17: 5
A18: n17 | B18: Water Quality Permitting | C18: Department of Environmental Quality | D18: 2 | E18: n04 | G18: https://deq.nc.gov/about/divisions/water-resources/water-resources-permits | H18: Yes | I18: Yes | J18: Yes | K18: No | L18: 4
A19: n18 | B19: Nondischarge Permitting Branch | C19: Department of Environmental Quality | D19: 2 | E19: n17 | F19: Responsible for the permitting and compliance of residual and wastewater effluent land application facilities. | G19: https://deq.nc.gov/about/divisions/water-resources/water-resources-permits/wastewater-branch/non-discharge-permitting | H19: No | I19: No | J19: Yes | K19: No | L19: 5
A20: n19 | B20: Complex Permitting Branch | C20: Department of Environmental Quality | D20: 2 | E20: n17 | F20: Responsible for major and minor National Pollutant Discharge Elimination System wastewater permitting, special technical issues, Level B modeling and policy implementation. | G20: https://deq.nc.gov/about/divisions/water-resources/water-quality-permitting/npdes-wastewater/permitting-contacts | H20: No | I20: No | J20: Yes | K20: No | L20: 5
A21: n20 | B21: Compliance and Expedited Permitting Branch | C21: Department of Environmental Quality | D21: 2 | E21: n17 | F21: Responsible for permitting and compliance in accordance with the federal National Pollutant Discharge Elimination System. | G21: https://deq.nc.gov/about/divisions/water-resources/water-resources-permits/wastewater-branch/npdes-wastewater-permits | H21: No | I21: No | J21: Yes | K21: No | L21: 5
A22: n21 | B22: Pretreatment, Emergency Response, and Collection Systems Branch | C22: Department of Environmental Quality | D22: 2 | E22: n17 | F22: Controls and documents the discharge of wastewater from Significant and Categorical Industrial Users to the Publicly Owned Treatment Works, is responsible for the various permitting programs for wastewater collection systems, oversees wastewater collection construction, operation, maintenance and enforcement and coordinates the division's emergency response operations. | G22: https://deq.nc.gov/about/divisions/water-resources/water-resources-permits/percs | H22: Yes | I22: Yes | J22: Yes | K22: No | L22: 5
A23: n22 | B23: 401 and Buffer Permitting Branch | C23: Department of Environmental Quality | D23: 2 | E23: n17 | F23: Responsible for implementing the state waters, wetlands and riparian buffer regulatory programs and assisting with compliance and enforcement procedures. | G23: https://deq.nc.gov/about/divisions/water-resources/water-resources-permits/wastewater-branch/401-wetlands-buffer-permits | H23: No | I23: No | J23: Yes | K23: No | L23: 5
A24: n23 | B24: Transportation Permitting Branch | C24: Department of Environmental Quality | D24: 2 | E24: n17 | F24: Assists the NC DOT with the planning and permitting of their projects. | G24: https://deq.nc.gov/about/divisions/water-resources/water-quality-permitting/transportation-permitting | H24: No | I24: No | J24: Yes | K24: No | L24: 5
A25: n24 | B25: Energy, Mineral, and Land Resources | C25: Department of Environmental Quality | D25: 2 | E25: n02 | F25: Dedicated to ensuring a sustainable energy future for the citizens of North Carolina. | G25: https://deq.nc.gov/about/divisions/energy-mineral-land-resources | H25: Yes | I25: Yes | J25: Yes | K25: No | L25: 3
A26: n25 | B26: Dam Safety | C26: Department of Environmental Quality | D26: 2 | E26: n24 | F26: Provides oversight of more than 3,000 dams statewide, working to provide for the ceritification and inspection of dams to reduce the risk of failure of dams; to prevent property damage, personal injury, and loss of reservoir storage; and to ensure maintneance of minimum flows of adequate quantity and quality below dams. | G26: https://deq.nc.gov/about/divisions/energy-mineral-land-resources/energy-mineral-land-permits/dam-safety | H26: Yes | I26: Yes | J26: Yes | K26: No | L26: 4
A27: n26 | B27: Stormwater | C27: Department of Environmental Quality | D27: 2 | E27: n24 | F27: Develops and implements programs to protect North CarolinaÕs surface waters from stormwater runoff. | G27: https://deq.nc.gov/about/divisions/energy-mineral-land-resources/stormwater | H27: No | I27: Yes | J27: No | K27: No | L27: 4
A28: n27 | B28: Coastal Management | C28: Department of Environmental Quality | D28: 2 | E28: n02 | F28: Protect, conserve and manage North Carolina's coastal resources through an integrated program of planning, permitting, education and research. | G28: https://deq.nc.gov/about/divisions/coastal-management | H28: No | I28: Yes | J28: No | K28: Yes | L28: 3
A29: n28 | B29: Department of Agriculture and Consumer Services | C29: Department of Agriculture and Consumer Services | D29: 3 | E29: n01 | F29: Provide services that promote and improve agriculture, agribusiness and forests; protect consumers and businesses; and conserve farmland and natural resources for the prosperity of all North Carolinians. | G29: http://www.ncagr.gov/index.htm | H29: No | I29: Yes | J29: No | K29: Yes | L29: 2
A30: n29 | B30: Agricultural Statistics | C30: Department of Agriculture and Consumer Services | D30: 3 | E30: n28 | F30: Provide timely, accurate, and useful statistics in service to North Carolina and U.S. agriculture. | G30: http://www.ncagr.gov/stats/index.htm | H30: No | I30: Yes | J30: No | K30: No | L30: 3
A31: n30 | B31: Environmental Statistics | C31: Department of Agriculture and Consumer Services | D31: 3 | E31: n29 | G31: http://www.ncagr.gov/stats/environmental/index.htm | H31: No | I31: Yes | J31: No | K31: No | L31: 4
A32: n31 | B32: Weather and Crop Reports | C32: Department of Agriculture and Consumer Services | D32: 3 | E32: n29 | G32: http://www.ncagr.gov/stats/weather/weather.htm | H32: No | I32: Yes | J32: No | K32: No | L32: 4
A33: n32 | B33: North Carolina Forest Service | C33: Department of Agriculture and Consumer Services | D33: 3 | E33: n28 | G33: http://www.ncforestservice.gov/ | H33: No | I33: Yes | J33: No | K33: Yes | L33: 3
A34: n33 | B34: Department of Information Technology | C34: Department of Information Technology | D34: 4 | E34: n01 | F34: Provide technology services to state agencies and other government customers across North Carolina. | G34: https://it.nc.gov/ | H34: Yes | I34: Yes | J34: No | K34: No | L34: 2
A35: n34 | B35: Geographic Information Coordinating Council | C35: Department of Information Technology | D35: 4 | E35: n33 | F35: Quality of statewide geographic information, public access to geospatial resources, collaboration in data development and GIS applications, and wide use of geographic information as a strategic element in public and private business processes. | G35: https://it.nc.gov/gicc | H35: No | I35: Yes | J35: No | K35: No | L35: 3
A36: n35 | B36: Department of Health and Human Services | C36: Department of Health and Human Services | D36: 5 | E36: n01 | F36: Provides essential services to improve the health, safety and well-being of all North Carolinians. | G36: https://www.ncdhhs.gov/ | H36: No | I36: No | J36: Yes | K36: No | L36: 2
A37: n36 | B37: Public Health | C37: Department of Health and Human Services | D37: 5 | E37: n35 | F37: Promote disease prevention, health services and health promotion programs that protect communities from communicable diseases, epidemics and contaminated food and water. | G37: https://publichealth.nc.gov/ | H37: No | I37: No | J37: Yes | K37: No | L37: 3
A38: n37 | B38: Environmental Health | C38: Department of Health and Human Services | D38: 5 | E38: n36 | F38: Safeguard life, promote human health and protect the environment through the practice of modern environmental health science, the use of technology, rules, public education and above all, dedication to the public trust. | G38: https://ehs.ncpublichealth.com/ | H38: No | I38: No | J38: Yes | K38: No | L38: 4
A39: n38 | B39: On Site Water Protection | C39: Department of Health and Human Services | D39: 5 | E39: n37 | F39: Provide regulatory oversight of sub-surface on-site wastewater treatment and dispersal systems, as well as inspection and testing of private drinking water wells constructed, repaired or abandoned, on or after July 1, 2008. | G39: https://ehs.ncpublichealth.com/oswp/ | H39: No | I39: No | J39: Yes | K39: No | L39: 5
A40: n39 | B40: Department of Transportation | C40: Department of Transportation | D40: 6 | E40: n01 | F40: Connecting people, products and places safely and efficiently with customer focus, accountability and environmental sensitivity to enhance the economy and vitality of North Carolina | G40: https://www.ncdot.gov | H40: No | I40: Yes | J40: Yes | K40: No | L40: 2
...

Sheet orgEdges
A1: from | B1: to
A2: n01 | B2: n02
A3: n01 | B3: n28
A4: n01 | B4: n33
A5: n01 | B5: n35
A6: n01 | B6: n39
A7: n01 | B7: n40
A8: n02 | B8: n03
A9: n02 | B9: n04
A10: n02 | B10: n24
A11: n02 | B11: n27
A12: n02 | B12: n43
... A43: n41 | B43: n42

Sheet platformNodes
A1: platformID | B1: platform | C1: entity | D1: entityID | E1: webLabel | F1: heatmapLabel | G1: tier1and2entity | H1: tier1and2entityID | I1: website | J1: easeDiscover | K1: methodDiscover | L1: easeAccess | M1: methodAccess | N1: fileFormat | O1: metadata | P1: metadataFormat | Q1: dataDefinitions | R1: metaAttributes | S1: metadataStandards | T1: timeliness | U1: lengthAvailable
A2: p01 | B2: Online Document Library | C2: Water Resources | D2: n04 | E2: DEQ-Water Resources | F2: =CONCATENATE(E2,": ",B2) -> DEQ-Water Resources: Online Document Library | G2: =VLOOKUP($D2,orgNodes!$A$2:$D$44,3,FALSE) -> Department of Environmental Quality | H2: =VLOOKUP($D2,orgNodes!$A$2:$D$44,4,FALSE) -> 2 | I2: https://edocs.deq.nc.gov/WaterResources/Welcome.aspx?cr=1 | J2: Low | K2: Website | L2: Yes | M2: Individual Export | N2: pdf | O2: Yes | P2: html | Q2: No | R2: Descriptive | S2: No | T2: Irregular | U2: Limited Record
A3: p02 | B3: Forms, Reports, and Publications | C3: Water Resources | D3: n04 | E3: DEQ-Water Resources | F3: =CONCATENATE(E3,": ",B3) -> DEQ-Water Resources: Forms, Reports, and Publications | G3: =VLOOKUP($D3,orgNodes!$A$2:$D$44,3,FALSE) -> Department of Environmental Quality | H3: =VLOOKUP($D3,orgNodes!$A$2:$D$44,4,FALSE) -> 2 | I3: https://deq.nc.gov/about/divisions/water-resources/forms-publications | J3: Low | K3: Website | L3: Yes | M3: Individual Export | N3: pdf | O3: No | P3: No | Q3: No | R3: No | S3: No | T3: Yearly or Higher | U3: Period of Record
A4: p03 | B4: Electronic Discharge Monitoring Report | C4: Water Resources | D4: n04 | E4: DEQ-Water Resources | F4: =CONCATENATE(E4,": ",B4) -> DEQ-Water Resources: Electronic Discharge Monitoring Report | G4: =VLOOKUP($D4,orgNodes!$A$2:$D$44,3,FALSE) -> Department of Environmental Quality | H4: =VLOOKUP($D4,orgNodes!$A$2:$D$44,4,FALSE) -> 2 | I4: https://deq.nc.gov/about/divisions/water-resources/edmr | J4: No | K4: Unknown | L4: No | M4: Unknown | N4: Unknown | O4: Unknown | P4: Unknown | Q4: Unknown | R4: Unknown | S4: Unknown | T4: Unknown | U4: Unknown
A5: p04 | B5: BasinWide Information Management System | C5: Water Resources | D5: n04 | E5: DEQ-Water Resources | F5: =CONCATENATE(E5,": ",B5) -> DEQ-Water Resources: BasinWide Information Management System | G5: =VLOOKUP($D5,orgNodes!$A$2:$D$44,3,FALSE) -> Department of Environmental Quality | H5: =VLOOKUP($D5,orgNodes!$A$2:$D$44,4,FALSE) -> 2 | I5: http://bimsportal.ncdenr.org:7001/Welcome.do | J5: No | K5: Unknown | L5: No | M5: Unknown | N5: Unknown | O5: Unknown | P5: Unknown | Q5: Unknown | R5: Unknown | S5: Unknown | T5: Unknown | U5: Unknown
A6: p05 | B6: Water Resources Hot Topics | C6: Water Resources | D6: n04 | E6: DEQ-Water Resources | F6: =CONCATENATE(E6,": ",B6) -> DEQ-Water Resources: Water Resources Hot Topics | G6: =VLOOKUP($D6,orgNodes!$A$2:$D$44,3,FALSE) -> Department of Environmental Quality | H6: =VLOOKUP($D6,orgNodes!$A$2:$D$44,4,FALSE) -> 2 | I6: https://deq.nc.gov/about/divisions/water-resources/dwr-hot-topics | J6: Low | K6: Map; Website | L6: Yes | M6: Individual Export; Link to Source | N6: excel; pdf; shapefile; jpg | O6: Yes | P6: No | Q6: No | R6: No | S6: No | T6: Irregular | U6: Limited Record
A7: p06 | B7: Public Water Supply | C7: Water Resources | D7: n04 | E7: DEQ-Water Resources | F7: =CONCATENATE(E7,": ",B7) -> DEQ-Water Resources: Public Water Supply | G7: =VLOOKUP($D7,orgNodes!$A$2:$D$44,3,FALSE) -> Department of Environmental Quality | H7: =VLOOKUP($D7,orgNodes!$A$2:$D$44,4,FALSE) -> 2 | I7: https://deq.nc.gov/about/divisions/water-resources/drinking-water/drinking-water-protection-program | J7: Low | K7: Website | L7: Yes | M7: Individual Export | N7: pdf; shapefile | O7: Yes | P7: html | Q7: Yes | R7: Administrative | S7: No | T7: Irregular | U7: Current Only
A8: p07 | B8: Sampling Status Report | C8: Public Water Supply | D8: n06 | E8: DEQ-Public Water Supply | F8: =CONCATENATE(E8,": ",B8) -> DEQ-Public Water Supply: Sampling Status Report | G8: =VLOOKUP($D8,orgNodes!$A$2:$D$44,3,FALSE) -> Department of Environmental Quality | H8: =VLOOKUP($D8,orgNodes!$A$2:$D$44,4,FALSE) -> 2 | I8: https://pws.ncwater.org/PWSReports/pages/default.aspx | J8: Low | K8: Website | L8: Yes | M8: Individual Export | N8: pdf | O8: No | P8: in data | Q8: No | R8: Administrative | S8: No | T8: Irregular | U8: Limited Record
A9: p08 | B9: Drinking Water Watch | C9: Public Water Supply | D9: n06 | E9: DEQ-Public Water Supply | F9: =CONCATENATE(E9,": ",B9) -> DEQ-Public Water Supply: Drinking Water Watch | G9: =VLOOKUP($D9,orgNodes!$A$2:$D$44,3,FALSE) -> Department of Environmental Quality | H9: =VLOOKUP($D9,orgNodes!$A$2:$D$44,4,FALSE) -> 2 | I9: https://www.pwss.enr.state.nc.us/NCDWW2/ | J9: Low | K9: Website | L9: Yes | M9: Copy and Paste | N9: html | O9: No | P9: No | Q9: No | R9: No | S9: No | T9: Irregular | U9: Limited Record
A10: p09 | B10: Watershed Assessment Team | C10: Water Sciences | D10: n43 | E10: DEQ-Water Sciences | F10: =CONCATENATE(E10,": ",B10) -> DEQ-Water Sciences: Watershed Assessment Team | G10: =VLOOKUP($D10,orgNodes!$A$2:$D$44,3,FALSE) -> Department of Environmental Quality | H10: =VLOOKUP($D10,orgNodes!$A$2:$D$44,4,FALSE) -> 2 | I10: https://deq.nc.gov/about/divisions/water-resources/water-resources-data/watershed-assessment-team | J10: Low | K10: Website | L10: Yes | M10: Individual Export | N10: pdf | O10: No | P10: No | Q10: No | R10: No | S10: No | T10: Unknown | U10: Current Only
A11: p10 | B11: Local Water Supply Plans | C11: Water Planning | D11: n07 | E11: DEQ-Water Planning | F11: =CONCATENATE(E11,": ",B11) -> DEQ-Water Planning: Local Water Supply Plans | G11: =VLOOKUP($D11,orgNodes!$A$2:$D$44,3,FALSE) -> Department of Environmental Quality | H11: =VLOOKUP($D11,orgNodes!$A$2:$D$44,4,FALSE) -> 2 | I11: https://www.ncwater.org/Water_Supply_Planning/Local_Water_Supply_Plan/index.php | J11: Low | K11: Website | L11: Yes | M11: Copy and Paste | N11: html | O11: No | P11: in data | Q11: No | R11: Administrative; Descriptive | S11: No | T11: Yearly or Higher | U11: Period of Record
A12: p11 | B12: Basin Planning | C12: Water Planning | D12: n07 | E12: DEQ-Water Planning | F12: =CONCATENATE(E12,": ",B12) -> DEQ-Water Planning: Basin Planning | G12: =VLOOKUP($D12,orgNodes!$A$2:$D$44,3,FALSE) -> Department of Environmental Quality | H12: =VLOOKUP($D12,orgNodes!$A$2:$D$44,4,FALSE) -> 2 | I12: https://deq.nc.gov/about/divisions/water-resources/planning/basin-planning/maps | J12: Medium | K12: Map; Website | L12: Yes | M12: Web Services; Individual Export | N12: pdf; shapefile | O12: No | P12: No | Q12: No | R12: No | S12: No | T12: Irregular | U12: Varies
A13: p12 | B13: Classifications, Standards, and Rules Review | C13: Water Planning | D13: n07 | E13: DEQ-Water Planning | F13: =CONCATENATE(E13,": ",B13) -> DEQ-Water Planning: Classifications, Standards, and Rules Review | G13: =VLOOKUP($D13,orgNodes!$A$2:$D$44,3,FALSE) -> Department of Environmental Quality | H13: =VLOOKUP($D13,orgNodes!$A$2:$D$44,4,FALSE) -> 2 | I13: https://deq.nc.gov/about/divisions/water-resources/planning/classification-standards/classifications | J13: Medium | K13: Map | L13: Yes | M13: Link to Source | N13: shapefile; pdf | O13: Yes | P13: html; json | Q13: Yes | R13: Descriptive; Structural | S13: No | T13: Irregular | U13: Current Only
... A33: p32 | B33: Coastal Management Science and Data | C33: Coastal Management | D33: n27 | E33: DEQ-Coastal | F33: =CONCATENATE(E33,": ",B33) -> DEQ-Coastal: Coastal Management Science and Data | G33: =VLOOKUP($D33,orgNodes!$A$2:$D$44,3,FALSE) -> Department of Environmental Quality | H33: =VLOOKUP($D33,orgNodes!$A$2:$D$44,4,FALSE) -> 2 | I33: https://deq.nc.gov/about/divisions/coastal-management/coastal-management-data/setback-factor-maps-1998-shoreline/wetlands-gis-data | J33: Medium | K33: Map; Website | L33: Yes | M33: Individual Export; Web Services | N33: shapefile | O33: Yes | P33: Broken Link | Q33: Unknown | R33: Unknown | S33: Unknown | T33: Irregular | U33: Current Only
A34: p33 | B34: Application Tracker | C34: Permits and Rules | D34: NA | E34: DEQ-Permits and Rules | F34: =CONCATENATE(E34,": ",B34) -> DEQ-Permits and Rules: Application Tracker | G34: Departmetn of Environmental Quality | H34: 2 | I34: https://deq.nc.gov/permits-regulations/permit-guidance/environmental-application-tracker | J34: High | K34: Map | L34: No | M34: None | N34: None | O34: No | P34: No | Q34: No | R34: No | S34: No | T34: Daily or Higher | U34: Current Only
A35: p34 | B35: NCDEQ Online GIS | C35: Department of Environmental Quality | D35: n02 | E35: DEQ-Online GIS | F35: =CONCATENATE(E35,": ",B35) -> DEQ-Online GIS: NCDEQ Online GIS | G35: =VLOOKUP($D35,orgNodes!$A$2:$D$44,3,FALSE) -> Department of Environmental Quality | H35: =VLOOKUP($D35,orgNodes!$A$2:$D$44,4,FALSE) -> 2 | I35: http://data-ncdenr.opendata.arcgis.com/ | J35: High | K35: Catalog | L35: Yes | M35: Individual Export; Web Services | N35: shapefile; raster; kml; geodatabase; csv | O35: Yes | P35: json; html | Q35: No | R35: Administrative; Descriptive | S35: Yes | T35: Irregular | U35: Varies
A36: p35 | B36: Non-Point Source Pollution Program | C36: On Site Water Protection | D36: n38 | E36: HHS-Water Protection | F36: =CONCATENATE(E36,": ",B36) -> HHS-Water Protection: Non-Point Source Pollution Program | G36: =VLOOKUP($D36,orgNodes!$A$2:$D$44,3,FALSE) -> Department of Health and Human Services | H36: =VLOOKUP($D36,orgNodes!$A$2:$D$44,4,FALSE) -> 5 | I36: https://ehs.ncpublichealth.com/oswp/nps/resources.htm | J36: Low | K36: Website | L36: Yes | M36: Individual Export | N36: pdf | O36: No | P36: No | Q36: No | R36: No | S36: No | T36: Unknown | U36: Not Applicable
A37: p36 | B37: NC Onemap | C37: Geographic Information Coordinating Council | D37: n34 | E37: IT-GIS Data | F37: =CONCATENATE(E37,": ",B37) -> IT-GIS Data: NC Onemap | G37: =VLOOKUP($D37,orgNodes!$A$2:$D$44,3,FALSE) -> Department of Information Technology | H37: =VLOOKUP($D37,orgNodes!$A$2:$D$44,4,FALSE) -> 4 | I37: http://www.nconemap.com/ | J37: Medium | K37: Map; Catalog | L37: Yes | M37: Web Services; Individual Export | N37: shapefile; raster; json; csv | O37: Yes | P37: xml | Q37: No | R37: Administrative; Descriptive; Structural | S37: Yes | T37: Irregular | U37: Current Only
A38: p37 | B38: Environmental Statistics | C38: Agricultural Statistics | D38: n29 | E38: DACS-Ag Statistics | F38: =CONCATENATE(E38,": ",B38) -> DACS-Ag Statistics: Environmental Statistics | G38: =VLOOKUP($D38,orgNodes!$A$2:$D$44,3,FALSE) -> Department of Agriculture and Consumer Services | H38: =VLOOKUP($D38,orgNodes!$A$2:$D$44,4,FALSE) -> 3 | I38: http://www.ncagr.gov/stats/environmental/index.htm | J38: Low | K38: Website | L38: Yes | M38: Individual Export; Copy and Paste | N38: pdf | O38: No | P38: No | Q38: No | R38: No | S38: No | T38: Irregular | U38: Period of Record
A39: p38 | B39: Weather and Crop Reports | C39: Agricultural Statistics | D39: n29 | E39: DACS-Ag Statistics | F39: =CONCATENATE(E39,": ",B39) -> DACS-Ag Statistics: Weather and Crop Reports | G39: =VLOOKUP($D39,orgNodes!$A$2:$D$44,3,FALSE) -> Department of Agriculture and Consumer Services | H39: =VLOOKUP($D39,orgNodes!$A$2:$D$44,4,FALSE) -> 3 | I39: http://www.ncagr.gov/stats/weather/weather.htm | J39: Low | K39: Website | L39: Yes | M39: Individual Export; Copy and Paste | N39: pdf | O39: Yes | P39: in data | Q39: No | R39: Administrative | S39: No | T39: Weekly or higher | U39: Limited Record
A40: p39 | B40: Water Quality | C40: North Carolina Forest Service | D40: n32 | E40: DACS-Forest Service | F40: =CONCATENATE(E40,": ",B40) -> DACS-Forest Service: Water Quality | G40: =VLOOKUP($D40,orgNodes!$A$2:$D$44,3,FALSE) -> Department of Agriculture and Consumer Services | H40: =VLOOKUP($D40,orgNodes!$A$2:$D$44,4,FALSE) -> 3 | I40: http://www.ncforestservice.gov/water_quality/water_quality.htm# | J40: Low | K40: Website | L40: Yes | M40: Individual Export; Copy and Paste | N40: pdf | O40: No | P40: No | Q40: No | R40: No | S40: No | T40: Yearly or Higher | U40: Not Applicable
A41: p40 | B41: Environmental Compliance | C41: Connect NCDOT | D41: NA | E41: DOT-Env. Compliance | F41: =CONCATENATE(E41,": ",B41) -> DOT-Env. Compliance: Environmental Compliance | G41: Department of Transportation | H41: 6 | I41: https://connect.ncdot.gov/resources/Environmental/Pages/default.aspx | J41: Low | K41: Website | L41: Yes | M41: Individual Export | N41: pdf | O41: No | P41: No | Q41: No | R41: No | S41: No | T41: Irregular | U41: Not Applicable
A42: p41 | B42: Floodplain Mapping and Management | C42: Risk Management | D42: n42 | E42: PS-Risk Management | F42: =CONCATENATE(E42,": ",B42) -> PS-Risk Management: Floodplain Mapping and Management | G42: =VLOOKUP($D42,orgNodes!$A$2:$D$44,3,FALSE) -> Department of Public Safety | H42: 7 | I42: https://flood.nc.gov/ncflood/index.html | J42: Medium | K42: Map; Catalog | L42: Yes | M42: Link to Source; Individual Export | N42: pdf | O42: Yes | P42: html | Q42: No | R42: Administrative | S42: No | T42: Unknown | U42: Current Only
A43: p42 | B43: Flood Inundation Mapping and Alert Network | C43: Risk Management | D43: n42 | E43: PS-Risk Management | F43: =CONCATENATE(E43,": ",B43) -> PS-Risk Management: Flood Inundation Mapping and Alert Network | G43: =VLOOKUP($D43,orgNodes!$A$2:$D$44,3,FALSE) -> Department of Public Safety | H43: 7 | I43: https://fiman.nc.gov/fiman/ | J43: High | K43: Map | L43: Yes | M43: Individual Export; Batch Export | N43: excel; pdf | O43: Yes | P43: html | Q43: No | R43: Descriptive | S43: No | T43: Daily or Higher | U43: Current Only
A44: p43 | B44: Flood Risk Information System | C44: Risk Management | D44: n42 | E44: PS-Risk Management | F44: =CONCATENATE(E44,": ",B44) -> PS-Risk Management: Flood Risk Information System | G44: =VLOOKUP($D44,orgNodes!$A$2:$D$44,3,FALSE) -> Department of Public Safety | H44: 7 | I44: https://fris.nc.gov/fris/?ST=NC | J44: High | K44: Map; Catalog | L44: Yes | M44: Individual Export; Batch Export | N44: zip; pdf; shapefile; geodatabase | O44: Yes | P44: html | Q44: No | R44: Administrative | S44: No | T44: Unknown | U44: Current Only
A45: p44 | B45: Spatial Data Download | C45: Risk Management | D45: n42 | E45: PS-Risk Management | F45: =CONCATENATE(E45,": ",B45) -> PS-Risk Management: Spatial Data Download | G45: =VLOOKUP($D45,orgNodes!$A$2:$D$44,3,FALSE) -> Department of Public Safety | H45: 7 | I45: https://sdd.nc.gov/sdd/ | J45: High | K45: Map | L45: Registration Required | M45: Batch Export | N45: geodatabase; shapefile | O45: Yes | P45: Broken Link | Q45: Unknown | R45: Unknown | S45: Unknown | T45: Unknown | U45: Unknown

Sheet dataNodes
A1: dataID | B1: dataGroup | C1: dataCategory
A2: d01 | B2: Built | C2: Infrastructure
A3: d02 | B3: Natural | C3: Infrastructure
A4: d03 | B4: Quality | C4: Quality
A5: d04 | B5: Regulatory | C5: Quality
A6: d05 | B6: Evapotranspiration | C6: Quantity
A7: d06 | B7: Extreme Events | C7: Quantity
A8: d07 | B8: Glacial and Snow | C8: Quantity
A9: d08 | B9: Groundwater | C9: Quantity
A10: d09 | B10: Meteorology | C10: Quantity
A11: d10 | B11: Precipitation | C11: Quantity
A12: d11 | B12: Reservoir | C12: Quantity
... A19: d18 | B19: Management Plans | C19: Use

Sheet dataNodeTypes
A1: platformID | B1: platform | C1: entity | D1: tier1and2entity | E1: website | F1: data | G1: dataGroup | H1: dataCategory | I1: dataID | J1: notes | M1: dataGroup - linked to dataNodes tab | N1: dataID - linked to dataNodes tab
A2: p01 | B2: NC Division of Water Resources Online Document Library | C2: Water Resources | D2: Department of Environmental Quality | E2: https://edocs.deq.nc.gov/WaterResources/Welcome.aspx?cr=1 | F2: Water Quality Permits | G2: Regulatory | H2: =VLOOKUP(G2,dataNodes!$B$2:$C$19,2,FALSE) -> Quality | I2: =VLOOKUP(G2,$M$2:$N$19,2,FALSE) -> d04 | M2: =dataNodes!B2 -> Built | N2: =dataNodes!A2 -> d01
A3: p01 | B3: NC Division of Water Resources Online Document Library | C3: Water Resources | D3: Department of Environmental Quality | E3: https://edocs.deq.nc.gov/WaterResources/Welcome.aspx?cr=1 | F3: Stream and Buffer Determination | G3: Regulatory | H3: =VLOOKUP(G3,dataNodes!$B$2:$C$19,2,FALSE) -> Quality | I3: =VLOOKUP(G3,$M$2:$N$19,2,FALSE) -> d04 | M3: =dataNodes!B3 -> Natural | N3: =dataNodes!A3 -> d02
A4: p01 | B4: NC Division of Water Resources Online Document Library | C4: Water Resources | D4: Department of Environmental Quality | E4: https://edocs.deq.nc.gov/WaterResources/Welcome.aspx?cr=1 | F4: Wetland Permits | G4: Regulatory | H4: =VLOOKUP(G4,dataNodes!$B$2:$C$19,2,FALSE) -> Quality | I4: =VLOOKUP(G4,$M$2:$N$19,2,FALSE) -> d04 | M4: =dataNodes!B4 -> Quality | N4: =dataNodes!A4 -> d03
A5: p02 | B5: Annual Compliance Reports | C5: Water Resources | D5: Department of Environmental Quality | E5: https://deq.nc.gov/about/divisions/water-resources/forms-publications | F5: Annual Compliance Reports | G5: Regulatory | H5: =VLOOKUP(G5,dataNodes!$B$2:$C$19,2,FALSE) -> Quality | I5: =VLOOKUP(G5,$M$2:$N$19,2,FALSE) -> d04 | M5: =dataNodes!B5 -> Regulatory | N5: =dataNodes!A5 -> d04
A6: p03 | B6: eDMR - NPDES reporting | C6: Water Resources | D6: Department of Environmental Quality | E6: https://deq.nc.gov/about/divisions/water-resources/edmr | F6: NPDES Facility Compliance | G6: Regulatory | H6: =VLOOKUP(G6,dataNodes!$B$2:$C$19,2,FALSE) -> Quality | I6: =VLOOKUP(G6,$M$2:$N$19,2,FALSE) -> d04 | M6: =dataNodes!B6 -> Evapotranspiration | N6: =dataNodes!A6 -> d05
A7: p04 | B7: BasinWide Information Management System | C7: Water Resources | D7: Department of Environmental Quality | E7: https://bimsportal.ncdenr.org/Welcome.do | F7: Facility Compliance | G7: Regulatory | H7: =VLOOKUP(G7,dataNodes!$B$2:$C$19,2,FALSE) -> Quality | I7: =VLOOKUP(G7,$M$2:$N$19,2,FALSE) -> d04 | M7: =dataNodes!B7 -> Extreme Events | N7: =dataNodes!A7 -> d06
A8: p04 | B8: BasinWide Information Management System | C8: Water Resources | D8: Department of Environmental Quality | E8: https://bimsportal.ncdenr.org/Welcome.do | F8: Stormwater Assessments | G8: Regulatory | H8: =VLOOKUP(G8,dataNodes!$B$2:$C$19,2,FALSE) -> Quality | I8: =VLOOKUP(G8,$M$2:$N$19,2,FALSE) -> d04 | M8: =dataNodes!B8 -> Glacial and Snow | N8: =dataNodes!A8 -> d07
A9: p05 | B9: Water Resources Hot Topics | C9: Water Resources | D9: Department of Environmental Quality | E9: https://deq.nc.gov/about/divisions/water-resources/dwr-hot-topics | F9: Groundwater monitoring data | G9: Quality | H9: =VLOOKUP(G9,dataNodes!$B$2:$C$19,2,FALSE) -> Quality | I9: =VLOOKUP(G9,$M$2:$N$19,2,FALSE) -> d03 | M9: =dataNodes!B9 -> Groundwater | N9: =dataNodes!A9 -> d08
A10: p05 | B10: Water Resources Hot Topics | C10: Water Resources | D10: Department of Environmental Quality | E10: https://deq.nc.gov/about/divisions/water-resources/dwr-hot-topics | F10: Groundwater monitoring data | G10: Groundwater | H10: =VLOOKUP(G10,dataNodes!$B$2:$C$19,2,FALSE) -> Quantity | I10: =VLOOKUP(G10,$M$2:$N$19,2,FALSE) -> d08 | M10: =dataNodes!B10 -> Meteorology | N10: =dataNodes!A10 -> d09
A11: p05 | B11: Water Resources Hot Topics | C11: Water Resources | D11: Department of Environmental Quality | E11: https://deq.nc.gov/about/divisions/water-resources/dwr-hot-topics | F11: Discharge Permit | G11: Regulatory | H11: =VLOOKUP(G11,dataNodes!$B$2:$C$19,2,FALSE) -> Quality | I11: =VLOOKUP(G11,$M$2:$N$19,2,FALSE) -> d04 | M11: =dataNodes!B11 -> Precipitation | N11: =dataNodes!A11 -> d10
A12: p05 | B12: Water Resources Hot Topics | C12: Water Resources | D12: Department of Environmental Quality | E12: https://ncdenr.maps.arcgis.com/apps/webappviewer/index.html?id=c11c3af22c854d9a8d4e8415e095088a | F12: Water Well Investigation | G12: Quality | H12: =VLOOKUP(G12,dataNodes!$B$2:$C$19,2,FALSE) -> Quality | I12: =VLOOKUP(G12,$M$2:$N$19,2,FALSE) -> d03 | M12: =dataNodes!B12 -> Reservoir | N12: =dataNodes!A12 -> d11
A13: p05 | B13: Water Resources Hot Topics | C13: Water Resources | D13: Department of Environmental Quality | E13: https://deq.nc.gov/about/divisions/water-resources/dwr-hot-topics | F13: Jordan Lake Nutrients | G13: Quality | H13: =VLOOKUP(G13,dataNodes!$B$2:$C$19,2,FALSE) -> Quality | I13: =VLOOKUP(G13,$M$2:$N$19,2,FALSE) -> d03 | M13: =dataNodes!B13 -> Soil | N13: =dataNodes!A13 -> d12
... A19: p07 | B19: Sampling Status Report | C19: Water Resources | D19: Department of Environmental Quality | E19: https://pws.ncwater.org/PWSReports/pages/default.aspx | F19: Facility Compliance | G19: Regulatory | H19: =VLOOKUP(G19,dataNodes!$B$2:$C$19,2,FALSE) -> Quality | I19: =VLOOKUP(G19,$M$2:$N$19,2,FALSE) -> d04 | M19: =dataNodes!B19 -> Management Plans | N19: =dataNodes!A19 -> d18
A20: p08 | B20: Drinking Water Watch | C20: Water Resources | D20: Department of Environmental Quality | E20: https://www.pwss.enr.state.nc.us/NCDWW2/ | F20: Water Systems | G20: Utilities | H20: =VLOOKUP(G20,dataNodes!$B$2:$C$19,2,FALSE) -> Use | I20: =VLOOKUP(G20,$M$2:$N$19,2,FALSE) -> d17
A21: p08 | B21: Drinking Water Watch | C21: Water Resources | D21: Department of Environmental Quality | E21: https://www.pwss.enr.state.nc.us/NCDWW2/ | F21: Water Systems | G21: Regulatory | H21: =VLOOKUP(G21,dataNodes!$B$2:$C$19,2,FALSE) -> Quality | I21: =VLOOKUP(G21,$M$2:$N$19,2,FALSE) -> d04
A22: p09 | B22: Watershed Assessment Team | C22: Water Resources | D22: Department of Environmental Quality | E22: https://deq.nc.gov/about/divisions/water-resources/water-resources-data/watershed-assessment-team | F22: Surface water quality | G22: Quality | H22: =VLOOKUP(G22,dataNodes!$B$2:$C$19,2,FALSE) -> Quality | I22: =VLOOKUP(G22,$M$2:$N$19,2,FALSE) -> d03
A23: p10 | B23: Local Water Supply Plans | C23: Water Resources | D23: Department of Environmental Quality | E23: https://www.ncwater.org/Water_Supply_Planning/Local_Water_Supply_Plan/index.php | F23: Local Water Supply Plans | G23: Utilities | H23: =VLOOKUP(G23,dataNodes!$B$2:$C$19,2,FALSE) -> Use | I23: =VLOOKUP(G23,$M$2:$N$19,2,FALSE) -> d17
A24: p11 | B24: Basin Planning | C24: Water Resources | D24: Department of Environmental Quality | E24: https://deq.nc.gov/about/divisions/water-resources/planning/basin-planning/maps | F24: Facility Permits | G24: Regulatory | H24: =VLOOKUP(G24,dataNodes!$B$2:$C$19,2,FALSE) -> Quality | I24: =VLOOKUP(G24,$M$2:$N$19,2,FALSE) -> d04
A25: p11 | B25: Basin Planning | C25: Water Resources | D25: Department of Environmental Quality | E25: https://deq.nc.gov/about/divisions/water-resources/planning/basin-planning/maps | F25: Surface water quality | G25: Quality | H25: =VLOOKUP(G25,dataNodes!$B$2:$C$19,2,FALSE) -> Quality | I25: =VLOOKUP(G25,$M$2:$N$19,2,FALSE) -> d03
A26: p11 | B26: Basin Planning | C26: Water Resources | D26: Department of Environmental Quality | E26: https://deq.nc.gov/about/divisions/water-resources/planning/basin-planning/maps | F26: Benthos and Fish Sampling | G26: Quality | H26: =VLOOKUP(G26,dataNodes!$B$2:$C$19,2,FALSE) -> Quality | I26: =VLOOKUP(G26,$M$2:$N$19,2,FALSE) -> d03
A27: p11 | B27: Basin Planning | C27: Water Resources | D27: Department of Environmental Quality | E27: https://deq.nc.gov/about/divisions/water-resources/planning/basin-planning/maps | F27: 303d Assessment & TMDLs | G27: Quality | H27: =VLOOKUP(G27,dataNodes!$B$2:$C$19,2,FALSE) -> Quality | I27: =VLOOKUP(G27,$M$2:$N$19,2,FALSE) -> d03
A28: p11 | B28: Basin Planning | C28: Water Resources | D28: Department of Environmental Quality | E28: https://deq.nc.gov/about/divisions/water-resources/planning/basin-planning/maps | F28: 303d Assessment & TMDLs | G28: Regulatory | H28: =VLOOKUP(G28,dataNodes!$B$2:$C$19,2,FALSE) -> Quality | I28: =VLOOKUP(G28,$M$2:$N$19,2,FALSE) -> d04
A29: p11 | B29: Basin Planning | C29: Water Resources | D29: Department of Environmental Quality | E29: https://deq.nc.gov/about/divisions/water-resources/planning/basin-planning/maps | F29: Water supply watersheds | G29: Utilities | H29: =VLOOKUP(G29,dataNodes!$B$2:$C$19,2,FALSE) -> Use | I29: =VLOOKUP(G29,$M$2:$N$19,2,FALSE) -> d17
A30: p11 | B30: Basin Planning | C30: Water Resources | D30: Department of Environmental Quality | E30: https://deq.nc.gov/about/divisions/water-resources/planning/basin-planning/maps | F30: Watershed boundaries | G30: Natural | H30: =VLOOKUP(G30,dataNodes!$B$2:$C$19,2,FALSE) -> Infrastructure | I30: =VLOOKUP(G30,$M$2:$N$19,2,FALSE) -> d02
A31: p11 | B31: Basin Planning | C31: Water Resources | D31: Department of Environmental Quality | E31: https://deq.nc.gov/about/divisions/water-resources/planning/basin-planning/maps | F31: Watershed quality and quantity management plans | G31: Management Plans | H31: =VLOOKUP(G31,dataNodes!$B$2:$C$19,2,FALSE) -> Use | I31: =VLOOKUP(G31,$M$2:$N$19,2,FALSE) -> d18
... A99: p44 | B99: Spatial Data Download | C99: Risk Management | D99: Department of Public Safety | E99: https://sdd.nc.gov/sdd/ | F99: Flood Hazard Area | G99: Extreme Events | H99: =VLOOKUP(G99,dataNodes!$B$2:$C$19,2,FALSE) -> Quantity | I99: =VLOOKUP(G99,$M$2:$N$19,2,FALSE) -> d06

Sheet dataEdges
A1: from | B1: to
A2: p01 | B2: d04
A3: p02 | B3: d04
A4: p03 | B4: d04
A5: p04 | B5: d04
A6: p05 | B6: d03
A7: p05 | B7: d08
A8: p05 | B8: d04
A9: p06 | B9: d17
A10: p06 | B10: d03
A11: p07 | B11: d17
A12: p07 | B12: d04
... A81: p44 | B81: d06
