Workbook
Name Infrastructure: #REF!
Name Quality: #REF!
Name Quantity: #REF!
Name Use: #REF!

Sheet metricsKey
A1: columnName | B1: categories | C1: definition | D1: proposedScore
B2: None | C2: Data are collected but not found.
B3: Unknown | C3: Data are collected and available but not to the public
A4: easeDiscover | B4: Low | C4: Data are not found in the same location and are not searchable. | D4: 1
A5: easeDiscover | B5: Medium | C5: Data found at the same location; however, the search index is poor or inconsistent. | D5: 2
A6: easeDiscover | B6: High | C6: Data found at the same location that can be queried via spatial or text filters with well-defined key words. | D6: 3
A7: methodDiscover | B7: Unknown | C7: Data could not be discovered without seeking permission, registration, or an additional step. | D7: 0
A8: methodDiscover | B8: Website | C8: Data were found by navigating through URL links. | D8: 1
A9: methodDiscover | B9: Catalog | C9: Connects data sources to a searchable, descriptive directory so the user can find and explore the data they need no matter where it's located. | D9: 2
A10: methodDiscover | B10: Map | C10: Data found based on a location (such as watershed, aquifer, or county). | D10: 2
A11: methodDiscover | B11: Website; Catalog | C11: Combination of values | D11: 1.5
A12: methodDiscover | B12: Catalog; Map | C12: Combination of values | D12: 2
A13: methodDiscover | B13: Website; Map | C13: Combination of values | D13: 1.5
A14: easeAccess | B14: Unknown | C14: Platform shows the data exist, but does not provide any information or means to access the data. | D14: 0
A15: easeAccess | B15: Permission Required | C15: User must request permission to access data. Permission is not guaranteed. | D15: 1
... A32: fileFormat | B32: Machine readable with open software | C32: Data are machine-readable and include csv, txt, xml, json, geojson, netCDF, etc. | D32: 5
A33: metadata | B33: Unknown | C33: Don't know if they have metadata… usually can't access data
A34: metadata | B34: yes | C34: All the data have metadata
A35: metadata | B35: no | C35: None of the data have metadata
A36: metadata | B36: some | C36: Some data have metadata
A37: metadataFormat | B37: No | C37: No metadata were provided. | D37: 0
A38: metadataFormat | B38: Unknown | C38: Data could not be accessed. It is unknown if metadata are provided. | D38: 1
A39: metadataFormat | B39: Not machine readable | C39: Metadata is not in a machine readable format. It may be located within the text of a pdf. | D39: 1
A40: metadataFormat | B40: Machine readable with proprietary software | C40: Metadata are in a machine readable format that requires proprietary software to access. File formats include excel and word. | D40: 2
A41: metadataFormat | B41: Machine readable with open software | C41: Metadata are in a machine-readable format (typically xml). Sometimes the metadata are part of the data file (for instance, USGS stream gauge data provides metadata within the data download). | D41: 3
A42: dataDefinitions | B42: No | C42: No data glossaries found. | D42: 0
A43: dataDefinitions | B43: Unknown | C43: Data were not publicly accessible and so it is unknown if a data glossary is available. | D43: 0
A44: dataDefinitions | B44: Some | C44: Some data had glossaries. | D44: 1
A45: dataDefinitions | B45: Yes | C45: Data glossaries were available for all data. | D45: 2
A46: metadataAttributes | B46: No | C46: No metadata were provided. | D46: 0
A47: metadataAttributes | B47: Unknown | C47: Data were not publicly accessible so it is unknown if metadata were provided | D47: 0
A48: metadataAttributes | B48: Administrative | C48: Administrative metadata provides information to help manage a resource, such as when and how it was created, file type and other technical information, including quality control, and who can access it. | D48: 1
... A66: lengthAvailable | B66: Period of Record | C66: The full time series for the data are accessible. | D66: 4
A68: List of File Formats | B68: List of Metadata formats
A69: unknown | B69: unknown
A70: no | B70: no
A71: pdf | B71: broken link
A72: png | B72: in data
A73: image | B73: pdf
A74: jpg | B74: word
...

Sheet orgEdges
A1: from | B1: to
A2: calculate in R

Sheet orgNodes
A1: entityID | B1: entity | C1: tier1and2entity | D1: tier1and2entityID | E1: entityIDAbove | F1: mission | G1: website | H1: operational | I1: decision | J1: regulatory | K1: research | L1: level
A2: n01 | B2: Wyoming | C2: Wyoming | D2: 1 | E2: NA | G2: http://www.wyo.gov/ | H2: Yes | I2: Yes | J2: Yes | K2: Yes | L2: 1
A3: n02 | B3: Department of Agriculture | C3: Department of Agriculture | D3: 2 | E3: n01 | F3: Assists the citizens of Wyoming to live safe and healthy lives, promote and preserve our agricultural community, be responsible stewards of our natural resources, and achieve integrity in the marketplace. | G3: https://wyagric.state.wy.us/ | H3: No | I3: Yes | J3: No | K3: Yes | L3: 2
A4: n03 | B4: Natural Resources and Policy | C4: Department of Agriculture | D4: 2 | E4: n02 | F4: Lead and support the agriculture industry in the wise management of natural resources to further the interests of that industry and to enhance Wyoming's natural resources, and increase the visibility of the agricultural industry and WDA programs and employees. | G4: https://wyagric.state.wy.us/divisions/nrp | H4: No | I4: Yes | J4: No | K4: No | L4: 3
A5: n04 | B5: Climate Issues Committee | C5: Department of Agriculture | D5: 2 | E5: n02 | F5: Address timely climate issues by reviewing current issues and discussing possible future climate related impacts. | G5: https://wyagric.state.wy.us/divisions/nrp/climate-issues | H5: No | I5: Yes | J5: No | K5: Yes | L5: 3
A6: n05 | B6: Department of Environmental Quality | C6: Department of Environmental Quality | D6: 3 | E6: n01 | F6: Contribute to the quality of life in Wyoming through a combination of monitoring, permitting, inspection, enforcement, restoration and remediation activities that support responsible stewardship of our state’s natural resources. | G6: http://deq.wyoming.gov/ | H6: Yes | I6: Yes | J6: Yes | K6: Yes | L6: 2
A7: n06 | B7: Division of Water Quality | C7: Department of Environmental Quality | D7: 3 | E7: n05 | F7: Keep Wyoming’s water clean by monitoring and protecting surface- and groundwater in the state | G7: http://deq.wyoming.gov/wqd/ | H7: Yes | I7: Yes | J7: Yes | K7: No | L7: 3
A8: n07 | B8: Groundwater Program | C8: Department of Environmental Quality | D8: 3 | E8: n06 | F8: Protect and preserve Wyoming’s groundwater by permitting facilities to prevent contamination, and investigating and cleaning up known releases. | G8: http://deq.wyoming.gov/wqd/groundwater/ | H8: Yes | I8: No | J8: Yes | K8: No | L8: 4
A9: n08 | B9: Watershed Protection Program | C9: Department of Environmental Quality | D9: 3 | E9: n06 | F9: Responsible for a variety of planning and water quality project implementation activities | G9: http://deq.wyoming.gov/wqd/watershed-protection-2/ | H9: No | I9: Yes | J9: No | K9: Yes | L9: 4
A10: n09 | B10: Water and Wastewater Program | C10: Department of Environmental Quality | D10: 3 | E10: n06 | F10: Ensure safe and adequate supplies of drinking water and the proper disposal of wastewater | G10: http://deq.wyoming.gov/wqd/water-wastewater/ | H10: Yes | I10: No | J10: Yes | K10: No | L10: 4
A11: n10 | B11: Wyoming Pollutant Discharge Elimination System (WYPDES) Program | C11: Department of Environmental Quality | D11: 3 | E11: n06 | F11: regulate discharge of any pollutants from a point source into surface water | G11: http://deq.wyoming.gov/wqd/wypdes/ | H11: No | I11: No | J11: Yes | K11: No | L11: 4
A12: n11 | B12: State Engineer's Office | C12: State Engineer's Office | D12: 4 | E12: n01 | F12: Charged with the regulation and administration of the water resources in Wyoming | G12: https://sites.google.com/a/wyo.gov/seo/home/about | H12: Yes | I12: Yes | J12: Yes | K12: No | L12: 2
A13: n12 | B13: Groundwater Division | C13: State Engineer's Office | D13: 4 | E13: n11 | F13: Processing and maintaining groundwater permits, as well as a statewide observation well network. | G13: http://seo.wyo.gov/ground-water | H13: Yes | I13: Yes | J13: Yes | K13: No | L13: 3
A14: n13 | B14: Surface water Division | C14: State Engineer's Office | D14: 4 | E14: n11 | F14: Review permit applications which beneficially use surface waters of the state of Wyoming | G14: http://seo.wyo.gov/surface-water | H14: No | I14: Yes | J14: Yes | K14: No | L14: 3
... A26: n25 | B26: State Climate Office | C26: University of Wyoming | D26: 8 | E26: n24 | F26: provides a variety of services, ranging from the development of enhanced drought-monitoring products to the online dissemination of water and climate data. WRDS and the SCO also support a variety of stakeholder groups by assisting in the development of the State Water Plan and helping to coordinate long-term climate and hydrologic monitoring efforts throughout the region. | G26: http://www.wrds.uwyo.edu/sco/climate_office.html | H26: No | I26: Yes | J26: No | K26: Yes | L26: 4

Sheet platformNodes
A1: platformID | B1: platform | C1: entity | D1: entityID | E1: webLabel | F1: heatmapLabel | G1: tier1and2entity | H1: tier1and2entityID | I1: website | J1: easeDiscover | K1: methodDiscover | L1: easeAccess | M1: methodAccess | N1: LinktoSource | O1: fileFormat | P1: metadata | Q1: metadataFormat | R1: dataDefinitions | S1: metaAttributes | T1: metadataStandards | U1: timeliness | V1: lengthAvailable | W1: Notes
A2: p02 | B2: Gillette-Madison Well Field Project | C2: Groundwater | D2: n07 | E2: WDEQ | F2: =CONCATENATE(E2,": ",B2) -> WDEQ: Gillette-Madison Well Field Project | G2: Department of Environmental Quality | H2: 3 | I2: http://deq.wyoming.gov/wqd/gillette-madison-well-field-project/ | J2: Medium | K2: Website | L2: Yes | M2: Individual Export | N2: Not Applicable | O2: pdf; excel | P2: yes | Q2: pdf | R2: Some | S2: Descriptive; Administrative | T2: No | U2: Unknown | V2: Current Only
A3: p04 | B3: Pavillion Investigation | C3: Groundwater | D3: n07 | E3: WDEQ | F3: =CONCATENATE(E3,": ",B3) -> WDEQ: Pavillion Investigation | G3: Department of Environmental Quality | H3: 3 | I3: http://deq.wyoming.gov/wqd/pavillion-investigation/ | J3: Medium | K3: Website; Catalog | L3: Yes | M3: Individual Export | N3: Not Applicable | O3: pdf | P3: yes | Q3: in data | R3: Yes | S3: Descriptive; Administrative | T3: No | U3: Irregular | V3: Current Only
A4: p06 | B4: GEM Database | C4: Groundwater | D4: n07 | E4: WDEQ | F4: =CONCATENATE(E4,": ",B4) -> WDEQ: GEM Database | G4: Department of Environmental Quality | H4: 3 | I4: http://deq.wyoming.gov/wqd/underground-injection-control/resources/gem-database/ | J4: Low | K4: Unknown | L4: Permission Required | M4: Unknown | N4: Not Applicable | O4: unknown | P4: Unknown | Q4: unknown | R4: Unknown | S4: Unknown | T4: Unknown | U4: Unknown | V4: Unknown
A5: p07 | B5: Monitoring Data | C5: Groundwater | D5: n07 | E5: WDEQ | F5: =CONCATENATE(E5,": ",B5) -> WDEQ: Monitoring Data | G5: Department of Environmental Quality | H5: 3 | I5: http://deq.wyoming.gov/wqd/groundwater/resources/monitoring-data/ | J5: Medium | K5: Website; Catalog | L5: Yes | M5: Individual Export; Full Export | N5: Not Applicable | O5: shapefile; zip; pdf | P5: yes | Q5: html; xml | R5: Yes | S5: Administrative; Descriptive | T5: Yes | U5: Irregular | V5: Current Only
A6: p08 | B6: Nonpoint Source Projects | C6: Watershed Protection | D6: n08 | E6: WDEQ | F6: =CONCATENATE(E6,": ",B6) -> WDEQ: Nonpoint Source Projects | G6: Department of Environmental Quality | H6: 3 | I6: http://deq.wyoming.gov/wqd/non-point-source/resources/projects/ | J6: Low | K6: Website | L6: Yes | M6: Individual Export | N6: Not Applicable | O6: pdf | P6: some | Q6: in data | R6: Some | S6: Descriptive; Administrative | T6: No | U6: Varies | V6: Limited Record
A7: p09 | B7: Waterbody Assessment Reports | C7: Watershed Protection | D7: n08 | E7: WDEQ | F7: =CONCATENATE(E7,": ",B7) -> WDEQ: Waterbody Assessment Reports | G7: Department of Environmental Quality | H7: 3 | I7: http://deq.wyoming.gov/wqd/non-point-source/resources/reports/ | J7: Low | K7: Website | L7: Yes | M7: Individual Export | N7: Not Applicable | O7: pdf | P7: yes | Q7: in data | R7: Yes | S7: Descriptive | T7: No | U7: Yearly or Higher | V7: Limited Record
A8: p10 | B8: TMDL Completed Projects | C8: Watershed Protection | D8: n08 | E8: WDEQ | F8: =CONCATENATE(E8,": ",B8) -> WDEQ: TMDL Completed Projects | G8: Department of Environmental Quality | H8: 3 | I8: http://deq.wyoming.gov/wqd/tmdl/resources/completed-projects/ | J8: Low | K8: Website | L8: Yes | M8: Individual Export | N8: Not Applicable | O8: pdf | P8: Yes | Q8: in data | R8: Yes | S8: Descriptive | T8: No | U8: Irregular | V8: Limited Record
A9: p11 | B9: Water Quality Assessment Reports | C9: Watershed Protection | D9: n08 | E9: WDEQ | F9: =CONCATENATE(E9,": ",B9) -> WDEQ: Water Quality Assessment Reports | G9: Department of Environmental Quality | H9: 3 | I9: http://deq.wyoming.gov/wqd/water-quality-assessment/resources/reports/ | J9: Low | K9: Website | L9: Yes | M9: Individual Export | N9: Not Applicable | O9: pdf; shapefile | P9: yes | Q9: in data | R9: Yes | S9: Administrative; Descriptive | T9: No | U9: Irregular | V9: Period of Record
A10: p12 | B10: Authorized Permit Archive | C10: Water and Wastewater | D10: n09 | E10: WDEQ | F10: =CONCATENATE(E10,": ",B10) -> WDEQ: Authorized Permit Archive | G10: Department of Environmental Quality | H10: 3 | I10: http://deq.wyoming.gov/wqd/water-wastewater/resources/authorized-archive/ | J10: Low | K10: Website; Catalog | L10: Yes | M10: Individual Export | N10: Not Applicable | O10: pdf | P10: yes | Q10: in data | R10: No | S10: Descriptive | T10: No | U10: Irregular | V10: Period of Record
A11: p14 | B11: NRCS Snowdata and Reporting | C11: Snow Survey and Water Supply Forecasting Program | D11: n16 | E11: SNOW | F11: =CONCATENATE(E11,": ",B11) -> SNOW: NRCS Snowdata and Reporting | G11: State Engineer's Office | H11: 4 | I11: http://snow.wyo.gov/snow-data/nrcs-national-water-and-climate-center | J11: Medium | K11: Website | L11: Yes | M11: Link to Source | N11: Indirect | O11: unknown | P11: unknown | Q11: unknown | R11: unknown | S11: Unknown | T11: Unknown | U11: Daily or Higher | V11: Period of Record
A12: p15 | B12: SEO Snowpack Report by Drainage | C12: Snow Survey and Water Supply Forecasting Program | D12: n16 | E12: SNOW | F12: =CONCATENATE(E12,": ",B12) -> SNOW: SEO Snowpack Report by Drainage | G12: State Engineer's Office | H12: 4 | I12: http://snow.wyo.gov/snow-data/seo-snowpack-reports-by-drainage | J12: Medium | K12: Website | L12: Yes | M12: Individual Export | N12: Not Applicable | O12: pdf | P12: no | Q12: no | R12: No | S12: No | T12: No | U12: Yearly or Higher | V12: Limited Record
A13: p16 | B13: NOAA National Snow Analyses | C13: Snow Survey and Water Supply Forecasting Program | D13: n16 | E13: SNOW | F13: =CONCATENATE(E13,": ",B13) -> SNOW: NOAA National Snow Analyses | G13: State Engineer's Office | H13: 4 | I13: http://snow.wyo.gov/snow-data/noaa-national-snow-analyses | J13: Medium | K13: Website | L13: Yes | M13: Link to Source | N13: Indirect | O13: unknown | P13: unknown | Q13: unknown | R13: unknown | S13: Unknown | T13: Unknown | U13: Daily or Higher | V13: Unknown
A14: p17 | B14: Realtime Stream Flow | C14: State Engineer's Office | D14: n11 | E14: SEOFLOW | F14: =CONCATENATE(E14,": ",B14) -> SEOFLOW: Realtime Stream Flow | G14: State Engineer's Office | H14: 4 | I14: http://seoflow.wyo.gov/ | J14: High | K14: Map; Catalog | L14: Yes | M14: Batch Export; Full Export | N14: Not Applicable | O14: csv | P14: Yes | Q14: html | R14: No | S14: Descriptive; Administrative | T14: No | U14: Daily or Higher | V14: Period of Record
A15: p18 | B15: Products and Data | C15: State Climate Office | D15: n16 | E15: WRDS | F15: =CONCATENATE(E15,": ",B15) -> WRDS: Products and Data | G15: University of Wyoming | H15: n24 | I15: http://www.wrds.uwyo.edu/products_and_data.html | J15: High | K15: Website; Map; Catalog | L15: Yes | M15: Copy and Paste; Individual Export | N15: Not Applicable | O15: html; csv; jpg | P15: some | Q15: html; xml | R15: No | S15: Administrative; Descriptive | T15: Yes | U15: Daily or Higher | V15: Period of Record
A16: p20 | B16: Order of the State Engineer - Laramie County Control Area | C16: Groundwater Division | D16: n12 | E16: SEO | F16: =CONCATENATE(E16,": ",B16) -> SEO: Order of the State Engineer - Laramie County Control Area | G16: State Engineer's Office | H16: 4 | I16: http://seo.wyo.gov/ground-water/state-engineer-s-orders | J16: Low | K16: Unknown | L16: Yes | M16: Individual Export | N16: Not Applicable | O16: pdf | P16: yes | Q16: in data | R16: No | S16: Descriptive; Structural | T16: No | U16: Irregular | V16: Current only
A17: p21 | B17: Groundwater Hydrographs | C17: Groundwater Division | D17: n12 | E17: SEO | F17: =CONCATENATE(E17,": ",B17) -> SEO: Groundwater Hydrographs | G17: State Engineer's Office | H17: 4 | I17: http://seo.wyo.gov/documents-data/groundwater-hydrographs | J17: Medium | K17: Website | L17: Yes | M17: Individual Export | N17: Not Applicable | O17: pdf | P17: no | Q17: no | R17: No | S17: No | T17: No | U17: Yearly or Higher | V17: Period of Record
A18: p22 | B18: Interference Investigations | C18: Groundwater Division | D18: n12 | E18: SEO | F18: =CONCATENATE(E18,": ",B18) -> SEO: Interference Investigations | G18: State Engineer's Office | H18: 4 | I18: http://seo.wyo.gov/ground-water/interference-investigations | J18: Medium | K18: Website | L18: Yes | M18: Individual Export | N18: Not Applicable | O18: pdf | P18: yes | Q18: in data | R18: No | S18: Descriptive | T18: No | U18: Irregular | V18: Period of Record
A19: p23 | B19: Dam and Reservoir Planning | C19: Planning Program | D19: n18 | E19: WWDO | F19: =CONCATENATE(E19,": ",B19) -> WWDO: Dam and Reservoir Planning | G19: Wyoming Water Development Office | H19: 5 | I19: http://wwdc.state.wy.us/dam_reservoir/dam_reservoir.html | J19: Medium | K19: Website | L19: Yes | M19: Copy and Paste; Individual Export | N19: Not Applicable | O19: html; pdf | P19: no | Q19: no | R19: No | S19: No | T19: No | U19: Irregular | V19: Current only
A20: p24 | B20: Instream Flow Filings | C20: Planning Program | D20: n18 | E20: WWDO | F20: =CONCATENATE(E20,": ",B20) -> WWDO: Instream Flow Filings | G20: Wyoming Water Development Office | H20: 5 | I20: http://wwdc.state.wy.us/instream_flows/instream_flows.html | J20: Medium | K20: Catalog; Map | L20: Yes | M20: Copy and Paste; Individual Export | N20: Not Applicable | O20: html; pdf | P20: yes | Q20: no | R20: No | S20: Administrative; Structural | T20: No | U20: Varies | V20: Period of Record
A21: p25 | B21: Wyoming Water and Climate Web Atlas | C21: Planning Program | D21: n18 | E21: WWDO | F21: =CONCATENATE(E21,": ",B21) -> WWDO: Wyoming Water and Climate Web Atlas | G21: Wyoming Water Development Office | H21: 5 | I21: http://www.wrds.uwyo.edu/Map/index.html?Type=ISF# | J21: Low | K21: Map | L21: Yes | M21: Individual Export; Link to Source | N21: Direct | O21: html; csv; jpg | P21: some | Q21: in data | R21: No | S21: Administrative; Structural | T21: Yes | U21: Varies | V21: Current only
A22: p27 | B22: Probable Maximum Precipitation | C22: Planning Program | D22: n18 | E22: WWDO | F22: =CONCATENATE(E22,": ",B22) -> WWDO: Probable Maximum Precipitation | G22: Wyoming Water Development Office | H22: 5 | I22: http://wwdc.state.wy.us/PMP/PMP.html | J22: Low | K22: Website | L22: Yes | M22: Individual Export; Full Export | N22: Not Applicable | O22: pdf; shapefile; png | P22: some | Q22: in data | R22: No | S22: Descriptive; Administrative | T22: No | U22: Unknown | V22: Current only
A23: p28 | B23: Wyoming State Water Plans | C23: Planning Program | D23: n18 | E23: WWDO | F23: =CONCATENATE(E23,": ",B23) -> WWDO: Wyoming State Water Plans | G23: Wyoming Water Development Office | H23: 5 | I23: http://waterplan.state.wy.us/ | J23: Low | K23: Catalog; Website | L23: Yes | M23: Copy and Paste; Individual Export; Link to Source | N23: Direct | O23: html; pdf | P23: yes | Q23: pdf | R23: No | S23: Administrative; Descriptive | T23: No | U23: Irregular | V23: Current Only
A24: p31 | B24: Wyoming Water and Climate Hub | C24: Wyoming Water Development Office | D24: n17 | E24: WWDO | F24: =CONCATENATE(E24,": ",B24) -> WWDO: Wyoming Water and Climate Hub | G24: Wyoming Water Development Office | H24: 5 | I24: http://water.geospatialhub.org/ | J24: Low | K24: Catalog | L24: Yes | M24: Individual Export; FTP | N24: Not Applicable | O24: excel; kml; shapefile | P24: some | Q24: html | R24: Yes | S24: Administrative; Descriptive | T24: Yes | U24: Varies | V24: Varies
A25: p32 | B25: Irrigation and Public Water System Surveys | C25: Wyoming Water Development Office | D25: n17 | E25: WWDO | F25: =CONCATENATE(E25,": ",B25) -> WWDO: Irrigation and Public Water System Surveys | G25: Wyoming Water Development Office | H25: 5 | I25: http://wwdc.state.wy.us/surveys/surveys.html | J25: Medium | K25: Website | L25: Yes | M25: Individual Export; Copy and Paste | N25: Not Applicable | O25: pdf; html | P25: yes | Q25: in data | R25: Yes | S25: Administrative; Descriptive; Structural | T25: Yes | U25: Varies | V25: Period of Record
A26: p33 | B26: Legislative Reports | C26: Wyoming Water Development Office | D26: n17 | E26: WWDO | F26: =CONCATENATE(E26,": ",B26) -> WWDO: Legislative Reports | G26: Wyoming Water Development Office | H26: 5 | I26: http://wwdc.state.wy.us/legreport/legreports.html | J26: Medium | K26: Website | L26: Yes | M26: Individual Export | N26: Not Applicable | O26: pdf | P26: no | Q26: no | R26: Yes | S26: No | T26: No | U26: Yearly or Higher | V26: Limited Record
A27: p35 | B27: Water Resources Data System Library | C27: Water Resources Data System & Wyoming State Climate Office | D27: n16 | E27: WRDS | F27: =CONCATENATE(E27,": ",B27) -> WRDS: Water Resources Data System Library | G27: University of Wyoming | H27: 8 | I27: http://library.wrds.uwyo.edu/ | J27: Medium | K27: Website | L27: Yes | M27: Individual Export | N27: Not Applicable | O27: pdf | P27: some | Q27: in data | R27: Some | S27: Administrative; Descriptive | T27: Some | U27: Varies | V27: Varies
A28: p36 | B28: WOGCC Data | C28: Wyoming Oil and Gas Conservation Commission | D28: n20 | E28: WOGCC | F28: =CONCATENATE(E28,": ",B28) -> WOGCC: WOGCC Data | G28: Wyoming Oil and Gas Conservation Commission | H28: 6 | I28: http://pipeline.wyo.gov/legacywogcce.cfm | J28: High | K28: Website; Catalog | L28: Yes | M28: Copy and Paste | N28: Not Applicable | O28: html | P28: no | Q28: No | R28: Yes | S28: No | T28: No | U28: Varies | V28: Varies
A29: p37 | B29: Groundwater Atlas of Wyoming | C29: Wyoming State Geological Survey | D29: n21 | E29: WSGS | F29: =CONCATENATE(E29,": ",B29) -> WSGS: Groundwater Atlas of Wyoming | G29: Wyoming State Geological Survey | H29: 7 | I29: https://wsgs.maps.arcgis.com/apps/webappviewer/index.html?id=09ebeedba94048a0b1ec4dcfc71eb9b5 | J29: Medium | K29: Map | L29: Yes | M29: Batch Export | N29: Not Applicable | O29: csv | P29: yes | Q29: html | R29: No | S29: Descriptive; Administrative | T29: No | U29: Unknown | V29: Unknown | W29: Map was not working
A30: p38 | B30: Wyoming State Geological Survey Publications Sales And Free Downloads | C30: Wyoming State Geological Survey | D30: n21 | E30: WSGS | F30: =CONCATENATE(E30,": ",B30) -> WSGS: Wyoming State Geological Survey Publications Sales And Free Downloads | G30: Wyoming State Geological Survey | H30: 7 | I30: http://sales.wsgs.wyo.gov/water/ | J30: High | K30: Website | L30: Yes | M30: Individual Export | N30: Not Applicable | O30: pdf | P30: no | Q30: No | R30: No | S30: No | T30: No | U30: Irregular | V30: Period of Record
A31: p39 | B31: Wyoming Geospatial Hub | C31: Wyoming | D31: n01 | E31: GeoHub | F31: =CONCATENATE(E31,": ",B31) -> GeoHub: Wyoming Geospatial Hub | G31: Wyoming | H31: 1 | I31: https://www.geospatialhub.org/ | J31: Low | K31: Catalog | L31: Yes | M31: Full Export; Web Services | N31: Not Applicable | O31: shapefile; excel; kml; geojson | P31: yes | Q31: html; xml | R31: No | S31: Descriptive; Administrative; Structural | T31: Yes | U31: Daily or Higher | V31: Varies

Sheet dataNodeTypes
A1: platformID | B1: platform | C1: entity | D1: tier1and2entity | E1: website | F1: data | G1: dataGroup | H1: dataCategory | I1: dataID | J1: notes | M1: dataGroup - linked to dataNodes tab | N1: dataID - linked to dataNodes tab
A2: p02 | B2: Gillette-Madison Well Field Project | C2: Groundwater | D2: Department of Environmental Quality | E2: http://deq.wyoming.gov/wqd/gillette-madison-well-field-project/ | F2: DEQ Pollution Discharge Elimination Systems Permits | G2: Regulatory | H2: =VLOOKUP(G2,dataNodes!$B$2:$C$19,2,FALSE) -> Quality | I2: =VLOOKUP(G2,$M$2:$N$19,2,FALSE) -> d04 | M2: =[1]dataNodes!B2 -> Built | N2: =[1]dataNodes!A2 -> d01
A3: p02 | B3: Gillette-Madison Well Field Project | C3: Groundwater | D3: Department of Environmental Quality | E3: http://deq.wyoming.gov/wqd/gillette-madison-well-field-project/ | F3: Individual Private Landowner Well Information | G3: Built | H3: =VLOOKUP(G3,dataNodes!$B$2:$C$19,2,FALSE) -> Infrastructure | I3: =VLOOKUP(G3,$M$2:$N$19,2,FALSE) -> d01 | M3: =[1]dataNodes!B3 -> Natural | N3: =[1]dataNodes!A3 -> d02
A4: p02 | B4: Gillette-Madison Well Field Project | C4: Groundwater | D4: Department of Environmental Quality | E4: http://deq.wyoming.gov/wqd/gillette-madison-well-field-project/ | F4: Discharge Estimates | G4: Groundwater | H4: =VLOOKUP(G4,dataNodes!$B$2:$C$19,2,FALSE) -> Quantity | I4: =VLOOKUP(G4,$M$2:$N$19,2,FALSE) -> d08 | M4: =[1]dataNodes!B4 -> Quality | N4: =[1]dataNodes!A4 -> d03
A5: p02 | B5: Gillette-Madison Well Field Project | C5: Groundwater | D5: Department of Environmental Quality | E5: http://deq.wyoming.gov/wqd/gillette-madison-well-field-project/ | F5: Metal concentration in wells | G5: Quality | H5: =VLOOKUP(G5,dataNodes!$B$2:$C$19,2,FALSE) -> Quality | I5: =VLOOKUP(G5,$M$2:$N$19,2,FALSE) -> d03 | M5: =[1]dataNodes!B5 -> Regulatory | N5: =[1]dataNodes!A5 -> d04
A6: p04 | B6: Pavillion Investigation | C6: Groundwater | D6: Department of Environmental Quality | E6: http://deq.wyoming.gov/wqd/pavillion-investigation/ | F6: Well water quality investigation | G6: Quality | H6: =VLOOKUP(G6,dataNodes!$B$2:$C$19,2,FALSE) -> Quality | I6: =VLOOKUP(G6,$M$2:$N$19,2,FALSE) -> d03 | M6: =[1]dataNodes!B6 -> Evapotranspiration | N6: =[1]dataNodes!A6 -> d05
A7: p04 | B7: Pavillion Investigation | C7: Groundwater | D7: Department of Environmental Quality | E7: http://deq.wyoming.gov/wqd/pavillion-investigation/ | F7: Well water quality investigation | G7: Groundwater | H7: =VLOOKUP(G7,dataNodes!$B$2:$C$19,2,FALSE) -> Quantity | I7: =VLOOKUP(G7,$M$2:$N$19,2,FALSE) -> d08 | M7: =[1]dataNodes!B7 -> Extreme Events | N7: =[1]dataNodes!A7 -> d06
A8: p06 | B8: GEM Database | C8: Groundwater | D8: Department of Environmental Quality | E8: http://deq.wyoming.gov/wqd/underground-injection-control/resources/gem-database/ | F8: Reporting monitoring data to the Underground Injection Control | G8: Regulatory | H8: =VLOOKUP(G8,[1]dataNodes!$B$2:$C$19,2,FALSE) -> Quality | I8: =VLOOKUP(G8,$M$2:$N$19,2,FALSE) -> d04 | M8: =[1]dataNodes!B8 -> Glacial and Snow | N8: =[1]dataNodes!A8 -> d07
A9: p06 | B9: GEM Database | C9: Groundwater | D9: Department of Environmental Quality | E9: http://deq.wyoming.gov/wqd/underground-injection-control/resources/gem-database/ | F9: Reporting monitoring data to the Underground Injection Control | G9: Quality | H9: =VLOOKUP(G9,[1]dataNodes!$B$2:$C$19,2,FALSE) -> Quality | I9: =VLOOKUP(G9,$M$2:$N$19,2,FALSE) -> d03 | M9: =[1]dataNodes!B9 -> Groundwater | N9: =[1]dataNodes!A9 -> d08
A10: p06 | B10: GEM Database | C10: Groundwater | D10: Department of Environmental Quality | E10: http://deq.wyoming.gov/wqd/underground-injection-control/resources/gem-database/ | F10: Reporting monitoring data to the Underground Injection Control | G10: Groundwater | H10: =VLOOKUP(G10,[1]dataNodes!$B$2:$C$19,2,FALSE) -> Quantity | I10: =VLOOKUP(G10,$M$2:$N$19,2,FALSE) -> d08 | M10: =[1]dataNodes!B10 -> Meteorology | N10: =[1]dataNodes!A10 -> d09
A11: p07 | B11: Monitoring Data | C11: Groundwater | D11: Department of Environmental Quality | E11: http://deq.wyoming.gov/wqd/groundwater/resources/monitoring-data/ | F11: Groundwater and surface water data for each county | G11: Quality | H11: =VLOOKUP(G11,[1]dataNodes!$B$2:$C$19,2,FALSE) -> Quality | I11: =VLOOKUP(G11,$M$2:$N$19,2,FALSE) -> d03 | M11: =[1]dataNodes!B11 -> Precipitation | N11: =[1]dataNodes!A11 -> d10
A12: p07 | B12: Monitoring Data | C12: Groundwater | D12: Department of Environmental Quality | E12: http://deq.wyoming.gov/wqd/groundwater/resources/monitoring-data/ | F12: Depth to groundwater coverage | G12: Groundwater | H12: =VLOOKUP(G12,[1]dataNodes!$B$2:$C$19,2,FALSE) -> Quantity | I12: =VLOOKUP(G12,$M$2:$N$19,2,FALSE) -> d08 | M12: =[1]dataNodes!B12 -> Reservoir | N12: =[1]dataNodes!A12 -> d11
A13: p08 | B13: Nonpoint Source Projects | C13: Watershed Protection | D13: Department of Environmental Quality | E13: http://deq.wyoming.gov/wqd/non-point-source/resources/projects/ | F13: Impaired waterbody restoration projects | G13: Management Plans | H13: =VLOOKUP(G13,[1]dataNodes!$B$2:$C$19,2,FALSE) -> Use | I13: =VLOOKUP(G13,$M$2:$N$19,2,FALSE) -> d18 | M13: =[1]dataNodes!B13 -> Soil | N13: =[1]dataNodes!A13 -> d12
A14: p09 | B14: Waterbody Assessment Reports | C14: Watershed Protection | D14: Department of Environmental Quality | E14: http://deq.wyoming.gov/wqd/non-point-source/resources/reports/ | F14: Water bodies administration and facilitation | G14: Management Plans | H14: =VLOOKUP(G14,[1]dataNodes!$B$2:$C$19,2,FALSE) -> Use | I14: =VLOOKUP(G14,$M$2:$N$19,2,FALSE) -> d18 | M14: =[1]dataNodes!B14 -> Surface Water | N14: =[1]dataNodes!A14 -> d13
A15: p09 | B15: Waterbody Assessment Reports | C15: Watershed Protection | D15: Department of Environmental Quality | E15: http://deq.wyoming.gov/wqd/non-point-source/resources/reports/ | F15: Water bodies chemical, physical and biological monitoring and nutrient budget | G15: Quality | H15: =VLOOKUP(G15,[1]dataNodes!$B$2:$C$19,2,FALSE) -> Quality | I15: =VLOOKUP(G15,$M$2:$N$19,2,FALSE) -> d03 | M15: =[1]dataNodes!B15 -> Hydropower | N15: =[1]dataNodes!A15 -> d14
A16: p10 | B16: TMDL Completed Projects | C16: Watershed Protection | D16: Department of Environmental Quality | E16: http://deq.wyoming.gov/wqd/tmdl/resources/completed-projects/ | F16: TMDL | G16: Regulatory | H16: =VLOOKUP(G16,[1]dataNodes!$B$2:$C$19,2,FALSE) -> Quality | I16: =VLOOKUP(G16,$M$2:$N$19,2,FALSE) -> d04 | M16: =[1]dataNodes!B16 -> Irrigation | N16: =[1]dataNodes!A16 -> d15
A17: p10 | B17: TMDL Completed Projects | C17: Watershed Protection | D17: Department of Environmental Quality | E17: http://deq.wyoming.gov/wqd/tmdl/resources/completed-projects/ | F17: TMDL | G17: Quality | H17: =VLOOKUP(G17,[1]dataNodes!$B$2:$C$19,2,FALSE) -> Quality | I17: =VLOOKUP(G17,$M$2:$N$19,2,FALSE) -> d03 | M17: =[1]dataNodes!B17 -> Use | N17: =[1]dataNodes!A17 -> d16
A18: p10 | B18: TMDL Completed Projects | C18: Watershed Protection | D18: Department of Environmental Quality | E18: http://deq.wyoming.gov/wqd/tmdl/resources/completed-projects/ | F18: Precipitation by water bodies | G18: Precipitation | H18: =VLOOKUP(G18,[1]dataNodes!$B$2:$C$19,2,FALSE) -> Quantity | I18: =VLOOKUP(G18,$M$2:$N$19,2,FALSE) -> d10 | M18: =[1]dataNodes!B18 -> Utilities | N18: =[1]dataNodes!A18 -> d17
A19: p10 | B19: TMDL Completed Projects | C19: Watershed Protection | D19: Department of Environmental Quality | E19: http://deq.wyoming.gov/wqd/tmdl/resources/completed-projects/ | F19: Average temperatures by water bodies | G19: Meteorology | H19: =VLOOKUP(G19,[1]dataNodes!$B$2:$C$19,2,FALSE) -> Quantity | I19: =VLOOKUP(G19,$M$2:$N$19,2,FALSE) -> d09 | M19: =[1]dataNodes!B19 -> Management Plans | N19: =[1]dataNodes!A19 -> d18
A20: p10 | B20: TMDL Completed Projects | C20: Watershed Protection | D20: Department of Environmental Quality | E20: http://deq.wyoming.gov/wqd/tmdl/resources/completed-projects/ | F20: Soil type water bodies | G20: Soil | H20: =VLOOKUP(G20,[1]dataNodes!$B$2:$C$19,2,FALSE) -> Quantity | I20: =VLOOKUP(G20,$M$2:$N$19,2,FALSE) -> d12
A21: p11 | B21: Water Quality Assessment Reports | C21: Watershed Protection | D21: Department of Environmental Quality | E21: http://deq.wyoming.gov/wqd/water-quality-assessment/resources/reports/ | F21: Integrated 305(b) and 303(d) Reports for Lakes, streams and rivers | G21: Regulatory | H21: =VLOOKUP(G21,[1]dataNodes!$B$2:$C$19,2,FALSE) -> Quality | I21: =VLOOKUP(G21,$M$2:$N$19,2,FALSE) -> d04
A22: p11 | B22: Water Quality Assessment Reports | C22: Watershed Protection | D22: Department of Environmental Quality | E22: http://deq.wyoming.gov/wqd/water-quality-assessment/resources/reports/ | F22: Causes of Imparied waters and pollutant sources | G22: Quality | H22: =VLOOKUP(G22,[1]dataNodes!$B$2:$C$19,2,FALSE) -> Quality | I22: =VLOOKUP(G22,$M$2:$N$19,2,FALSE) -> d03
A23: p11 | B23: Water Quality Assessment Reports | C23: Watershed Protection | D23: Department of Environmental Quality | E23: http://deq.wyoming.gov/wqd/water-quality-assessment/resources/reports/ | F23: Designated use | G23: Use | H23: =VLOOKUP(G23,[1]dataNodes!$B$2:$C$19,2,FALSE) -> Use | I23: =VLOOKUP(G23,$M$2:$N$19,2,FALSE) -> d16
A24: p11 | B24: Water Quality Assessment Reports | C24: Watershed Protection | D24: Department of Environmental Quality | E24: http://deq.wyoming.gov/wqd/water-quality-assessment/resources/reports/ | F24: Location and category of surface waters | G24: Natural | H24: =VLOOKUP(G24,[1]dataNodes!$B$2:$C$19,2,FALSE) -> Infrastructure | I24: =VLOOKUP(G24,$M$2:$N$19,2,FALSE) -> d02
A25: p12 | B25: Authorized Permit Archive | C25: Water and Wastewater | D25: Department of Environmental Quality | E25: http://deq.wyoming.gov/wqd/water-wastewater/resources/authorized-archive/ | F25: Water utility permits | G25: Regulatory | H25: =VLOOKUP(G25,[1]dataNodes!$B$2:$C$19,2,FALSE) -> Quality | I25: =VLOOKUP(G25,$M$2:$N$19,2,FALSE) -> d04
A26: p12 | B26: Authorized Permit Archive | C26: Water and Wastewater | D26: Department of Environmental Quality | E26: http://deq.wyoming.gov/wqd/water-wastewater/resources/authorized-archive/ | F26: Water utility capactity | G26: Utilities | H26: =VLOOKUP(G26,[1]dataNodes!$B$2:$C$19,2,FALSE) -> Use | I26: =VLOOKUP(G26,$M$2:$N$19,2,FALSE) -> d17
A27: p14 | B27: NRCS Snowdata and Reporting | C27: Snow Survey and Water Supply Forecasting Program | D27: Wyoming State Engineer's Office | E27: http://www.wrds.uwyo.edu/wrds/nrcs/nrcs.html | F27: snowpack reports | G27: Glacial and Snow | H27: =VLOOKUP(G27,dataNodes!$B$2:$C$19,2,FALSE) -> Quantity | I27: =VLOOKUP(G27,$M$2:$N$19,2,FALSE) -> d07
A28: p15 | B28: SEO Snowpack Report by Drainage | C28: Snow Survey and Water Supply Forecasting Program | D28: Wyoming State Engineer's Office | E28: http://snow.wyo.gov/snow-data/seo-snowpack-reports-by-drainage | F28: snowpack reports | G28: Glacial and Snow | H28: =VLOOKUP(G28,dataNodes!$B$2:$C$19,2,FALSE) -> Quantity | I28: =VLOOKUP(G28,$M$2:$N$19,2,FALSE) -> d07
A29: p16 | B29: NOAA National Snow Analyses | C29: Snow Survey and Water Supply Forecasting Program | D29: Wyoming State Engineer's Office | E29: https://www.nohrsc.noaa.gov/ | F29: snow anlysis | G29: Glacial and Snow | H29: =VLOOKUP(G29,dataNodes!$B$2:$C$19,2,FALSE) -> Quantity | I29: =VLOOKUP(G29,$M$2:$N$19,2,FALSE) -> d07
A30: p17 | B30: Realtime Stream Flow | C30: Wyoming State Engineer's Office | D30: Wyoming State Engineer's Office | E30: http://seoflow.wyo.gov/ | F30: reservoir levels, etc | G30: Reservoir | H30: =VLOOKUP(G30,dataNodes!$B$2:$C$19,2,FALSE) -> Quantity | I30: =VLOOKUP(G30,$M$2:$N$19,2,FALSE) -> d11
A31: p17 | B31: Realtime Stream Flow | C31: Wyoming State Engineer's Office | D31: Wyoming State Engineer's Office | E31: http://seoflow.wyo.gov/ | F31: ph levels | G31: Quality | H31: =VLOOKUP(G31,dataNodes!$B$2:$C$19,2,FALSE) -> Quality | I31: =VLOOKUP(G31,$M$2:$N$19,2,FALSE) -> d03
A32: p17 | B32: Realtime Stream Flow | C32: Wyoming State Engineer's Office | D32: Wyoming State Engineer's Office | E32: http://seoflow.wyo.gov/ | F32: precipitation data | G32: Precipitation | H32: =VLOOKUP(G32,dataNodes!$B$2:$C$19,2,FALSE) -> Quantity | I32: =VLOOKUP(G32,$M$2:$N$19,2,FALSE) -> d10
A33: p17 | B33: Realtime Stream Flow | C33: Wyoming State Engineer's Office | D33: Wyoming State Engineer's Office | E33: http://seoflow.wyo.gov/ | F33: wind data | G33: Meteorology | H33: =VLOOKUP(G33,dataNodes!$B$2:$C$19,2,FALSE) -> Quantity | I33: =VLOOKUP(G33,$M$2:$N$19,2,FALSE) -> d09
A34: p17 | B34: Realtime Stream Flow | C34: Wyoming State Engineer's Office | D34: Wyoming State Engineer's Office | E34: http://seoflow.wyo.gov/ | F34: water velocity, discharge velocity | G34: Surface Water | H34: =VLOOKUP(G34,dataNodes!$B$2:$C$19,2,FALSE) -> Quantity | I34: =VLOOKUP(G34,$M$2:$N$19,2,FALSE) -> d13
A35: p17 | B35: Realtime Stream Flow | C35: Wyoming State Engineer's Office | D35: Wyoming State Engineer's Office | E35: http://seoflow.wyo.gov/ | F35: snow water equivalent | G35: Glacial and Snow | H35: =VLOOKUP(G35,dataNodes!$B$2:$C$19,2,FALSE) -> Quantity | I35: =VLOOKUP(G35,$M$2:$N$19,2,FALSE) -> d07
A36: p17 | B36: Realtime Stream Flow | C36: Wyoming State Engineer's Office | D36: Wyoming State Engineer's Office | E36: http://seoflow.wyo.gov/ | F36: voltage | G36: Hydropower | H36: =VLOOKUP(G36,dataNodes!$B$2:$C$19,2,FALSE) -> Use | I36: =VLOOKUP(G36,$M$2:$N$19,2,FALSE) -> d14
A37: p18 | B37: Products and Data | C37: Snow Survey and Water Supply Forecasting Program | D37: Wyoming State Engineer's Office | E37: http://www.wrds.uwyo.edu/wrds/nrcs/nrcs.html | F37: snow, snow water equivalent | G37: Glacial and Snow | H37: =VLOOKUP(G37,dataNodes!$B$2:$C$19,2,FALSE) -> Quantity | I37: =VLOOKUP(G37,$M$2:$N$19,2,FALSE) -> d07
A38: p18 | B38: Products and Data | C38: Snow Survey and Water Supply Forecasting Program | D38: Wyoming State Engineer's Office | E38: http://www.wrds.uwyo.edu/wrds/nrcs/nrcs.html | F38: Temperature | G38: Meteorology | H38: =VLOOKUP(G38,dataNodes!$B$2:$C$19,2,FALSE) -> Quantity | I38: =VLOOKUP(G38,$M$2:$N$19,2,FALSE) -> d09
... A44: p18 | B44: Products and Data | C44: Snow Survey and Water Supply Forecasting Program | D44: Wyoming State Engineer's Office | E44: http://www.wrds.uwyo.edu/wrds/nrcs/nrcs.html | F44: Drought; Floods | G44: Extreme Events | H44: =VLOOKUP(G44,dataNodes!$B$2:$C$19,2,FALSE) -> Quantity | I44: =VLOOKUP(G44,$M$2:$N$19,2,FALSE) -> d06
A45: p20 | B45: Order of the State Engineer - Laramie County Control Area | C45: Groundwater Division | D45: State Engineer's Office | E45: http://seo.wyo.gov/ground-water/state-engineer-s-orders | F45: Annual and spatial variation of precipitation in Laramie County | G45: Precipitation | H45: =VLOOKUP(G45,[1]dataNodes!$B$2:$C$19,2,FALSE) -> Quantity | I45: =VLOOKUP(G45,$M$2:$N$19,2,FALSE) -> d10
...

Sheet dataEdges
A1: from | B1: to
A2: calculated in R

Sheet dataNodes
A1: dataID | B1: dataGroup | C1: dataCategory
A2: d01 | B2: Built | C2: Infrastructure
A3: d02 | B3: Natural | C3: Infrastructure
A4: d03 | B4: Quality | C4: Quality
A5: d04 | B5: Regulatory | C5: Quality
A6: d05 | B6: Evapotranspiration | C6: Quantity
A7: d06 | B7: Extreme Events | C7: Quantity
A8: d07 | B8: Glacial and Snow | C8: Quantity
A9: d08 | B9: Groundwater | C9: Quantity
A10: d09 | B10: Meteorology | C10: Quantity
A11: d10 | B11: Precipitation | C11: Quantity
A12: d11 | B12: Reservoir | C12: Quantity
... A19: d18 | B19: Management Plans | C19: Use
